Traceback (most recent call last):
  File "/app_shell/backup-platform/webadmins/scheduler.py", line 21, in <module>
    import sched_task.shced_fs_backup_tasks
ModuleNotFoundError: No module named 'sched_task.shced_fs_backup_tasks'
Traceback (most recent call last):
  File "/app_shell/backup-platform/webadmins/scheduler.py", line 21, in <module>
    import sched_task.shced_fs_backup_tasks
ModuleNotFoundError: No module named 'sched_task.shced_fs_backup_tasks'
Traceback (most recent call last):
  File "/app_shell/backup-platform/webadmins/scheduler.py", line 21, in <module>
    import sched_task.shced_fs_backup_tasks
ModuleNotFoundError: No module named 'sched_task.shced_fs_backup_tasks'
Traceback (most recent call last):
  File "/app_shell/backup-platform/webadmins/scheduler.py", line 21, in <module>
    import sched_task.shced_fs_backup_tasks
ModuleNotFoundError: No module named 'sched_task.shced_fs_backup_tasks'
Traceback (most recent call last):
  File "/app_shell/backup-platform/webadmins/scheduler.py", line 21, in <module>
    import sched_task.shced_fs_backup_tasks
ModuleNotFoundError: No module named 'sched_task.shced_fs_backup_tasks'
Traceback (most recent call last):
  File "/app_shell/backup-platform/webadmins/scheduler.py", line 21, in <module>
    import sched_task.shced_fs_backup_tasks
ModuleNotFoundError: No module named 'sched_task.shced_fs_backup_tasks'
Traceback (most recent call last):
  File "/app_shell/backup-platform/webadmins/scheduler.py", line 21, in <module>
    import sched_task.shced_fs_backup_tasks
ModuleNotFoundError: No module named 'sched_task.shced_fs_backup_tasks'
Traceback (most recent call last):
  File "/app_shell/backup-platform/webadmins/scheduler.py", line 21, in <module>
    import sched_task.shced_fs_backup_tasks
ModuleNotFoundError: No module named 'sched_task.shced_fs_backup_tasks'
Traceback (most recent call last):
  File "/app_shell/backup-platform/webadmins/scheduler.py", line 21, in <module>
    import sched_task.shced_fs_backup_tasks
ModuleNotFoundError: No module named 'sched_task.shced_fs_backup_tasks'
Traceback (most recent call last):
  File "/app_shell/backup-platform/webadmins/scheduler.py", line 21, in <module>
    import sched_task.shced_fs_backup_tasks
ModuleNotFoundError: No module named 'sched_task.shced_fs_backup_tasks'
Job "db_backup_tools.db_backup_start (trigger: cron[day_of_week='0,1,2,3,4,5,6', minute='*/1'], next run at: 2019-07-19 07:01:00 UTC)" raised an exception
Traceback (most recent call last):
  File "/app_shell/backup-platform/lib/python3.6/site-packages/apscheduler/executors/base.py", line 125, in run_job
    retval = job.func(*job.args, **job.kwargs)
  File "/app_shell/backup-platform/webadmins/sched_task/sched_db_backup_tasks.py", line 43, in db_backup_start
    result = x.xtrabackup_full_backup(backup_to_local_path)
  File "/app_shell/backup-platform/webadmins/lib/db_backup_tools.py", line 65, in xtrabackup_full_backup
    raise DB_BACKUP_ERROR(u"主机%s数据库备份失败! err:%s" % (self.sshObj.host, output["stderr"].decode(encoding="utf-8").strip()))
db_backup_tools.DB_BACKUP_ERROR: 主机172.16.70.221数据库备份失败! err:190628 16:08:32 innobackupex: Starting the backup operation

IMPORTANT: Please check that the backup run completes successfully.
           At the end of a successful backup run innobackupex
           prints "completed OK!".

Can't locate Digest/MD5.pm in @INC (@INC contains: /usr/local/lib64/perl5 /usr/local/share/perl5 /usr/lib64/perl5/vendor_perl /usr/share/perl5/vendor_perl /usr/lib64/perl5 /usr/share/perl5 .) at - line 693.
BEGIN failed--compilation aborted at - line 693.
190628 16:08:32 Connecting to MySQL server host: 172.16.70.221, user: root, password: set, port: 3306, socket: not set
Using server version 5.7.26
/usr/local/percona-xtrabackup/bin/innobackupex version 2.4.9 based on MySQL server 5.7.13 Linux (x86_64) (revision id: a467167cdd4)
xtrabackup: uses posix_fadvise().
xtrabackup: cd to /var/lib/mysql/
xtrabackup: open files limit requested 0, set to 1024
xtrabackup: using the following InnoDB configuration:
xtrabackup:   innodb_data_home_dir = .
xtrabackup:   innodb_data_file_path = ibdata1:12M:autoextend
xtrabackup:   innodb_log_group_home_dir = ./
xtrabackup:   innodb_log_files_in_group = 2
xtrabackup:   innodb_log_file_size = 50331648
InnoDB: Number of pools: 1
innobackupex: Can't create/write to file '/mnt/nfs/588525330779870/172.16.70.221/20190719070000/xtrabackup_logfile' (Errcode: 17 - File exists)
xtrabackup: error: failed to open the target stream for 'xtrabackup_logfile'.
Job "db_backup_tools.db_backup_start (trigger: cron[day_of_week='0,1,2,3,4,5,6', minute='*/1'], next run at: 2019-07-19 07:04:00 UTC)" raised an exception
Traceback (most recent call last):
  File "/app_shell/backup-platform/lib/python3.6/site-packages/apscheduler/executors/base.py", line 125, in run_job
    retval = job.func(*job.args, **job.kwargs)
  File "/app_shell/backup-platform/webadmins/sched_task/sched_db_backup_tasks.py", line 43, in db_backup_start
    result = x.xtrabackup_full_backup(backup_to_local_path)
  File "/app_shell/backup-platform/webadmins/lib/db_backup_tools.py", line 65, in xtrabackup_full_backup
    raise DB_BACKUP_ERROR(u"主机%s数据库备份失败! err:%s" % (self.sshObj.host, output["stderr"].decode(encoding="utf-8").strip()))
db_backup_tools.DB_BACKUP_ERROR: 主机172.16.70.221数据库备份失败! err:190628 16:11:32 innobackupex: Starting the backup operation

IMPORTANT: Please check that the backup run completes successfully.
           At the end of a successful backup run innobackupex
           prints "completed OK!".

Can't locate Digest/MD5.pm in @INC (@INC contains: /usr/local/lib64/perl5 /usr/local/share/perl5 /usr/lib64/perl5/vendor_perl /usr/share/perl5/vendor_perl /usr/lib64/perl5 /usr/share/perl5 .) at - line 693.
BEGIN failed--compilation aborted at - line 693.
190628 16:11:32 Connecting to MySQL server host: 172.16.70.221, user: root, password: set, port: 3306, socket: not set
Using server version 5.7.26
/usr/local/percona-xtrabackup/bin/innobackupex version 2.4.9 based on MySQL server 5.7.13 Linux (x86_64) (revision id: a467167cdd4)
xtrabackup: uses posix_fadvise().
xtrabackup: cd to /var/lib/mysql/
xtrabackup: open files limit requested 0, set to 1024
xtrabackup: using the following InnoDB configuration:
xtrabackup:   innodb_data_home_dir = .
xtrabackup:   innodb_data_file_path = ibdata1:12M:autoextend
xtrabackup:   innodb_log_group_home_dir = ./
xtrabackup:   innodb_log_files_in_group = 2
xtrabackup:   innodb_log_file_size = 50331648
InnoDB: Number of pools: 1
innobackupex: Can't create/write to file '/mnt/nfs/588525330779870/172.16.70.221/20190719070300/xtrabackup_logfile' (Errcode: 17 - File exists)
xtrabackup: error: failed to open the target stream for 'xtrabackup_logfile'.
Job "db_backup_tools.db_backup_start (trigger: cron[day_of_week='0,1,2,3,4,5,6', minute='*/3'], next run at: 2019-07-19 07:09:00 UTC)" raised an exception
Traceback (most recent call last):
  File "/app_shell/backup-platform/lib/python3.6/site-packages/apscheduler/executors/base.py", line 125, in run_job
    retval = job.func(*job.args, **job.kwargs)
  File "/app_shell/backup-platform/webadmins/sched_task/sched_db_backup_tasks.py", line 43, in db_backup_start
    result = x.xtrabackup_full_backup(backup_to_local_path)
  File "/app_shell/backup-platform/webadmins/lib/db_backup_tools.py", line 65, in xtrabackup_full_backup
    raise DB_BACKUP_ERROR(u"主机%s数据库备份失败! err:%s" % (self.sshObj.host, output["stderr"].decode(encoding="utf-8").strip()))
db_backup_tools.DB_BACKUP_ERROR: 主机172.16.70.221数据库备份失败! err:190628 16:14:32 innobackupex: Starting the backup operation

IMPORTANT: Please check that the backup run completes successfully.
           At the end of a successful backup run innobackupex
           prints "completed OK!".

Can't locate Digest/MD5.pm in @INC (@INC contains: /usr/local/lib64/perl5 /usr/local/share/perl5 /usr/lib64/perl5/vendor_perl /usr/share/perl5/vendor_perl /usr/lib64/perl5 /usr/share/perl5 .) at - line 693.
BEGIN failed--compilation aborted at - line 693.
190628 16:14:32 Connecting to MySQL server host: 172.16.70.221, user: root, password: set, port: 3306, socket: not set
Using server version 5.7.26
/usr/local/percona-xtrabackup/bin/innobackupex version 2.4.9 based on MySQL server 5.7.13 Linux (x86_64) (revision id: a467167cdd4)
xtrabackup: uses posix_fadvise().
xtrabackup: cd to /var/lib/mysql/
xtrabackup: open files limit requested 0, set to 1024
xtrabackup: using the following InnoDB configuration:
xtrabackup:   innodb_data_home_dir = .
xtrabackup:   innodb_data_file_path = ibdata1:12M:autoextend
xtrabackup:   innodb_log_group_home_dir = ./
xtrabackup:   innodb_log_files_in_group = 2
xtrabackup:   innodb_log_file_size = 50331648
InnoDB: Number of pools: 1
innobackupex: Can't create/write to file '/mnt/nfs/588525330779870/172.16.70.221/20190719070600/xtrabackup_logfile' (Errcode: 17 - File exists)
xtrabackup: error: failed to open the target stream for 'xtrabackup_logfile'.
Job "db_backup_tools.db_backup_start (trigger: cron[day_of_week='0,1,2,3,4,5,6', minute='*/3'], next run at: 2019-07-19 07:12:00 UTC)" raised an exception
Traceback (most recent call last):
  File "/app_shell/backup-platform/lib/python3.6/site-packages/apscheduler/executors/base.py", line 125, in run_job
    retval = job.func(*job.args, **job.kwargs)
  File "/app_shell/backup-platform/webadmins/sched_task/sched_db_backup_tasks.py", line 43, in db_backup_start
    result = x.xtrabackup_full_backup(backup_to_local_path)
  File "/app_shell/backup-platform/webadmins/lib/db_backup_tools.py", line 65, in xtrabackup_full_backup
    raise DB_BACKUP_ERROR(u"主机%s数据库备份失败! err:%s" % (self.sshObj.host, output["stderr"].decode(encoding="utf-8").strip()))
db_backup_tools.DB_BACKUP_ERROR: 主机172.16.70.221数据库备份失败! err:190628 16:17:32 innobackupex: Starting the backup operation

IMPORTANT: Please check that the backup run completes successfully.
           At the end of a successful backup run innobackupex
           prints "completed OK!".

Can't locate Digest/MD5.pm in @INC (@INC contains: /usr/local/lib64/perl5 /usr/local/share/perl5 /usr/lib64/perl5/vendor_perl /usr/share/perl5/vendor_perl /usr/lib64/perl5 /usr/share/perl5 .) at - line 693.
BEGIN failed--compilation aborted at - line 693.
190628 16:17:32 Connecting to MySQL server host: 172.16.70.221, user: root, password: set, port: 3306, socket: not set
Using server version 5.7.26
/usr/local/percona-xtrabackup/bin/innobackupex version 2.4.9 based on MySQL server 5.7.13 Linux (x86_64) (revision id: a467167cdd4)
xtrabackup: uses posix_fadvise().
xtrabackup: cd to /var/lib/mysql/
xtrabackup: open files limit requested 0, set to 1024
xtrabackup: using the following InnoDB configuration:
xtrabackup:   innodb_data_home_dir = .
xtrabackup:   innodb_data_file_path = ibdata1:12M:autoextend
xtrabackup:   innodb_log_group_home_dir = ./
xtrabackup:   innodb_log_files_in_group = 2
xtrabackup:   innodb_log_file_size = 50331648
InnoDB: Number of pools: 1
innobackupex: Can't create/write to file '/mnt/nfs/588525330779870/172.16.70.221/20190719070900/xtrabackup_logfile' (Errcode: 17 - File exists)
xtrabackup: error: failed to open the target stream for 'xtrabackup_logfile'.
Job "db_backup_tools.db_backup_start (trigger: cron[day_of_week='0,1,2,3,4,5,6', minute='*/1'], next run at: 2019-07-19 07:13:00 UTC)" raised an exception
Traceback (most recent call last):
  File "/app_shell/backup-platform/lib/python3.6/site-packages/apscheduler/executors/base.py", line 125, in run_job
    retval = job.func(*job.args, **job.kwargs)
  File "/app_shell/backup-platform/webadmins/sched_task/sched_db_backup_tasks.py", line 43, in db_backup_start
    result = x.xtrabackup_full_backup(backup_to_local_path)
  File "/app_shell/backup-platform/webadmins/lib/db_backup_tools.py", line 65, in xtrabackup_full_backup
    raise DB_BACKUP_ERROR(u"主机%s数据库备份失败! err:%s" % (self.sshObj.host, output["stderr"].decode(encoding="utf-8").strip()))
db_backup_tools.DB_BACKUP_ERROR: 主机172.16.70.221数据库备份失败! err:190628 16:20:32 innobackupex: Starting the backup operation

IMPORTANT: Please check that the backup run completes successfully.
           At the end of a successful backup run innobackupex
           prints "completed OK!".

Can't locate Digest/MD5.pm in @INC (@INC contains: /usr/local/lib64/perl5 /usr/local/share/perl5 /usr/lib64/perl5/vendor_perl /usr/share/perl5/vendor_perl /usr/lib64/perl5 /usr/share/perl5 .) at - line 693.
BEGIN failed--compilation aborted at - line 693.
190628 16:20:32 Connecting to MySQL server host: 172.16.70.221, user: root, password: set, port: 3306, socket: not set
Using server version 5.7.26
/usr/local/percona-xtrabackup/bin/innobackupex version 2.4.9 based on MySQL server 5.7.13 Linux (x86_64) (revision id: a467167cdd4)
xtrabackup: uses posix_fadvise().
xtrabackup: cd to /var/lib/mysql/
xtrabackup: open files limit requested 0, set to 1024
xtrabackup: using the following InnoDB configuration:
xtrabackup:   innodb_data_home_dir = .
xtrabackup:   innodb_data_file_path = ibdata1:12M:autoextend
xtrabackup:   innodb_log_group_home_dir = ./
xtrabackup:   innodb_log_files_in_group = 2
xtrabackup:   innodb_log_file_size = 50331648
InnoDB: Number of pools: 1
innobackupex: Can't create/write to file '/mnt/nfs/588525330779870/172.16.70.221/20190719071200/xtrabackup_logfile' (Errcode: 17 - File exists)
xtrabackup: error: failed to open the target stream for 'xtrabackup_logfile'.
Job "db_backup_tools.db_backup_start (trigger: cron[day_of_week='0,1,2,3,4,5,6', minute='*/3'], next run at: 2019-07-19 07:18:00 UTC)" raised an exception
Traceback (most recent call last):
  File "/app_shell/backup-platform/lib/python3.6/site-packages/apscheduler/executors/base.py", line 125, in run_job
    retval = job.func(*job.args, **job.kwargs)
  File "/app_shell/backup-platform/webadmins/sched_task/sched_db_backup_tasks.py", line 43, in db_backup_start
    result = x.xtrabackup_full_backup(backup_to_local_path)
  File "/app_shell/backup-platform/webadmins/lib/db_backup_tools.py", line 65, in xtrabackup_full_backup
    raise DB_BACKUP_ERROR(u"主机%s数据库备份失败! err:%s" % (self.sshObj.host, output["stderr"].decode(encoding="utf-8").strip()))
db_backup_tools.DB_BACKUP_ERROR: 主机172.16.70.221数据库备份失败! err:190628 16:23:32 innobackupex: Starting the backup operation

IMPORTANT: Please check that the backup run completes successfully.
           At the end of a successful backup run innobackupex
           prints "completed OK!".

Can't locate Digest/MD5.pm in @INC (@INC contains: /usr/local/lib64/perl5 /usr/local/share/perl5 /usr/lib64/perl5/vendor_perl /usr/share/perl5/vendor_perl /usr/lib64/perl5 /usr/share/perl5 .) at - line 693.
BEGIN failed--compilation aborted at - line 693.
190628 16:23:32 Connecting to MySQL server host: 172.16.70.221, user: root, password: set, port: 3306, socket: not set
Using server version 5.7.26
/usr/local/percona-xtrabackup/bin/innobackupex version 2.4.9 based on MySQL server 5.7.13 Linux (x86_64) (revision id: a467167cdd4)
xtrabackup: uses posix_fadvise().
xtrabackup: cd to /var/lib/mysql/
xtrabackup: open files limit requested 0, set to 1024
xtrabackup: using the following InnoDB configuration:
xtrabackup:   innodb_data_home_dir = .
xtrabackup:   innodb_data_file_path = ibdata1:12M:autoextend
xtrabackup:   innodb_log_group_home_dir = ./
xtrabackup:   innodb_log_files_in_group = 2
xtrabackup:   innodb_log_file_size = 50331648
InnoDB: Number of pools: 1
innobackupex: Can't create/write to file '/mnt/nfs/588525330779870/172.16.70.221/20190719071500/xtrabackup_logfile' (Errcode: 17 - File exists)
xtrabackup: error: failed to open the target stream for 'xtrabackup_logfile'.
Job "db_backup_tools.db_backup_start (trigger: cron[day_of_week='0,1,2,3,4,5,6', minute='*/3'], next run at: 2019-07-19 07:21:00 UTC)" raised an exception
Traceback (most recent call last):
  File "/app_shell/backup-platform/lib/python3.6/site-packages/apscheduler/executors/base.py", line 125, in run_job
    retval = job.func(*job.args, **job.kwargs)
  File "/app_shell/backup-platform/webadmins/sched_task/sched_db_backup_tasks.py", line 43, in db_backup_start
    result = x.xtrabackup_full_backup(backup_to_local_path)
  File "/app_shell/backup-platform/webadmins/lib/db_backup_tools.py", line 65, in xtrabackup_full_backup
    raise DB_BACKUP_ERROR(u"主机%s数据库备份失败! err:%s" % (self.sshObj.host, output["stderr"].decode(encoding="utf-8").strip()))
db_backup_tools.DB_BACKUP_ERROR: 主机172.16.70.221数据库备份失败! err:190628 16:26:32 innobackupex: Starting the backup operation

IMPORTANT: Please check that the backup run completes successfully.
           At the end of a successful backup run innobackupex
           prints "completed OK!".

Can't locate Digest/MD5.pm in @INC (@INC contains: /usr/local/lib64/perl5 /usr/local/share/perl5 /usr/lib64/perl5/vendor_perl /usr/share/perl5/vendor_perl /usr/lib64/perl5 /usr/share/perl5 .) at - line 693.
BEGIN failed--compilation aborted at - line 693.
190628 16:26:33 Connecting to MySQL server host: 172.16.70.221, user: root, password: set, port: 3306, socket: not set
Using server version 5.7.26
/usr/local/percona-xtrabackup/bin/innobackupex version 2.4.9 based on MySQL server 5.7.13 Linux (x86_64) (revision id: a467167cdd4)
xtrabackup: uses posix_fadvise().
xtrabackup: cd to /var/lib/mysql/
xtrabackup: open files limit requested 0, set to 1024
xtrabackup: using the following InnoDB configuration:
xtrabackup:   innodb_data_home_dir = .
xtrabackup:   innodb_data_file_path = ibdata1:12M:autoextend
xtrabackup:   innodb_log_group_home_dir = ./
xtrabackup:   innodb_log_files_in_group = 2
xtrabackup:   innodb_log_file_size = 50331648
InnoDB: Number of pools: 1
innobackupex: Can't create/write to file '/mnt/nfs/588525330779870/172.16.70.221/20190719071800/xtrabackup_logfile' (Errcode: 17 - File exists)
xtrabackup: error: failed to open the target stream for 'xtrabackup_logfile'.
Job "db_backup_tools.db_backup_start (trigger: cron[day_of_week='0,1,2,3,4,5,6', minute='*/1'], next run at: 2019-07-19 07:22:00 UTC)" raised an exception
Traceback (most recent call last):
  File "/app_shell/backup-platform/lib/python3.6/site-packages/apscheduler/executors/base.py", line 125, in run_job
    retval = job.func(*job.args, **job.kwargs)
  File "/app_shell/backup-platform/webadmins/sched_task/sched_db_backup_tasks.py", line 43, in db_backup_start
    result = x.xtrabackup_full_backup(backup_to_local_path)
  File "/app_shell/backup-platform/webadmins/lib/db_backup_tools.py", line 65, in xtrabackup_full_backup
    raise DB_BACKUP_ERROR(u"主机%s数据库备份失败! err:%s" % (self.sshObj.host, output["stderr"].decode(encoding="utf-8").strip()))
db_backup_tools.DB_BACKUP_ERROR: 主机172.16.70.221数据库备份失败! err:190628 16:29:32 innobackupex: Starting the backup operation

IMPORTANT: Please check that the backup run completes successfully.
           At the end of a successful backup run innobackupex
           prints "completed OK!".

Can't locate Digest/MD5.pm in @INC (@INC contains: /usr/local/lib64/perl5 /usr/local/share/perl5 /usr/lib64/perl5/vendor_perl /usr/share/perl5/vendor_perl /usr/lib64/perl5 /usr/share/perl5 .) at - line 693.
BEGIN failed--compilation aborted at - line 693.
190628 16:29:32 Connecting to MySQL server host: 172.16.70.221, user: root, password: set, port: 3306, socket: not set
Using server version 5.7.26
/usr/local/percona-xtrabackup/bin/innobackupex version 2.4.9 based on MySQL server 5.7.13 Linux (x86_64) (revision id: a467167cdd4)
xtrabackup: uses posix_fadvise().
xtrabackup: cd to /var/lib/mysql/
xtrabackup: open files limit requested 0, set to 1024
xtrabackup: using the following InnoDB configuration:
xtrabackup:   innodb_data_home_dir = .
xtrabackup:   innodb_data_file_path = ibdata1:12M:autoextend
xtrabackup:   innodb_log_group_home_dir = ./
xtrabackup:   innodb_log_files_in_group = 2
xtrabackup:   innodb_log_file_size = 50331648
InnoDB: Number of pools: 1
innobackupex: Can't create/write to file '/mnt/nfs/588525330779870/172.16.70.221/20190719072100/xtrabackup_logfile' (Errcode: 17 - File exists)
xtrabackup: error: failed to open the target stream for 'xtrabackup_logfile'.
Job "db_backup_tools.db_backup_start (trigger: cron[day_of_week='0,1,2,3,4,5,6', minute='*/1'], next run at: 2019-07-19 07:25:00 UTC)" raised an exception
Traceback (most recent call last):
  File "/app_shell/backup-platform/lib/python3.6/site-packages/apscheduler/executors/base.py", line 125, in run_job
    retval = job.func(*job.args, **job.kwargs)
  File "/app_shell/backup-platform/webadmins/sched_task/sched_db_backup_tasks.py", line 43, in db_backup_start
    result = x.xtrabackup_full_backup(backup_to_local_path)
  File "/app_shell/backup-platform/webadmins/lib/db_backup_tools.py", line 65, in xtrabackup_full_backup
    raise DB_BACKUP_ERROR(u"主机%s数据库备份失败! err:%s" % (self.sshObj.host, output["stderr"].decode(encoding="utf-8").strip()))
db_backup_tools.DB_BACKUP_ERROR: 主机172.16.70.221数据库备份失败! err:190628 16:32:32 innobackupex: Starting the backup operation

IMPORTANT: Please check that the backup run completes successfully.
           At the end of a successful backup run innobackupex
           prints "completed OK!".

Can't locate Digest/MD5.pm in @INC (@INC contains: /usr/local/lib64/perl5 /usr/local/share/perl5 /usr/lib64/perl5/vendor_perl /usr/share/perl5/vendor_perl /usr/lib64/perl5 /usr/share/perl5 .) at - line 693.
BEGIN failed--compilation aborted at - line 693.
190628 16:32:33 Connecting to MySQL server host: 172.16.70.221, user: root, password: set, port: 3306, socket: not set
Using server version 5.7.26
/usr/local/percona-xtrabackup/bin/innobackupex version 2.4.9 based on MySQL server 5.7.13 Linux (x86_64) (revision id: a467167cdd4)
xtrabackup: uses posix_fadvise().
xtrabackup: cd to /var/lib/mysql/
xtrabackup: open files limit requested 0, set to 1024
xtrabackup: using the following InnoDB configuration:
xtrabackup:   innodb_data_home_dir = .
xtrabackup:   innodb_data_file_path = ibdata1:12M:autoextend
xtrabackup:   innodb_log_group_home_dir = ./
xtrabackup:   innodb_log_files_in_group = 2
xtrabackup:   innodb_log_file_size = 50331648
InnoDB: Number of pools: 1
innobackupex: Can't create/write to file '/mnt/nfs/588525330779870/172.16.70.221/20190719072400/xtrabackup_logfile' (Errcode: 17 - File exists)
xtrabackup: error: failed to open the target stream for 'xtrabackup_logfile'.
Job "db_backup_tools.db_backup_start (trigger: cron[day_of_week='0,1,2,3,4,5,6', minute='*/1'], next run at: 2019-07-19 07:28:00 UTC)" raised an exception
Traceback (most recent call last):
  File "/app_shell/backup-platform/lib/python3.6/site-packages/apscheduler/executors/base.py", line 125, in run_job
    retval = job.func(*job.args, **job.kwargs)
  File "/app_shell/backup-platform/webadmins/sched_task/sched_db_backup_tasks.py", line 43, in db_backup_start
    result = x.xtrabackup_full_backup(backup_to_local_path)
  File "/app_shell/backup-platform/webadmins/lib/db_backup_tools.py", line 65, in xtrabackup_full_backup
    raise DB_BACKUP_ERROR(u"主机%s数据库备份失败! err:%s" % (self.sshObj.host, output["stderr"].decode(encoding="utf-8").strip()))
db_backup_tools.DB_BACKUP_ERROR: 主机172.16.70.221数据库备份失败! err:190628 16:35:32 innobackupex: Starting the backup operation

IMPORTANT: Please check that the backup run completes successfully.
           At the end of a successful backup run innobackupex
           prints "completed OK!".

Can't locate Digest/MD5.pm in @INC (@INC contains: /usr/local/lib64/perl5 /usr/local/share/perl5 /usr/lib64/perl5/vendor_perl /usr/share/perl5/vendor_perl /usr/lib64/perl5 /usr/share/perl5 .) at - line 693.
BEGIN failed--compilation aborted at - line 693.
190628 16:35:33 Connecting to MySQL server host: 172.16.70.221, user: root, password: set, port: 3306, socket: not set
Using server version 5.7.26
/usr/local/percona-xtrabackup/bin/innobackupex version 2.4.9 based on MySQL server 5.7.13 Linux (x86_64) (revision id: a467167cdd4)
xtrabackup: uses posix_fadvise().
xtrabackup: cd to /var/lib/mysql/
xtrabackup: open files limit requested 0, set to 1024
xtrabackup: using the following InnoDB configuration:
xtrabackup:   innodb_data_home_dir = .
xtrabackup:   innodb_data_file_path = ibdata1:12M:autoextend
xtrabackup:   innodb_log_group_home_dir = ./
xtrabackup:   innodb_log_files_in_group = 2
xtrabackup:   innodb_log_file_size = 50331648
InnoDB: Number of pools: 1
innobackupex: Can't create/write to file '/mnt/nfs/588525330779870/172.16.70.221/20190719072700/xtrabackup_logfile' (Errcode: 17 - File exists)
xtrabackup: error: failed to open the target stream for 'xtrabackup_logfile'.
Job "db_backup_tools.db_backup_start (trigger: cron[day_of_week='0,1,2,3,4,5,6', minute='*/3'], next run at: 2019-07-19 07:33:00 UTC)" raised an exception
Traceback (most recent call last):
  File "/app_shell/backup-platform/lib/python3.6/site-packages/apscheduler/executors/base.py", line 125, in run_job
    retval = job.func(*job.args, **job.kwargs)
  File "/app_shell/backup-platform/webadmins/sched_task/sched_db_backup_tasks.py", line 43, in db_backup_start
    result = x.xtrabackup_full_backup(backup_to_local_path)
  File "/app_shell/backup-platform/webadmins/lib/db_backup_tools.py", line 65, in xtrabackup_full_backup
    raise DB_BACKUP_ERROR(u"主机%s数据库备份失败! err:%s" % (self.sshObj.host, output["stderr"].decode(encoding="utf-8").strip()))
db_backup_tools.DB_BACKUP_ERROR: 主机172.16.70.221数据库备份失败! err:190628 16:38:32 innobackupex: Starting the backup operation

IMPORTANT: Please check that the backup run completes successfully.
           At the end of a successful backup run innobackupex
           prints "completed OK!".

Can't locate Digest/MD5.pm in @INC (@INC contains: /usr/local/lib64/perl5 /usr/local/share/perl5 /usr/lib64/perl5/vendor_perl /usr/share/perl5/vendor_perl /usr/lib64/perl5 /usr/share/perl5 .) at - line 693.
BEGIN failed--compilation aborted at - line 693.
190628 16:38:33 Connecting to MySQL server host: 172.16.70.221, user: root, password: set, port: 3306, socket: not set
Using server version 5.7.26
/usr/local/percona-xtrabackup/bin/innobackupex version 2.4.9 based on MySQL server 5.7.13 Linux (x86_64) (revision id: a467167cdd4)
xtrabackup: uses posix_fadvise().
xtrabackup: cd to /var/lib/mysql/
xtrabackup: open files limit requested 0, set to 1024
xtrabackup: using the following InnoDB configuration:
xtrabackup:   innodb_data_home_dir = .
xtrabackup:   innodb_data_file_path = ibdata1:12M:autoextend
xtrabackup:   innodb_log_group_home_dir = ./
xtrabackup:   innodb_log_files_in_group = 2
xtrabackup:   innodb_log_file_size = 50331648
InnoDB: Number of pools: 1
innobackupex: Can't create/write to file '/mnt/nfs/588525330779870/172.16.70.221/20190719073000/xtrabackup_logfile' (Errcode: 17 - File exists)
xtrabackup: error: failed to open the target stream for 'xtrabackup_logfile'.
Job "db_backup_tools.db_backup_start (trigger: cron[day_of_week='0,1,2,3,4,5,6', minute='*/3'], next run at: 2019-07-19 07:36:00 UTC)" raised an exception
Traceback (most recent call last):
  File "/app_shell/backup-platform/lib/python3.6/site-packages/apscheduler/executors/base.py", line 125, in run_job
    retval = job.func(*job.args, **job.kwargs)
  File "/app_shell/backup-platform/webadmins/sched_task/sched_db_backup_tasks.py", line 43, in db_backup_start
    result = x.xtrabackup_full_backup(backup_to_local_path)
  File "/app_shell/backup-platform/webadmins/lib/db_backup_tools.py", line 65, in xtrabackup_full_backup
    raise DB_BACKUP_ERROR(u"主机%s数据库备份失败! err:%s" % (self.sshObj.host, output["stderr"].decode(encoding="utf-8").strip()))
db_backup_tools.DB_BACKUP_ERROR: 主机172.16.70.221数据库备份失败! err:190628 16:41:33 innobackupex: Starting the backup operation

IMPORTANT: Please check that the backup run completes successfully.
           At the end of a successful backup run innobackupex
           prints "completed OK!".

Can't locate Digest/MD5.pm in @INC (@INC contains: /usr/local/lib64/perl5 /usr/local/share/perl5 /usr/lib64/perl5/vendor_perl /usr/share/perl5/vendor_perl /usr/lib64/perl5 /usr/share/perl5 .) at - line 693.
BEGIN failed--compilation aborted at - line 693.
190628 16:41:33 Connecting to MySQL server host: 172.16.70.221, user: root, password: set, port: 3306, socket: not set
Using server version 5.7.26
/usr/local/percona-xtrabackup/bin/innobackupex version 2.4.9 based on MySQL server 5.7.13 Linux (x86_64) (revision id: a467167cdd4)
xtrabackup: uses posix_fadvise().
xtrabackup: cd to /var/lib/mysql/
xtrabackup: open files limit requested 0, set to 1024
xtrabackup: using the following InnoDB configuration:
xtrabackup:   innodb_data_home_dir = .
xtrabackup:   innodb_data_file_path = ibdata1:12M:autoextend
xtrabackup:   innodb_log_group_home_dir = ./
xtrabackup:   innodb_log_files_in_group = 2
xtrabackup:   innodb_log_file_size = 50331648
InnoDB: Number of pools: 1
innobackupex: Can't create/write to file '/mnt/nfs/588525330779870/172.16.70.221/20190719073300/xtrabackup_logfile' (Errcode: 17 - File exists)
xtrabackup: error: failed to open the target stream for 'xtrabackup_logfile'.
Job "abstract_schedule.autoAddJob (trigger: interval[0:00:05], next run at: 2019-07-19 07:39:00 UTC)" raised an exception
Traceback (most recent call last):
  File "/app_shell/backup-platform/lib/python3.6/site-packages/apscheduler/executors/base.py", line 125, in run_job
    retval = job.func(*job.args, **job.kwargs)
  File "/app_shell/backup-platform/webadmins/scheduler.py", line 82, in autoAddJob
    self.delCronJob(job_id=j)
  File "/app_shell/backup-platform/webadmins/scheduler.py", line 48, in delCronJob
    if not jid["job_id"]:
KeyError: 'job_id'
Job "abstract_schedule.autoAddJob (trigger: interval[0:00:05], next run at: 2019-07-19 07:39:05 UTC)" raised an exception
Traceback (most recent call last):
  File "/app_shell/backup-platform/lib/python3.6/site-packages/apscheduler/executors/base.py", line 125, in run_job
    retval = job.func(*job.args, **job.kwargs)
  File "/app_shell/backup-platform/webadmins/scheduler.py", line 82, in autoAddJob
    self.delCronJob(job_id=j)
  File "/app_shell/backup-platform/webadmins/scheduler.py", line 48, in delCronJob
    if not jid["job_id"]:
KeyError: 'job_id'
Job "db_backup_tools.db_backup_start (trigger: cron[day_of_week='0,1,2,3,4,5,6', minute='*/1'], next run at: 2019-07-19 07:40:00 UTC)" raised an exception
Traceback (most recent call last):
  File "/app_shell/backup-platform/lib/python3.6/site-packages/apscheduler/executors/base.py", line 125, in run_job
    retval = job.func(*job.args, **job.kwargs)
  File "/app_shell/backup-platform/webadmins/sched_task/sched_db_backup_tasks.py", line 43, in db_backup_start
    result = x.xtrabackup_full_backup(backup_to_local_path)
  File "/app_shell/backup-platform/webadmins/lib/db_backup_tools.py", line 65, in xtrabackup_full_backup
    raise DB_BACKUP_ERROR(u"主机%s数据库备份失败! err:%s" % (self.sshObj.host, output["stderr"].decode(encoding="utf-8").strip()))
db_backup_tools.DB_BACKUP_ERROR: 主机172.16.70.221数据库备份失败! err:190628 16:47:32 innobackupex: Starting the backup operation

IMPORTANT: Please check that the backup run completes successfully.
           At the end of a successful backup run innobackupex
           prints "completed OK!".

Can't locate Digest/MD5.pm in @INC (@INC contains: /usr/local/lib64/perl5 /usr/local/share/perl5 /usr/lib64/perl5/vendor_perl /usr/share/perl5/vendor_perl /usr/lib64/perl5 /usr/share/perl5 .) at - line 693.
BEGIN failed--compilation aborted at - line 693.
190628 16:47:33 Connecting to MySQL server host: 172.16.70.221, user: root, password: set, port: 3306, socket: not set
Using server version 5.7.26
/usr/local/percona-xtrabackup/bin/innobackupex version 2.4.9 based on MySQL server 5.7.13 Linux (x86_64) (revision id: a467167cdd4)
xtrabackup: uses posix_fadvise().
xtrabackup: cd to /var/lib/mysql/
xtrabackup: open files limit requested 0, set to 1024
xtrabackup: using the following InnoDB configuration:
xtrabackup:   innodb_data_home_dir = .
xtrabackup:   innodb_data_file_path = ibdata1:12M:autoextend
xtrabackup:   innodb_log_group_home_dir = ./
xtrabackup:   innodb_log_files_in_group = 2
xtrabackup:   innodb_log_file_size = 50331648
InnoDB: Number of pools: 1
innobackupex: Can't create/write to file '/mnt/nfs/588525330779870/172.16.70.221/20190719073900/xtrabackup_logfile' (Errcode: 17 - File exists)
xtrabackup: error: failed to open the target stream for 'xtrabackup_logfile'.
Job "abstract_schedule.autoAddJob (trigger: interval[0:00:05], next run at: 2019-07-19 07:39:10 UTC)" raised an exception
Traceback (most recent call last):
  File "/app_shell/backup-platform/lib/python3.6/site-packages/apscheduler/executors/base.py", line 125, in run_job
    retval = job.func(*job.args, **job.kwargs)
  File "/app_shell/backup-platform/webadmins/scheduler.py", line 82, in autoAddJob
    self.delCronJob(job_id=j)
  File "/app_shell/backup-platform/webadmins/scheduler.py", line 48, in delCronJob
    if not jid["job_id"]:
KeyError: 'job_id'
Job "abstract_schedule.autoAddJob (trigger: interval[0:00:05], next run at: 2019-07-19 07:39:15 UTC)" raised an exception
Traceback (most recent call last):
  File "/app_shell/backup-platform/lib/python3.6/site-packages/apscheduler/executors/base.py", line 125, in run_job
    retval = job.func(*job.args, **job.kwargs)
  File "/app_shell/backup-platform/webadmins/scheduler.py", line 82, in autoAddJob
    self.delCronJob(job_id=j)
  File "/app_shell/backup-platform/webadmins/scheduler.py", line 48, in delCronJob
    if not jid["job_id"]:
KeyError: 'job_id'
Job "abstract_schedule.autoAddJob (trigger: interval[0:00:05], next run at: 2019-07-19 07:39:20 UTC)" raised an exception
Traceback (most recent call last):
  File "/app_shell/backup-platform/lib/python3.6/site-packages/apscheduler/executors/base.py", line 125, in run_job
    retval = job.func(*job.args, **job.kwargs)
  File "/app_shell/backup-platform/webadmins/scheduler.py", line 82, in autoAddJob
    self.delCronJob(job_id=j)
  File "/app_shell/backup-platform/webadmins/scheduler.py", line 48, in delCronJob
    if not jid["job_id"]:
KeyError: 'job_id'
Job "abstract_schedule.autoAddJob (trigger: interval[0:00:05], next run at: 2019-07-19 07:39:25 UTC)" raised an exception
Traceback (most recent call last):
  File "/app_shell/backup-platform/lib/python3.6/site-packages/apscheduler/executors/base.py", line 125, in run_job
    retval = job.func(*job.args, **job.kwargs)
  File "/app_shell/backup-platform/webadmins/scheduler.py", line 82, in autoAddJob
    self.delCronJob(job_id=j)
  File "/app_shell/backup-platform/webadmins/scheduler.py", line 48, in delCronJob
    if not jid["job_id"]:
KeyError: 'job_id'
Job "abstract_schedule.autoAddJob (trigger: interval[0:00:05], next run at: 2019-07-19 07:39:30 UTC)" raised an exception
Traceback (most recent call last):
  File "/app_shell/backup-platform/lib/python3.6/site-packages/apscheduler/executors/base.py", line 125, in run_job
    retval = job.func(*job.args, **job.kwargs)
  File "/app_shell/backup-platform/webadmins/scheduler.py", line 82, in autoAddJob
    self.delCronJob(job_id=j)
  File "/app_shell/backup-platform/webadmins/scheduler.py", line 48, in delCronJob
    if not jid["job_id"]:
KeyError: 'job_id'
Job "abstract_schedule.autoAddJob (trigger: interval[0:00:05], next run at: 2019-07-19 07:39:35 UTC)" raised an exception
Traceback (most recent call last):
  File "/app_shell/backup-platform/lib/python3.6/site-packages/apscheduler/executors/base.py", line 125, in run_job
    retval = job.func(*job.args, **job.kwargs)
  File "/app_shell/backup-platform/webadmins/scheduler.py", line 82, in autoAddJob
    self.delCronJob(job_id=j)
  File "/app_shell/backup-platform/webadmins/scheduler.py", line 48, in delCronJob
    if not jid["job_id"]:
KeyError: 'job_id'
Job "abstract_schedule.autoAddJob (trigger: interval[0:00:05], next run at: 2019-07-19 07:39:40 UTC)" raised an exception
Traceback (most recent call last):
  File "/app_shell/backup-platform/lib/python3.6/site-packages/apscheduler/executors/base.py", line 125, in run_job
    retval = job.func(*job.args, **job.kwargs)
  File "/app_shell/backup-platform/webadmins/scheduler.py", line 82, in autoAddJob
    self.delCronJob(job_id=j)
  File "/app_shell/backup-platform/webadmins/scheduler.py", line 48, in delCronJob
    if not jid["job_id"]:
KeyError: 'job_id'
Job "abstract_schedule.autoAddJob (trigger: interval[0:00:05], next run at: 2019-07-19 07:39:45 UTC)" raised an exception
Traceback (most recent call last):
  File "/app_shell/backup-platform/lib/python3.6/site-packages/apscheduler/executors/base.py", line 125, in run_job
    retval = job.func(*job.args, **job.kwargs)
  File "/app_shell/backup-platform/webadmins/scheduler.py", line 82, in autoAddJob
    self.delCronJob(job_id=j)
  File "/app_shell/backup-platform/webadmins/scheduler.py", line 48, in delCronJob
    if not jid["job_id"]:
KeyError: 'job_id'
Job "abstract_schedule.autoAddJob (trigger: interval[0:00:05], next run at: 2019-07-19 07:39:50 UTC)" raised an exception
Traceback (most recent call last):
  File "/app_shell/backup-platform/lib/python3.6/site-packages/apscheduler/executors/base.py", line 125, in run_job
    retval = job.func(*job.args, **job.kwargs)
  File "/app_shell/backup-platform/webadmins/scheduler.py", line 82, in autoAddJob
    self.delCronJob(job_id=j)
  File "/app_shell/backup-platform/webadmins/scheduler.py", line 48, in delCronJob
    if not jid["job_id"]:
KeyError: 'job_id'
Job "abstract_schedule.autoAddJob (trigger: interval[0:00:05], next run at: 2019-07-19 07:39:55 UTC)" raised an exception
Traceback (most recent call last):
  File "/app_shell/backup-platform/lib/python3.6/site-packages/apscheduler/executors/base.py", line 125, in run_job
    retval = job.func(*job.args, **job.kwargs)
  File "/app_shell/backup-platform/webadmins/scheduler.py", line 82, in autoAddJob
    self.delCronJob(job_id=j)
  File "/app_shell/backup-platform/webadmins/scheduler.py", line 48, in delCronJob
    if not jid["job_id"]:
KeyError: 'job_id'
Job "abstract_schedule.autoAddJob (trigger: interval[0:00:05], next run at: 2019-07-19 07:40:00 UTC)" raised an exception
Traceback (most recent call last):
  File "/app_shell/backup-platform/lib/python3.6/site-packages/apscheduler/executors/base.py", line 125, in run_job
    retval = job.func(*job.args, **job.kwargs)
  File "/app_shell/backup-platform/webadmins/scheduler.py", line 82, in autoAddJob
    self.delCronJob(job_id=j)
  File "/app_shell/backup-platform/webadmins/scheduler.py", line 48, in delCronJob
    if not jid["job_id"]:
KeyError: 'job_id'
Job "abstract_schedule.autoAddJob (trigger: interval[0:00:05], next run at: 2019-07-19 07:40:05 UTC)" raised an exception
Traceback (most recent call last):
  File "/app_shell/backup-platform/lib/python3.6/site-packages/apscheduler/executors/base.py", line 125, in run_job
    retval = job.func(*job.args, **job.kwargs)
  File "/app_shell/backup-platform/webadmins/scheduler.py", line 82, in autoAddJob
    self.delCronJob(job_id=j)
  File "/app_shell/backup-platform/webadmins/scheduler.py", line 48, in delCronJob
    if not jid["job_id"]:
KeyError: 'job_id'
Job "abstract_schedule.autoAddJob (trigger: interval[0:00:05], next run at: 2019-07-19 07:40:10 UTC)" raised an exception
Traceback (most recent call last):
  File "/app_shell/backup-platform/lib/python3.6/site-packages/apscheduler/executors/base.py", line 125, in run_job
    retval = job.func(*job.args, **job.kwargs)
  File "/app_shell/backup-platform/webadmins/scheduler.py", line 82, in autoAddJob
    self.delCronJob(job_id=j)
  File "/app_shell/backup-platform/webadmins/scheduler.py", line 48, in delCronJob
    if not jid["job_id"]:
KeyError: 'job_id'
Job "abstract_schedule.autoAddJob (trigger: interval[0:00:05], next run at: 2019-07-19 07:40:15 UTC)" raised an exception
Traceback (most recent call last):
  File "/app_shell/backup-platform/lib/python3.6/site-packages/apscheduler/executors/base.py", line 125, in run_job
    retval = job.func(*job.args, **job.kwargs)
  File "/app_shell/backup-platform/webadmins/scheduler.py", line 82, in autoAddJob
    self.delCronJob(job_id=j)
  File "/app_shell/backup-platform/webadmins/scheduler.py", line 48, in delCronJob
    if not jid["job_id"]:
KeyError: 'job_id'
Job "abstract_schedule.autoAddJob (trigger: interval[0:00:05], next run at: 2019-07-19 07:40:20 UTC)" raised an exception
Traceback (most recent call last):
  File "/app_shell/backup-platform/lib/python3.6/site-packages/apscheduler/executors/base.py", line 125, in run_job
    retval = job.func(*job.args, **job.kwargs)
  File "/app_shell/backup-platform/webadmins/scheduler.py", line 82, in autoAddJob
    self.delCronJob(job_id=j)
  File "/app_shell/backup-platform/webadmins/scheduler.py", line 48, in delCronJob
    if not jid["job_id"]:
KeyError: 'job_id'
Job "abstract_schedule.autoAddJob (trigger: interval[0:00:05], next run at: 2019-07-19 07:40:25 UTC)" raised an exception
Traceback (most recent call last):
  File "/app_shell/backup-platform/lib/python3.6/site-packages/apscheduler/executors/base.py", line 125, in run_job
    retval = job.func(*job.args, **job.kwargs)
  File "/app_shell/backup-platform/webadmins/scheduler.py", line 82, in autoAddJob
    self.delCronJob(job_id=j)
  File "/app_shell/backup-platform/webadmins/scheduler.py", line 48, in delCronJob
    if not jid["job_id"]:
KeyError: 'job_id'
Job "abstract_schedule.autoAddJob (trigger: interval[0:00:05], next run at: 2019-07-19 07:40:30 UTC)" raised an exception
Traceback (most recent call last):
  File "/app_shell/backup-platform/lib/python3.6/site-packages/apscheduler/executors/base.py", line 125, in run_job
    retval = job.func(*job.args, **job.kwargs)
  File "/app_shell/backup-platform/webadmins/scheduler.py", line 82, in autoAddJob
    self.delCronJob(job_id=j)
  File "/app_shell/backup-platform/webadmins/scheduler.py", line 48, in delCronJob
    if not jid["job_id"]:
KeyError: 'job_id'
Job "abstract_schedule.autoAddJob (trigger: interval[0:00:05], next run at: 2019-07-19 07:40:35 UTC)" raised an exception
Traceback (most recent call last):
  File "/app_shell/backup-platform/lib/python3.6/site-packages/apscheduler/executors/base.py", line 125, in run_job
    retval = job.func(*job.args, **job.kwargs)
  File "/app_shell/backup-platform/webadmins/scheduler.py", line 82, in autoAddJob
    self.delCronJob(job_id=j)
  File "/app_shell/backup-platform/webadmins/scheduler.py", line 48, in delCronJob
    if not jid["job_id"]:
KeyError: 'job_id'
Job "abstract_schedule.autoAddJob (trigger: interval[0:00:05], next run at: 2019-07-19 07:40:40 UTC)" raised an exception
Traceback (most recent call last):
  File "/app_shell/backup-platform/lib/python3.6/site-packages/apscheduler/executors/base.py", line 125, in run_job
    retval = job.func(*job.args, **job.kwargs)
  File "/app_shell/backup-platform/webadmins/scheduler.py", line 82, in autoAddJob
    self.delCronJob(job_id=j)
  File "/app_shell/backup-platform/webadmins/scheduler.py", line 48, in delCronJob
    if not jid["job_id"]:
KeyError: 'job_id'
Job "abstract_schedule.autoAddJob (trigger: interval[0:00:05], next run at: 2019-07-19 07:40:45 UTC)" raised an exception
Traceback (most recent call last):
  File "/app_shell/backup-platform/lib/python3.6/site-packages/apscheduler/executors/base.py", line 125, in run_job
    retval = job.func(*job.args, **job.kwargs)
  File "/app_shell/backup-platform/webadmins/scheduler.py", line 82, in autoAddJob
    self.delCronJob(job_id=j)
  File "/app_shell/backup-platform/webadmins/scheduler.py", line 48, in delCronJob
    if not jid["job_id"]:
KeyError: 'job_id'
Job "abstract_schedule.autoAddJob (trigger: interval[0:00:05], next run at: 2019-07-19 07:40:50 UTC)" raised an exception
Traceback (most recent call last):
  File "/app_shell/backup-platform/lib/python3.6/site-packages/apscheduler/executors/base.py", line 125, in run_job
    retval = job.func(*job.args, **job.kwargs)
  File "/app_shell/backup-platform/webadmins/scheduler.py", line 82, in autoAddJob
    self.delCronJob(job_id=j)
  File "/app_shell/backup-platform/webadmins/scheduler.py", line 48, in delCronJob
    if not jid["job_id"]:
KeyError: 'job_id'
Job "abstract_schedule.autoAddJob (trigger: interval[0:00:05], next run at: 2019-07-19 07:40:55 UTC)" raised an exception
Traceback (most recent call last):
  File "/app_shell/backup-platform/lib/python3.6/site-packages/apscheduler/executors/base.py", line 125, in run_job
    retval = job.func(*job.args, **job.kwargs)
  File "/app_shell/backup-platform/webadmins/scheduler.py", line 82, in autoAddJob
    self.delCronJob(job_id=j)
  File "/app_shell/backup-platform/webadmins/scheduler.py", line 48, in delCronJob
    if not jid["job_id"]:
KeyError: 'job_id'
Job "abstract_schedule.autoAddJob (trigger: interval[0:00:05], next run at: 2019-07-19 07:41:00 UTC)" raised an exception
Traceback (most recent call last):
  File "/app_shell/backup-platform/lib/python3.6/site-packages/apscheduler/executors/base.py", line 125, in run_job
    retval = job.func(*job.args, **job.kwargs)
  File "/app_shell/backup-platform/webadmins/scheduler.py", line 82, in autoAddJob
    self.delCronJob(job_id=j)
  File "/app_shell/backup-platform/webadmins/scheduler.py", line 48, in delCronJob
    if not jid["job_id"]:
KeyError: 'job_id'
Job "abstract_schedule.autoAddJob (trigger: interval[0:00:05], next run at: 2019-07-19 07:41:05 UTC)" raised an exception
Traceback (most recent call last):
  File "/app_shell/backup-platform/lib/python3.6/site-packages/apscheduler/executors/base.py", line 125, in run_job
    retval = job.func(*job.args, **job.kwargs)
  File "/app_shell/backup-platform/webadmins/scheduler.py", line 82, in autoAddJob
    self.delCronJob(job_id=j)
  File "/app_shell/backup-platform/webadmins/scheduler.py", line 48, in delCronJob
    if not jid["job_id"]:
KeyError: 'job_id'
Job "abstract_schedule.autoAddJob (trigger: interval[0:00:05], next run at: 2019-07-19 07:41:10 UTC)" raised an exception
Traceback (most recent call last):
  File "/app_shell/backup-platform/lib/python3.6/site-packages/apscheduler/executors/base.py", line 125, in run_job
    retval = job.func(*job.args, **job.kwargs)
  File "/app_shell/backup-platform/webadmins/scheduler.py", line 82, in autoAddJob
    self.delCronJob(job_id=j)
  File "/app_shell/backup-platform/webadmins/scheduler.py", line 48, in delCronJob
    if not jid["job_id"]:
KeyError: 'job_id'
Job "abstract_schedule.autoAddJob (trigger: interval[0:00:05], next run at: 2019-07-19 07:41:15 UTC)" raised an exception
Traceback (most recent call last):
  File "/app_shell/backup-platform/lib/python3.6/site-packages/apscheduler/executors/base.py", line 125, in run_job
    retval = job.func(*job.args, **job.kwargs)
  File "/app_shell/backup-platform/webadmins/scheduler.py", line 82, in autoAddJob
    self.delCronJob(job_id=j)
  File "/app_shell/backup-platform/webadmins/scheduler.py", line 48, in delCronJob
    if not jid["job_id"]:
KeyError: 'job_id'
Job "abstract_schedule.autoAddJob (trigger: interval[0:00:05], next run at: 2019-07-19 07:41:20 UTC)" raised an exception
Traceback (most recent call last):
  File "/app_shell/backup-platform/lib/python3.6/site-packages/apscheduler/executors/base.py", line 125, in run_job
    retval = job.func(*job.args, **job.kwargs)
  File "/app_shell/backup-platform/webadmins/scheduler.py", line 82, in autoAddJob
    self.delCronJob(job_id=j)
  File "/app_shell/backup-platform/webadmins/scheduler.py", line 48, in delCronJob
    if not jid["job_id"]:
KeyError: 'job_id'
Job "abstract_schedule.autoAddJob (trigger: interval[0:00:05], next run at: 2019-07-19 07:41:25 UTC)" raised an exception
Traceback (most recent call last):
  File "/app_shell/backup-platform/lib/python3.6/site-packages/apscheduler/executors/base.py", line 125, in run_job
    retval = job.func(*job.args, **job.kwargs)
  File "/app_shell/backup-platform/webadmins/scheduler.py", line 82, in autoAddJob
    self.delCronJob(job_id=j)
  File "/app_shell/backup-platform/webadmins/scheduler.py", line 48, in delCronJob
    if not jid["job_id"]:
KeyError: 'job_id'
Job "abstract_schedule.autoAddJob (trigger: interval[0:00:05], next run at: 2019-07-19 07:41:30 UTC)" raised an exception
Traceback (most recent call last):
  File "/app_shell/backup-platform/lib/python3.6/site-packages/apscheduler/executors/base.py", line 125, in run_job
    retval = job.func(*job.args, **job.kwargs)
  File "/app_shell/backup-platform/webadmins/scheduler.py", line 82, in autoAddJob
    self.delCronJob(job_id=j)
  File "/app_shell/backup-platform/webadmins/scheduler.py", line 48, in delCronJob
    if not jid["job_id"]:
KeyError: 'job_id'
Job "abstract_schedule.autoAddJob (trigger: interval[0:00:05], next run at: 2019-07-19 07:41:35 UTC)" raised an exception
Traceback (most recent call last):
  File "/app_shell/backup-platform/lib/python3.6/site-packages/apscheduler/executors/base.py", line 125, in run_job
    retval = job.func(*job.args, **job.kwargs)
  File "/app_shell/backup-platform/webadmins/scheduler.py", line 82, in autoAddJob
    self.delCronJob(job_id=j)
  File "/app_shell/backup-platform/webadmins/scheduler.py", line 48, in delCronJob
    if not jid["job_id"]:
KeyError: 'job_id'
Job "abstract_schedule.autoAddJob (trigger: interval[0:00:05], next run at: 2019-07-19 07:41:40 UTC)" raised an exception
Traceback (most recent call last):
  File "/app_shell/backup-platform/lib/python3.6/site-packages/apscheduler/executors/base.py", line 125, in run_job
    retval = job.func(*job.args, **job.kwargs)
  File "/app_shell/backup-platform/webadmins/scheduler.py", line 82, in autoAddJob
    self.delCronJob(job_id=j)
  File "/app_shell/backup-platform/webadmins/scheduler.py", line 48, in delCronJob
    if not jid["job_id"]:
KeyError: 'job_id'
Job "abstract_schedule.autoAddJob (trigger: interval[0:00:05], next run at: 2019-07-19 07:41:45 UTC)" raised an exception
Traceback (most recent call last):
  File "/app_shell/backup-platform/lib/python3.6/site-packages/apscheduler/executors/base.py", line 125, in run_job
    retval = job.func(*job.args, **job.kwargs)
  File "/app_shell/backup-platform/webadmins/scheduler.py", line 82, in autoAddJob
    self.delCronJob(job_id=j)
  File "/app_shell/backup-platform/webadmins/scheduler.py", line 48, in delCronJob
    if not jid["job_id"]:
KeyError: 'job_id'
Job "abstract_schedule.autoAddJob (trigger: interval[0:00:05], next run at: 2019-07-19 07:41:50 UTC)" raised an exception
Traceback (most recent call last):
  File "/app_shell/backup-platform/lib/python3.6/site-packages/apscheduler/executors/base.py", line 125, in run_job
    retval = job.func(*job.args, **job.kwargs)
  File "/app_shell/backup-platform/webadmins/scheduler.py", line 82, in autoAddJob
    self.delCronJob(job_id=j)
  File "/app_shell/backup-platform/webadmins/scheduler.py", line 48, in delCronJob
    if not jid["job_id"]:
KeyError: 'job_id'
Job "abstract_schedule.autoAddJob (trigger: interval[0:00:05], next run at: 2019-07-19 07:41:55 UTC)" raised an exception
Traceback (most recent call last):
  File "/app_shell/backup-platform/lib/python3.6/site-packages/apscheduler/executors/base.py", line 125, in run_job
    retval = job.func(*job.args, **job.kwargs)
  File "/app_shell/backup-platform/webadmins/scheduler.py", line 82, in autoAddJob
    self.delCronJob(job_id=j)
  File "/app_shell/backup-platform/webadmins/scheduler.py", line 48, in delCronJob
    if not jid["job_id"]:
KeyError: 'job_id'
Job "abstract_schedule.autoAddJob (trigger: interval[0:00:05], next run at: 2019-07-19 07:42:00 UTC)" raised an exception
Traceback (most recent call last):
  File "/app_shell/backup-platform/lib/python3.6/site-packages/apscheduler/executors/base.py", line 125, in run_job
    retval = job.func(*job.args, **job.kwargs)
  File "/app_shell/backup-platform/webadmins/scheduler.py", line 82, in autoAddJob
    self.delCronJob(job_id=j)
  File "/app_shell/backup-platform/webadmins/scheduler.py", line 48, in delCronJob
    if not jid["job_id"]:
KeyError: 'job_id'
Job "abstract_schedule.autoAddJob (trigger: interval[0:00:05], next run at: 2019-07-19 07:42:05 UTC)" raised an exception
Traceback (most recent call last):
  File "/app_shell/backup-platform/lib/python3.6/site-packages/apscheduler/executors/base.py", line 125, in run_job
    retval = job.func(*job.args, **job.kwargs)
  File "/app_shell/backup-platform/webadmins/scheduler.py", line 82, in autoAddJob
    self.delCronJob(job_id=j)
  File "/app_shell/backup-platform/webadmins/scheduler.py", line 48, in delCronJob
    if not jid["job_id"]:
KeyError: 'job_id'
Job "db_backup_tools.db_backup_start (trigger: cron[day_of_week='0,1,2,3,4,5,6', minute='*/3'], next run at: 2019-07-19 07:45:00 UTC)" raised an exception
Traceback (most recent call last):
  File "/app_shell/backup-platform/lib/python3.6/site-packages/apscheduler/executors/base.py", line 125, in run_job
    retval = job.func(*job.args, **job.kwargs)
  File "/app_shell/backup-platform/webadmins/sched_task/sched_db_backup_tasks.py", line 43, in db_backup_start
    result = x.xtrabackup_full_backup(backup_to_local_path)
  File "/app_shell/backup-platform/webadmins/lib/db_backup_tools.py", line 65, in xtrabackup_full_backup
    raise DB_BACKUP_ERROR(u"主机%s数据库备份失败! err:%s" % (self.sshObj.host, output["stderr"].decode(encoding="utf-8").strip()))
db_backup_tools.DB_BACKUP_ERROR: 主机172.16.70.221数据库备份失败! err:190628 16:50:32 innobackupex: Starting the backup operation

IMPORTANT: Please check that the backup run completes successfully.
           At the end of a successful backup run innobackupex
           prints "completed OK!".

Can't locate Digest/MD5.pm in @INC (@INC contains: /usr/local/lib64/perl5 /usr/local/share/perl5 /usr/lib64/perl5/vendor_perl /usr/share/perl5/vendor_perl /usr/lib64/perl5 /usr/share/perl5 .) at - line 693.
BEGIN failed--compilation aborted at - line 693.
190628 16:50:33 Connecting to MySQL server host: 172.16.70.221, user: root, password: set, port: 3306, socket: not set
Using server version 5.7.26
/usr/local/percona-xtrabackup/bin/innobackupex version 2.4.9 based on MySQL server 5.7.13 Linux (x86_64) (revision id: a467167cdd4)
xtrabackup: uses posix_fadvise().
xtrabackup: cd to /var/lib/mysql/
xtrabackup: open files limit requested 0, set to 1024
xtrabackup: using the following InnoDB configuration:
xtrabackup:   innodb_data_home_dir = .
xtrabackup:   innodb_data_file_path = ibdata1:12M:autoextend
xtrabackup:   innodb_log_group_home_dir = ./
xtrabackup:   innodb_log_files_in_group = 2
xtrabackup:   innodb_log_file_size = 50331648
InnoDB: Number of pools: 1
innobackupex: Can't create/write to file '/mnt/nfs/588525330779870/172.16.70.221/20190719074200/xtrabackup_logfile' (Errcode: 17 - File exists)
xtrabackup: error: failed to open the target stream for 'xtrabackup_logfile'.
Job "abstract_schedule.autoAddJob (trigger: interval[0:00:05], next run at: 2019-07-19 07:42:10 UTC)" raised an exception
Traceback (most recent call last):
  File "/app_shell/backup-platform/lib/python3.6/site-packages/apscheduler/executors/base.py", line 125, in run_job
    retval = job.func(*job.args, **job.kwargs)
  File "/app_shell/backup-platform/webadmins/scheduler.py", line 82, in autoAddJob
    self.delCronJob(job_id=j)
  File "/app_shell/backup-platform/webadmins/scheduler.py", line 48, in delCronJob
    if not jid["job_id"]:
KeyError: 'job_id'
Job "abstract_schedule.autoAddJob (trigger: interval[0:00:05], next run at: 2019-07-19 07:42:15 UTC)" raised an exception
Traceback (most recent call last):
  File "/app_shell/backup-platform/lib/python3.6/site-packages/apscheduler/executors/base.py", line 125, in run_job
    retval = job.func(*job.args, **job.kwargs)
  File "/app_shell/backup-platform/webadmins/scheduler.py", line 82, in autoAddJob
    self.delCronJob(job_id=j)
  File "/app_shell/backup-platform/webadmins/scheduler.py", line 48, in delCronJob
    if not jid["job_id"]:
KeyError: 'job_id'
Job "abstract_schedule.autoAddJob (trigger: interval[0:00:05], next run at: 2019-07-19 07:42:20 UTC)" raised an exception
Traceback (most recent call last):
  File "/app_shell/backup-platform/lib/python3.6/site-packages/apscheduler/executors/base.py", line 125, in run_job
    retval = job.func(*job.args, **job.kwargs)
  File "/app_shell/backup-platform/webadmins/scheduler.py", line 82, in autoAddJob
    self.delCronJob(job_id=j)
  File "/app_shell/backup-platform/webadmins/scheduler.py", line 48, in delCronJob
    if not jid["job_id"]:
KeyError: 'job_id'
Job "abstract_schedule.autoAddJob (trigger: interval[0:00:05], next run at: 2019-07-19 07:42:25 UTC)" raised an exception
Traceback (most recent call last):
  File "/app_shell/backup-platform/lib/python3.6/site-packages/apscheduler/executors/base.py", line 125, in run_job
    retval = job.func(*job.args, **job.kwargs)
  File "/app_shell/backup-platform/webadmins/scheduler.py", line 82, in autoAddJob
    self.delCronJob(job_id=j)
  File "/app_shell/backup-platform/webadmins/scheduler.py", line 48, in delCronJob
    if not jid["job_id"]:
KeyError: 'job_id'
Job "abstract_schedule.autoAddJob (trigger: interval[0:00:05], next run at: 2019-07-19 07:42:30 UTC)" raised an exception
Traceback (most recent call last):
  File "/app_shell/backup-platform/lib/python3.6/site-packages/apscheduler/executors/base.py", line 125, in run_job
    retval = job.func(*job.args, **job.kwargs)
  File "/app_shell/backup-platform/webadmins/scheduler.py", line 82, in autoAddJob
    self.delCronJob(job_id=j)
  File "/app_shell/backup-platform/webadmins/scheduler.py", line 48, in delCronJob
    if not jid["job_id"]:
KeyError: 'job_id'
Job "abstract_schedule.autoAddJob (trigger: interval[0:00:05], next run at: 2019-07-19 07:42:35 UTC)" raised an exception
Traceback (most recent call last):
  File "/app_shell/backup-platform/lib/python3.6/site-packages/apscheduler/executors/base.py", line 125, in run_job
    retval = job.func(*job.args, **job.kwargs)
  File "/app_shell/backup-platform/webadmins/scheduler.py", line 82, in autoAddJob
    self.delCronJob(job_id=j)
  File "/app_shell/backup-platform/webadmins/scheduler.py", line 48, in delCronJob
    if not jid["job_id"]:
KeyError: 'job_id'
Job "abstract_schedule.autoAddJob (trigger: interval[0:00:05], next run at: 2019-07-19 07:42:40 UTC)" raised an exception
Traceback (most recent call last):
  File "/app_shell/backup-platform/lib/python3.6/site-packages/apscheduler/executors/base.py", line 125, in run_job
    retval = job.func(*job.args, **job.kwargs)
  File "/app_shell/backup-platform/webadmins/scheduler.py", line 82, in autoAddJob
    self.delCronJob(job_id=j)
  File "/app_shell/backup-platform/webadmins/scheduler.py", line 48, in delCronJob
    if not jid["job_id"]:
KeyError: 'job_id'
Job "abstract_schedule.autoAddJob (trigger: interval[0:00:05], next run at: 2019-07-19 07:42:45 UTC)" raised an exception
Traceback (most recent call last):
  File "/app_shell/backup-platform/lib/python3.6/site-packages/apscheduler/executors/base.py", line 125, in run_job
    retval = job.func(*job.args, **job.kwargs)
  File "/app_shell/backup-platform/webadmins/scheduler.py", line 82, in autoAddJob
    self.delCronJob(job_id=j)
  File "/app_shell/backup-platform/webadmins/scheduler.py", line 48, in delCronJob
    if not jid["job_id"]:
KeyError: 'job_id'
Job "abstract_schedule.autoAddJob (trigger: interval[0:00:05], next run at: 2019-07-19 07:42:50 UTC)" raised an exception
Traceback (most recent call last):
  File "/app_shell/backup-platform/lib/python3.6/site-packages/apscheduler/executors/base.py", line 125, in run_job
    retval = job.func(*job.args, **job.kwargs)
  File "/app_shell/backup-platform/webadmins/scheduler.py", line 82, in autoAddJob
    self.delCronJob(job_id=j)
  File "/app_shell/backup-platform/webadmins/scheduler.py", line 48, in delCronJob
    if not jid["job_id"]:
KeyError: 'job_id'
Job "abstract_schedule.autoAddJob (trigger: interval[0:00:05], next run at: 2019-07-19 07:42:55 UTC)" raised an exception
Traceback (most recent call last):
  File "/app_shell/backup-platform/lib/python3.6/site-packages/apscheduler/executors/base.py", line 125, in run_job
    retval = job.func(*job.args, **job.kwargs)
  File "/app_shell/backup-platform/webadmins/scheduler.py", line 82, in autoAddJob
    self.delCronJob(job_id=j)
  File "/app_shell/backup-platform/webadmins/scheduler.py", line 48, in delCronJob
    if not jid["job_id"]:
KeyError: 'job_id'
Job "abstract_schedule.autoAddJob (trigger: interval[0:00:05], next run at: 2019-07-19 07:43:00 UTC)" raised an exception
Traceback (most recent call last):
  File "/app_shell/backup-platform/lib/python3.6/site-packages/apscheduler/executors/base.py", line 125, in run_job
    retval = job.func(*job.args, **job.kwargs)
  File "/app_shell/backup-platform/webadmins/scheduler.py", line 82, in autoAddJob
    self.delCronJob(job_id=j)
  File "/app_shell/backup-platform/webadmins/scheduler.py", line 48, in delCronJob
    if not jid["job_id"]:
KeyError: 'job_id'
Job "abstract_schedule.autoAddJob (trigger: interval[0:00:05], next run at: 2019-07-19 07:43:05 UTC)" raised an exception
Traceback (most recent call last):
  File "/app_shell/backup-platform/lib/python3.6/site-packages/apscheduler/executors/base.py", line 125, in run_job
    retval = job.func(*job.args, **job.kwargs)
  File "/app_shell/backup-platform/webadmins/scheduler.py", line 82, in autoAddJob
    self.delCronJob(job_id=j)
  File "/app_shell/backup-platform/webadmins/scheduler.py", line 48, in delCronJob
    if not jid["job_id"]:
KeyError: 'job_id'
Job "abstract_schedule.autoAddJob (trigger: interval[0:00:05], next run at: 2019-07-19 07:43:10 UTC)" raised an exception
Traceback (most recent call last):
  File "/app_shell/backup-platform/lib/python3.6/site-packages/apscheduler/executors/base.py", line 125, in run_job
    retval = job.func(*job.args, **job.kwargs)
  File "/app_shell/backup-platform/webadmins/scheduler.py", line 82, in autoAddJob
    self.delCronJob(job_id=j)
  File "/app_shell/backup-platform/webadmins/scheduler.py", line 48, in delCronJob
    if not jid["job_id"]:
KeyError: 'job_id'
Job "abstract_schedule.autoAddJob (trigger: interval[0:00:05], next run at: 2019-07-19 07:43:15 UTC)" raised an exception
Traceback (most recent call last):
  File "/app_shell/backup-platform/lib/python3.6/site-packages/apscheduler/executors/base.py", line 125, in run_job
    retval = job.func(*job.args, **job.kwargs)
  File "/app_shell/backup-platform/webadmins/scheduler.py", line 82, in autoAddJob
    self.delCronJob(job_id=j)
  File "/app_shell/backup-platform/webadmins/scheduler.py", line 48, in delCronJob
    if not jid["job_id"]:
KeyError: 'job_id'
Job "abstract_schedule.autoAddJob (trigger: interval[0:00:05], next run at: 2019-07-19 07:43:20 UTC)" raised an exception
Traceback (most recent call last):
  File "/app_shell/backup-platform/lib/python3.6/site-packages/apscheduler/executors/base.py", line 125, in run_job
    retval = job.func(*job.args, **job.kwargs)
  File "/app_shell/backup-platform/webadmins/scheduler.py", line 82, in autoAddJob
    self.delCronJob(job_id=j)
  File "/app_shell/backup-platform/webadmins/scheduler.py", line 48, in delCronJob
    if not jid["job_id"]:
KeyError: 'job_id'
Job "abstract_schedule.autoAddJob (trigger: interval[0:00:05], next run at: 2019-07-19 07:43:25 UTC)" raised an exception
Traceback (most recent call last):
  File "/app_shell/backup-platform/lib/python3.6/site-packages/apscheduler/executors/base.py", line 125, in run_job
    retval = job.func(*job.args, **job.kwargs)
  File "/app_shell/backup-platform/webadmins/scheduler.py", line 82, in autoAddJob
    self.delCronJob(job_id=j)
  File "/app_shell/backup-platform/webadmins/scheduler.py", line 48, in delCronJob
    if not jid["job_id"]:
KeyError: 'job_id'
Job "abstract_schedule.autoAddJob (trigger: interval[0:00:05], next run at: 2019-07-19 07:43:30 UTC)" raised an exception
Traceback (most recent call last):
  File "/app_shell/backup-platform/lib/python3.6/site-packages/apscheduler/executors/base.py", line 125, in run_job
    retval = job.func(*job.args, **job.kwargs)
  File "/app_shell/backup-platform/webadmins/scheduler.py", line 82, in autoAddJob
    self.delCronJob(job_id=j)
  File "/app_shell/backup-platform/webadmins/scheduler.py", line 48, in delCronJob
    if not jid["job_id"]:
KeyError: 'job_id'
Job "abstract_schedule.autoAddJob (trigger: interval[0:00:05], next run at: 2019-07-19 07:43:35 UTC)" raised an exception
Traceback (most recent call last):
  File "/app_shell/backup-platform/lib/python3.6/site-packages/apscheduler/executors/base.py", line 125, in run_job
    retval = job.func(*job.args, **job.kwargs)
  File "/app_shell/backup-platform/webadmins/scheduler.py", line 82, in autoAddJob
    self.delCronJob(job_id=j)
  File "/app_shell/backup-platform/webadmins/scheduler.py", line 48, in delCronJob
    if not jid["job_id"]:
KeyError: 'job_id'
Job "abstract_schedule.autoAddJob (trigger: interval[0:00:05], next run at: 2019-07-19 07:43:40 UTC)" raised an exception
Traceback (most recent call last):
  File "/app_shell/backup-platform/lib/python3.6/site-packages/apscheduler/executors/base.py", line 125, in run_job
    retval = job.func(*job.args, **job.kwargs)
  File "/app_shell/backup-platform/webadmins/scheduler.py", line 82, in autoAddJob
    self.delCronJob(job_id=j)
  File "/app_shell/backup-platform/webadmins/scheduler.py", line 48, in delCronJob
    if not jid["job_id"]:
KeyError: 'job_id'
Job "abstract_schedule.autoAddJob (trigger: interval[0:00:05], next run at: 2019-07-19 07:43:45 UTC)" raised an exception
Traceback (most recent call last):
  File "/app_shell/backup-platform/lib/python3.6/site-packages/apscheduler/executors/base.py", line 125, in run_job
    retval = job.func(*job.args, **job.kwargs)
  File "/app_shell/backup-platform/webadmins/scheduler.py", line 82, in autoAddJob
    self.delCronJob(job_id=j)
  File "/app_shell/backup-platform/webadmins/scheduler.py", line 48, in delCronJob
    if not jid["job_id"]:
KeyError: 'job_id'
Job "abstract_schedule.autoAddJob (trigger: interval[0:00:05], next run at: 2019-07-19 07:43:50 UTC)" raised an exception
Traceback (most recent call last):
  File "/app_shell/backup-platform/lib/python3.6/site-packages/apscheduler/executors/base.py", line 125, in run_job
    retval = job.func(*job.args, **job.kwargs)
  File "/app_shell/backup-platform/webadmins/scheduler.py", line 82, in autoAddJob
    self.delCronJob(job_id=j)
  File "/app_shell/backup-platform/webadmins/scheduler.py", line 48, in delCronJob
    if not jid["job_id"]:
KeyError: 'job_id'
Job "abstract_schedule.autoAddJob (trigger: interval[0:00:05], next run at: 2019-07-19 07:43:55 UTC)" raised an exception
Traceback (most recent call last):
  File "/app_shell/backup-platform/lib/python3.6/site-packages/apscheduler/executors/base.py", line 125, in run_job
    retval = job.func(*job.args, **job.kwargs)
  File "/app_shell/backup-platform/webadmins/scheduler.py", line 82, in autoAddJob
    self.delCronJob(job_id=j)
  File "/app_shell/backup-platform/webadmins/scheduler.py", line 48, in delCronJob
    if not jid["job_id"]:
KeyError: 'job_id'
Job "abstract_schedule.autoAddJob (trigger: interval[0:00:05], next run at: 2019-07-19 07:44:00 UTC)" raised an exception
Traceback (most recent call last):
  File "/app_shell/backup-platform/lib/python3.6/site-packages/apscheduler/executors/base.py", line 125, in run_job
    retval = job.func(*job.args, **job.kwargs)
  File "/app_shell/backup-platform/webadmins/scheduler.py", line 82, in autoAddJob
    self.delCronJob(job_id=j)
  File "/app_shell/backup-platform/webadmins/scheduler.py", line 48, in delCronJob
    if not jid["job_id"]:
KeyError: 'job_id'
Job "abstract_schedule.autoAddJob (trigger: interval[0:00:05], next run at: 2019-07-19 07:44:05 UTC)" raised an exception
Traceback (most recent call last):
  File "/app_shell/backup-platform/lib/python3.6/site-packages/apscheduler/executors/base.py", line 125, in run_job
    retval = job.func(*job.args, **job.kwargs)
  File "/app_shell/backup-platform/webadmins/scheduler.py", line 82, in autoAddJob
    self.delCronJob(job_id=j)
  File "/app_shell/backup-platform/webadmins/scheduler.py", line 48, in delCronJob
    if not jid["job_id"]:
KeyError: 'job_id'
Job "abstract_schedule.autoAddJob (trigger: interval[0:00:05], next run at: 2019-07-19 07:44:10 UTC)" raised an exception
Traceback (most recent call last):
  File "/app_shell/backup-platform/lib/python3.6/site-packages/apscheduler/executors/base.py", line 125, in run_job
    retval = job.func(*job.args, **job.kwargs)
  File "/app_shell/backup-platform/webadmins/scheduler.py", line 82, in autoAddJob
    self.delCronJob(job_id=j)
  File "/app_shell/backup-platform/webadmins/scheduler.py", line 48, in delCronJob
    if not jid["job_id"]:
KeyError: 'job_id'
Job "abstract_schedule.autoAddJob (trigger: interval[0:00:05], next run at: 2019-07-19 07:44:15 UTC)" raised an exception
Traceback (most recent call last):
  File "/app_shell/backup-platform/lib/python3.6/site-packages/apscheduler/executors/base.py", line 125, in run_job
    retval = job.func(*job.args, **job.kwargs)
  File "/app_shell/backup-platform/webadmins/scheduler.py", line 82, in autoAddJob
    self.delCronJob(job_id=j)
  File "/app_shell/backup-platform/webadmins/scheduler.py", line 48, in delCronJob
    if not jid["job_id"]:
KeyError: 'job_id'
Job "abstract_schedule.autoAddJob (trigger: interval[0:00:05], next run at: 2019-07-19 07:44:20 UTC)" raised an exception
Traceback (most recent call last):
  File "/app_shell/backup-platform/lib/python3.6/site-packages/apscheduler/executors/base.py", line 125, in run_job
    retval = job.func(*job.args, **job.kwargs)
  File "/app_shell/backup-platform/webadmins/scheduler.py", line 82, in autoAddJob
    self.delCronJob(job_id=j)
  File "/app_shell/backup-platform/webadmins/scheduler.py", line 48, in delCronJob
    if not jid["job_id"]:
KeyError: 'job_id'
Job "abstract_schedule.autoAddJob (trigger: interval[0:00:05], next run at: 2019-07-19 07:44:25 UTC)" raised an exception
Traceback (most recent call last):
  File "/app_shell/backup-platform/lib/python3.6/site-packages/apscheduler/executors/base.py", line 125, in run_job
    retval = job.func(*job.args, **job.kwargs)
  File "/app_shell/backup-platform/webadmins/scheduler.py", line 82, in autoAddJob
    self.delCronJob(job_id=j)
  File "/app_shell/backup-platform/webadmins/scheduler.py", line 48, in delCronJob
    if not jid["job_id"]:
KeyError: 'job_id'
Job "abstract_schedule.autoAddJob (trigger: interval[0:00:05], next run at: 2019-07-19 07:44:30 UTC)" raised an exception
Traceback (most recent call last):
  File "/app_shell/backup-platform/lib/python3.6/site-packages/apscheduler/executors/base.py", line 125, in run_job
    retval = job.func(*job.args, **job.kwargs)
  File "/app_shell/backup-platform/webadmins/scheduler.py", line 82, in autoAddJob
    self.delCronJob(job_id=j)
  File "/app_shell/backup-platform/webadmins/scheduler.py", line 48, in delCronJob
    if not jid["job_id"]:
KeyError: 'job_id'
Job "abstract_schedule.autoAddJob (trigger: interval[0:00:05], next run at: 2019-07-19 07:44:35 UTC)" raised an exception
Traceback (most recent call last):
  File "/app_shell/backup-platform/lib/python3.6/site-packages/apscheduler/executors/base.py", line 125, in run_job
    retval = job.func(*job.args, **job.kwargs)
  File "/app_shell/backup-platform/webadmins/scheduler.py", line 82, in autoAddJob
    self.delCronJob(job_id=j)
  File "/app_shell/backup-platform/webadmins/scheduler.py", line 48, in delCronJob
    if not jid["job_id"]:
KeyError: 'job_id'
Job "abstract_schedule.autoAddJob (trigger: interval[0:00:05], next run at: 2019-07-19 07:44:40 UTC)" raised an exception
Traceback (most recent call last):
  File "/app_shell/backup-platform/lib/python3.6/site-packages/apscheduler/executors/base.py", line 125, in run_job
    retval = job.func(*job.args, **job.kwargs)
  File "/app_shell/backup-platform/webadmins/scheduler.py", line 82, in autoAddJob
    self.delCronJob(job_id=j)
  File "/app_shell/backup-platform/webadmins/scheduler.py", line 48, in delCronJob
    if not jid["job_id"]:
KeyError: 'job_id'
Job "abstract_schedule.autoAddJob (trigger: interval[0:00:05], next run at: 2019-07-19 07:44:45 UTC)" raised an exception
Traceback (most recent call last):
  File "/app_shell/backup-platform/lib/python3.6/site-packages/apscheduler/executors/base.py", line 125, in run_job
    retval = job.func(*job.args, **job.kwargs)
  File "/app_shell/backup-platform/webadmins/scheduler.py", line 82, in autoAddJob
    self.delCronJob(job_id=j)
  File "/app_shell/backup-platform/webadmins/scheduler.py", line 48, in delCronJob
    if not jid["job_id"]:
KeyError: 'job_id'
Job "abstract_schedule.autoAddJob (trigger: interval[0:00:05], next run at: 2019-07-19 07:44:50 UTC)" raised an exception
Traceback (most recent call last):
  File "/app_shell/backup-platform/lib/python3.6/site-packages/apscheduler/executors/base.py", line 125, in run_job
    retval = job.func(*job.args, **job.kwargs)
  File "/app_shell/backup-platform/webadmins/scheduler.py", line 82, in autoAddJob
    self.delCronJob(job_id=j)
  File "/app_shell/backup-platform/webadmins/scheduler.py", line 48, in delCronJob
    if not jid["job_id"]:
KeyError: 'job_id'
Job "abstract_schedule.autoAddJob (trigger: interval[0:00:05], next run at: 2019-07-19 07:44:55 UTC)" raised an exception
Traceback (most recent call last):
  File "/app_shell/backup-platform/lib/python3.6/site-packages/apscheduler/executors/base.py", line 125, in run_job
    retval = job.func(*job.args, **job.kwargs)
  File "/app_shell/backup-platform/webadmins/scheduler.py", line 82, in autoAddJob
    self.delCronJob(job_id=j)
  File "/app_shell/backup-platform/webadmins/scheduler.py", line 48, in delCronJob
    if not jid["job_id"]:
KeyError: 'job_id'
Job "abstract_schedule.autoAddJob (trigger: interval[0:00:05], next run at: 2019-07-19 07:45:00 UTC)" raised an exception
Traceback (most recent call last):
  File "/app_shell/backup-platform/lib/python3.6/site-packages/apscheduler/executors/base.py", line 125, in run_job
    retval = job.func(*job.args, **job.kwargs)
  File "/app_shell/backup-platform/webadmins/scheduler.py", line 82, in autoAddJob
    self.delCronJob(job_id=j)
  File "/app_shell/backup-platform/webadmins/scheduler.py", line 48, in delCronJob
    if not jid["job_id"]:
KeyError: 'job_id'
Job "abstract_schedule.autoAddJob (trigger: interval[0:00:05], next run at: 2019-07-19 07:45:05 UTC)" raised an exception
Traceback (most recent call last):
  File "/app_shell/backup-platform/lib/python3.6/site-packages/apscheduler/executors/base.py", line 125, in run_job
    retval = job.func(*job.args, **job.kwargs)
  File "/app_shell/backup-platform/webadmins/scheduler.py", line 82, in autoAddJob
    self.delCronJob(job_id=j)
  File "/app_shell/backup-platform/webadmins/scheduler.py", line 48, in delCronJob
    if not jid["job_id"]:
KeyError: 'job_id'
Job "db_backup_tools.db_backup_start (trigger: cron[day_of_week='0,1,2,3,4,5,6', minute='*/3'], next run at: 2019-07-19 07:48:00 UTC)" raised an exception
Traceback (most recent call last):
  File "/app_shell/backup-platform/lib/python3.6/site-packages/apscheduler/executors/base.py", line 125, in run_job
    retval = job.func(*job.args, **job.kwargs)
  File "/app_shell/backup-platform/webadmins/sched_task/sched_db_backup_tasks.py", line 43, in db_backup_start
    result = x.xtrabackup_full_backup(backup_to_local_path)
  File "/app_shell/backup-platform/webadmins/lib/db_backup_tools.py", line 65, in xtrabackup_full_backup
    raise DB_BACKUP_ERROR(u"主机%s数据库备份失败! err:%s" % (self.sshObj.host, output["stderr"].decode(encoding="utf-8").strip()))
db_backup_tools.DB_BACKUP_ERROR: 主机172.16.70.221数据库备份失败! err:190628 16:53:32 innobackupex: Starting the backup operation

IMPORTANT: Please check that the backup run completes successfully.
           At the end of a successful backup run innobackupex
           prints "completed OK!".

Can't locate Digest/MD5.pm in @INC (@INC contains: /usr/local/lib64/perl5 /usr/local/share/perl5 /usr/lib64/perl5/vendor_perl /usr/share/perl5/vendor_perl /usr/lib64/perl5 /usr/share/perl5 .) at - line 693.
BEGIN failed--compilation aborted at - line 693.
190628 16:53:33 Connecting to MySQL server host: 172.16.70.221, user: root, password: set, port: 3306, socket: not set
Using server version 5.7.26
/usr/local/percona-xtrabackup/bin/innobackupex version 2.4.9 based on MySQL server 5.7.13 Linux (x86_64) (revision id: a467167cdd4)
xtrabackup: uses posix_fadvise().
xtrabackup: cd to /var/lib/mysql/
xtrabackup: open files limit requested 0, set to 1024
xtrabackup: using the following InnoDB configuration:
xtrabackup:   innodb_data_home_dir = .
xtrabackup:   innodb_data_file_path = ibdata1:12M:autoextend
xtrabackup:   innodb_log_group_home_dir = ./
xtrabackup:   innodb_log_files_in_group = 2
xtrabackup:   innodb_log_file_size = 50331648
InnoDB: Number of pools: 1
innobackupex: Can't create/write to file '/mnt/nfs/588525330779870/172.16.70.221/20190719074500/xtrabackup_logfile' (Errcode: 17 - File exists)
xtrabackup: error: failed to open the target stream for 'xtrabackup_logfile'.
Job "abstract_schedule.autoAddJob (trigger: interval[0:00:05], next run at: 2019-07-19 07:45:10 UTC)" raised an exception
Traceback (most recent call last):
  File "/app_shell/backup-platform/lib/python3.6/site-packages/apscheduler/executors/base.py", line 125, in run_job
    retval = job.func(*job.args, **job.kwargs)
  File "/app_shell/backup-platform/webadmins/scheduler.py", line 82, in autoAddJob
    self.delCronJob(job_id=j)
  File "/app_shell/backup-platform/webadmins/scheduler.py", line 48, in delCronJob
    if not jid["job_id"]:
KeyError: 'job_id'
Job "abstract_schedule.autoAddJob (trigger: interval[0:00:05], next run at: 2019-07-19 07:45:15 UTC)" raised an exception
Traceback (most recent call last):
  File "/app_shell/backup-platform/lib/python3.6/site-packages/apscheduler/executors/base.py", line 125, in run_job
    retval = job.func(*job.args, **job.kwargs)
  File "/app_shell/backup-platform/webadmins/scheduler.py", line 82, in autoAddJob
    self.delCronJob(job_id=j)
  File "/app_shell/backup-platform/webadmins/scheduler.py", line 48, in delCronJob
    if not jid["job_id"]:
KeyError: 'job_id'
Job "abstract_schedule.autoAddJob (trigger: interval[0:00:05], next run at: 2019-07-19 07:45:20 UTC)" raised an exception
Traceback (most recent call last):
  File "/app_shell/backup-platform/lib/python3.6/site-packages/apscheduler/executors/base.py", line 125, in run_job
    retval = job.func(*job.args, **job.kwargs)
  File "/app_shell/backup-platform/webadmins/scheduler.py", line 82, in autoAddJob
    self.delCronJob(job_id=j)
  File "/app_shell/backup-platform/webadmins/scheduler.py", line 48, in delCronJob
    if not jid["job_id"]:
KeyError: 'job_id'
Job "abstract_schedule.autoAddJob (trigger: interval[0:00:05], next run at: 2019-07-19 07:45:25 UTC)" raised an exception
Traceback (most recent call last):
  File "/app_shell/backup-platform/lib/python3.6/site-packages/apscheduler/executors/base.py", line 125, in run_job
    retval = job.func(*job.args, **job.kwargs)
  File "/app_shell/backup-platform/webadmins/scheduler.py", line 82, in autoAddJob
    self.delCronJob(job_id=j)
  File "/app_shell/backup-platform/webadmins/scheduler.py", line 48, in delCronJob
    if not jid["job_id"]:
KeyError: 'job_id'
Job "abstract_schedule.autoAddJob (trigger: interval[0:00:05], next run at: 2019-07-19 07:45:30 UTC)" raised an exception
Traceback (most recent call last):
  File "/app_shell/backup-platform/lib/python3.6/site-packages/apscheduler/executors/base.py", line 125, in run_job
    retval = job.func(*job.args, **job.kwargs)
  File "/app_shell/backup-platform/webadmins/scheduler.py", line 82, in autoAddJob
    self.delCronJob(job_id=j)
  File "/app_shell/backup-platform/webadmins/scheduler.py", line 48, in delCronJob
    if not jid["job_id"]:
KeyError: 'job_id'
Job "abstract_schedule.autoAddJob (trigger: interval[0:00:05], next run at: 2019-07-19 07:45:35 UTC)" raised an exception
Traceback (most recent call last):
  File "/app_shell/backup-platform/lib/python3.6/site-packages/apscheduler/executors/base.py", line 125, in run_job
    retval = job.func(*job.args, **job.kwargs)
  File "/app_shell/backup-platform/webadmins/scheduler.py", line 82, in autoAddJob
    self.delCronJob(job_id=j)
  File "/app_shell/backup-platform/webadmins/scheduler.py", line 48, in delCronJob
    if not jid["job_id"]:
KeyError: 'job_id'
Job "abstract_schedule.autoAddJob (trigger: interval[0:00:05], next run at: 2019-07-19 07:45:40 UTC)" raised an exception
Traceback (most recent call last):
  File "/app_shell/backup-platform/lib/python3.6/site-packages/apscheduler/executors/base.py", line 125, in run_job
    retval = job.func(*job.args, **job.kwargs)
  File "/app_shell/backup-platform/webadmins/scheduler.py", line 82, in autoAddJob
    self.delCronJob(job_id=j)
  File "/app_shell/backup-platform/webadmins/scheduler.py", line 48, in delCronJob
    if not jid["job_id"]:
KeyError: 'job_id'
Job "abstract_schedule.autoAddJob (trigger: interval[0:00:05], next run at: 2019-07-19 07:45:45 UTC)" raised an exception
Traceback (most recent call last):
  File "/app_shell/backup-platform/lib/python3.6/site-packages/apscheduler/executors/base.py", line 125, in run_job
    retval = job.func(*job.args, **job.kwargs)
  File "/app_shell/backup-platform/webadmins/scheduler.py", line 82, in autoAddJob
    self.delCronJob(job_id=j)
  File "/app_shell/backup-platform/webadmins/scheduler.py", line 48, in delCronJob
    if not jid["job_id"]:
KeyError: 'job_id'
Job "abstract_schedule.autoAddJob (trigger: interval[0:00:05], next run at: 2019-07-19 07:45:50 UTC)" raised an exception
Traceback (most recent call last):
  File "/app_shell/backup-platform/lib/python3.6/site-packages/apscheduler/executors/base.py", line 125, in run_job
    retval = job.func(*job.args, **job.kwargs)
  File "/app_shell/backup-platform/webadmins/scheduler.py", line 82, in autoAddJob
    self.delCronJob(job_id=j)
  File "/app_shell/backup-platform/webadmins/scheduler.py", line 48, in delCronJob
    if not jid["job_id"]:
KeyError: 'job_id'
Job "abstract_schedule.autoAddJob (trigger: interval[0:00:05], next run at: 2019-07-19 07:45:55 UTC)" raised an exception
Traceback (most recent call last):
  File "/app_shell/backup-platform/lib/python3.6/site-packages/apscheduler/executors/base.py", line 125, in run_job
    retval = job.func(*job.args, **job.kwargs)
  File "/app_shell/backup-platform/webadmins/scheduler.py", line 82, in autoAddJob
    self.delCronJob(job_id=j)
  File "/app_shell/backup-platform/webadmins/scheduler.py", line 48, in delCronJob
    if not jid["job_id"]:
KeyError: 'job_id'
Job "abstract_schedule.autoAddJob (trigger: interval[0:00:05], next run at: 2019-07-19 07:46:00 UTC)" raised an exception
Traceback (most recent call last):
  File "/app_shell/backup-platform/lib/python3.6/site-packages/apscheduler/executors/base.py", line 125, in run_job
    retval = job.func(*job.args, **job.kwargs)
  File "/app_shell/backup-platform/webadmins/scheduler.py", line 82, in autoAddJob
    self.delCronJob(job_id=j)
  File "/app_shell/backup-platform/webadmins/scheduler.py", line 48, in delCronJob
    if not jid["job_id"]:
KeyError: 'job_id'
Job "abstract_schedule.autoAddJob (trigger: interval[0:00:05], next run at: 2019-07-19 07:46:45 UTC)" raised an exception
Traceback (most recent call last):
  File "/app_shell/backup-platform/lib/python3.6/site-packages/apscheduler/executors/base.py", line 125, in run_job
    retval = job.func(*job.args, **job.kwargs)
  File "/app_shell/backup-platform/webadmins/scheduler.py", line 82, in autoAddJob
    self.delCronJob(job_id=j)
  File "/app_shell/backup-platform/webadmins/scheduler.py", line 48, in delCronJob
    if not jid["job_id"]:
KeyError: 'job_id'
Job "abstract_schedule.autoAddJob (trigger: interval[0:00:05], next run at: 2019-07-19 07:46:50 UTC)" raised an exception
Traceback (most recent call last):
  File "/app_shell/backup-platform/lib/python3.6/site-packages/apscheduler/executors/base.py", line 125, in run_job
    retval = job.func(*job.args, **job.kwargs)
  File "/app_shell/backup-platform/webadmins/scheduler.py", line 82, in autoAddJob
    self.delCronJob(job_id=j)
  File "/app_shell/backup-platform/webadmins/scheduler.py", line 48, in delCronJob
    if not jid["job_id"]:
KeyError: 'job_id'
Job "abstract_schedule.autoAddJob (trigger: interval[0:00:05], next run at: 2019-07-19 07:46:55 UTC)" raised an exception
Traceback (most recent call last):
  File "/app_shell/backup-platform/lib/python3.6/site-packages/apscheduler/executors/base.py", line 125, in run_job
    retval = job.func(*job.args, **job.kwargs)
  File "/app_shell/backup-platform/webadmins/scheduler.py", line 82, in autoAddJob
    self.delCronJob(job_id=j)
  File "/app_shell/backup-platform/webadmins/scheduler.py", line 48, in delCronJob
    if not jid["job_id"]:
KeyError: 'job_id'
Job "abstract_schedule.autoAddJob (trigger: interval[0:00:05], next run at: 2019-07-19 07:47:00 UTC)" raised an exception
Traceback (most recent call last):
  File "/app_shell/backup-platform/lib/python3.6/site-packages/apscheduler/executors/base.py", line 125, in run_job
    retval = job.func(*job.args, **job.kwargs)
  File "/app_shell/backup-platform/webadmins/scheduler.py", line 82, in autoAddJob
    self.delCronJob(job_id=j)
  File "/app_shell/backup-platform/webadmins/scheduler.py", line 48, in delCronJob
    if not jid["job_id"]:
KeyError: 'job_id'
Job "abstract_schedule.autoAddJob (trigger: interval[0:00:05], next run at: 2019-07-19 07:47:05 UTC)" raised an exception
Traceback (most recent call last):
  File "/app_shell/backup-platform/lib/python3.6/site-packages/apscheduler/executors/base.py", line 125, in run_job
    retval = job.func(*job.args, **job.kwargs)
  File "/app_shell/backup-platform/webadmins/scheduler.py", line 82, in autoAddJob
    self.delCronJob(job_id=j)
  File "/app_shell/backup-platform/webadmins/scheduler.py", line 48, in delCronJob
    if not jid["job_id"]:
KeyError: 'job_id'
Job "abstract_schedule.autoAddJob (trigger: interval[0:00:05], next run at: 2019-07-19 07:47:10 UTC)" raised an exception
Traceback (most recent call last):
  File "/app_shell/backup-platform/lib/python3.6/site-packages/apscheduler/executors/base.py", line 125, in run_job
    retval = job.func(*job.args, **job.kwargs)
  File "/app_shell/backup-platform/webadmins/scheduler.py", line 82, in autoAddJob
    self.delCronJob(job_id=j)
  File "/app_shell/backup-platform/webadmins/scheduler.py", line 48, in delCronJob
    if not jid["job_id"]:
KeyError: 'job_id'
Job "abstract_schedule.autoAddJob (trigger: interval[0:00:05], next run at: 2019-07-19 07:47:15 UTC)" raised an exception
Traceback (most recent call last):
  File "/app_shell/backup-platform/lib/python3.6/site-packages/apscheduler/executors/base.py", line 125, in run_job
    retval = job.func(*job.args, **job.kwargs)
  File "/app_shell/backup-platform/webadmins/scheduler.py", line 82, in autoAddJob
    self.delCronJob(job_id=j)
  File "/app_shell/backup-platform/webadmins/scheduler.py", line 48, in delCronJob
    if not jid["job_id"]:
KeyError: 'job_id'
Job "abstract_schedule.autoAddJob (trigger: interval[0:00:05], next run at: 2019-07-19 07:47:20 UTC)" raised an exception
Traceback (most recent call last):
  File "/app_shell/backup-platform/lib/python3.6/site-packages/apscheduler/executors/base.py", line 125, in run_job
    retval = job.func(*job.args, **job.kwargs)
  File "/app_shell/backup-platform/webadmins/scheduler.py", line 82, in autoAddJob
    self.delCronJob(job_id=j)
  File "/app_shell/backup-platform/webadmins/scheduler.py", line 48, in delCronJob
    if not jid["job_id"]:
KeyError: 'job_id'
Job "abstract_schedule.autoAddJob (trigger: interval[0:00:05], next run at: 2019-07-19 07:47:25 UTC)" raised an exception
Traceback (most recent call last):
  File "/app_shell/backup-platform/lib/python3.6/site-packages/apscheduler/executors/base.py", line 125, in run_job
    retval = job.func(*job.args, **job.kwargs)
  File "/app_shell/backup-platform/webadmins/scheduler.py", line 82, in autoAddJob
    self.delCronJob(job_id=j)
  File "/app_shell/backup-platform/webadmins/scheduler.py", line 48, in delCronJob
    if not jid["job_id"]:
KeyError: 'job_id'
Job "db_backup_tools.db_backup_start (trigger: cron[day_of_week='0,1,2,3,4,5,6', minute='*/3'], next run at: 2019-07-19 07:51:00 UTC)" raised an exception
Traceback (most recent call last):
  File "/app_shell/backup-platform/lib/python3.6/site-packages/apscheduler/executors/base.py", line 125, in run_job
    retval = job.func(*job.args, **job.kwargs)
  File "/app_shell/backup-platform/webadmins/sched_task/sched_db_backup_tasks.py", line 43, in db_backup_start
    result = x.xtrabackup_full_backup(backup_to_local_path)
  File "/app_shell/backup-platform/webadmins/lib/db_backup_tools.py", line 65, in xtrabackup_full_backup
    raise DB_BACKUP_ERROR(u"主机%s数据库备份失败! err:%s" % (self.sshObj.host, output["stderr"].decode(encoding="utf-8").strip()))
db_backup_tools.DB_BACKUP_ERROR: 主机172.16.70.221数据库备份失败! err:190628 16:56:32 innobackupex: Starting the backup operation

IMPORTANT: Please check that the backup run completes successfully.
           At the end of a successful backup run innobackupex
           prints "completed OK!".

Can't locate Digest/MD5.pm in @INC (@INC contains: /usr/local/lib64/perl5 /usr/local/share/perl5 /usr/lib64/perl5/vendor_perl /usr/share/perl5/vendor_perl /usr/lib64/perl5 /usr/share/perl5 .) at - line 693.
BEGIN failed--compilation aborted at - line 693.
190628 16:56:33 Connecting to MySQL server host: 172.16.70.221, user: root, password: set, port: 3306, socket: not set
Using server version 5.7.26
/usr/local/percona-xtrabackup/bin/innobackupex version 2.4.9 based on MySQL server 5.7.13 Linux (x86_64) (revision id: a467167cdd4)
xtrabackup: uses posix_fadvise().
xtrabackup: cd to /var/lib/mysql/
xtrabackup: open files limit requested 0, set to 1024
xtrabackup: using the following InnoDB configuration:
xtrabackup:   innodb_data_home_dir = .
xtrabackup:   innodb_data_file_path = ibdata1:12M:autoextend
xtrabackup:   innodb_log_group_home_dir = ./
xtrabackup:   innodb_log_files_in_group = 2
xtrabackup:   innodb_log_file_size = 50331648
InnoDB: Number of pools: 1
innobackupex: Can't create/write to file '/mnt/nfs/588525330779870/172.16.70.221/20190719074800/xtrabackup_logfile' (Errcode: 17 - File exists)
xtrabackup: error: failed to open the target stream for 'xtrabackup_logfile'.
Job "db_backup_tools.db_backup_start (trigger: cron[day_of_week='0,1,2,3,4,5,6', minute='*/3'], next run at: 2019-07-19 07:54:00 UTC)" raised an exception
Traceback (most recent call last):
  File "/app_shell/backup-platform/lib/python3.6/site-packages/apscheduler/executors/base.py", line 125, in run_job
    retval = job.func(*job.args, **job.kwargs)
  File "/app_shell/backup-platform/webadmins/sched_task/sched_db_backup_tasks.py", line 43, in db_backup_start
    result = x.xtrabackup_full_backup(backup_to_local_path)
  File "/app_shell/backup-platform/webadmins/lib/db_backup_tools.py", line 65, in xtrabackup_full_backup
    raise DB_BACKUP_ERROR(u"主机%s数据库备份失败! err:%s" % (self.sshObj.host, output["stderr"].decode(encoding="utf-8").strip()))
db_backup_tools.DB_BACKUP_ERROR: 主机172.16.70.221数据库备份失败! err:190628 16:59:32 innobackupex: Starting the backup operation

IMPORTANT: Please check that the backup run completes successfully.
           At the end of a successful backup run innobackupex
           prints "completed OK!".

Can't locate Digest/MD5.pm in @INC (@INC contains: /usr/local/lib64/perl5 /usr/local/share/perl5 /usr/lib64/perl5/vendor_perl /usr/share/perl5/vendor_perl /usr/lib64/perl5 /usr/share/perl5 .) at - line 693.
BEGIN failed--compilation aborted at - line 693.
190628 16:59:33 Connecting to MySQL server host: 172.16.70.221, user: root, password: set, port: 3306, socket: not set
Using server version 5.7.26
/usr/local/percona-xtrabackup/bin/innobackupex version 2.4.9 based on MySQL server 5.7.13 Linux (x86_64) (revision id: a467167cdd4)
xtrabackup: uses posix_fadvise().
xtrabackup: cd to /var/lib/mysql/
xtrabackup: open files limit requested 0, set to 1024
xtrabackup: using the following InnoDB configuration:
xtrabackup:   innodb_data_home_dir = .
xtrabackup:   innodb_data_file_path = ibdata1:12M:autoextend
xtrabackup:   innodb_log_group_home_dir = ./
xtrabackup:   innodb_log_files_in_group = 2
xtrabackup:   innodb_log_file_size = 50331648
InnoDB: Number of pools: 1
innobackupex: Can't create/write to file '/mnt/nfs/588525330779870/172.16.70.221/20190719075100/xtrabackup_logfile' (Errcode: 17 - File exists)
xtrabackup: error: failed to open the target stream for 'xtrabackup_logfile'.
Job "db_backup_tools.db_backup_start (trigger: cron[day_of_week='0,1,2,3,4,5,6', minute='*/1'], next run at: 2019-07-19 07:55:00 UTC)" raised an exception
Traceback (most recent call last):
  File "/app_shell/backup-platform/lib/python3.6/site-packages/apscheduler/executors/base.py", line 125, in run_job
    retval = job.func(*job.args, **job.kwargs)
  File "/app_shell/backup-platform/webadmins/sched_task/sched_db_backup_tasks.py", line 43, in db_backup_start
    result = x.xtrabackup_full_backup(backup_to_local_path)
  File "/app_shell/backup-platform/webadmins/lib/db_backup_tools.py", line 65, in xtrabackup_full_backup
    raise DB_BACKUP_ERROR(u"主机%s数据库备份失败! err:%s" % (self.sshObj.host, output["stderr"].decode(encoding="utf-8").strip()))
db_backup_tools.DB_BACKUP_ERROR: 主机172.16.70.221数据库备份失败! err:190628 17:02:32 innobackupex: Starting the backup operation

IMPORTANT: Please check that the backup run completes successfully.
           At the end of a successful backup run innobackupex
           prints "completed OK!".

Can't locate Digest/MD5.pm in @INC (@INC contains: /usr/local/lib64/perl5 /usr/local/share/perl5 /usr/lib64/perl5/vendor_perl /usr/share/perl5/vendor_perl /usr/lib64/perl5 /usr/share/perl5 .) at - line 693.
BEGIN failed--compilation aborted at - line 693.
190628 17:02:33 Connecting to MySQL server host: 172.16.70.221, user: root, password: set, port: 3306, socket: not set
Using server version 5.7.26
/usr/local/percona-xtrabackup/bin/innobackupex version 2.4.9 based on MySQL server 5.7.13 Linux (x86_64) (revision id: a467167cdd4)
xtrabackup: uses posix_fadvise().
xtrabackup: cd to /var/lib/mysql/
xtrabackup: open files limit requested 0, set to 1024
xtrabackup: using the following InnoDB configuration:
xtrabackup:   innodb_data_home_dir = .
xtrabackup:   innodb_data_file_path = ibdata1:12M:autoextend
xtrabackup:   innodb_log_group_home_dir = ./
xtrabackup:   innodb_log_files_in_group = 2
xtrabackup:   innodb_log_file_size = 50331648
InnoDB: Number of pools: 1
innobackupex: Can't create/write to file '/mnt/nfs/588525330779870/172.16.70.221/20190719075400/xtrabackup_logfile' (Errcode: 17 - File exists)
xtrabackup: error: failed to open the target stream for 'xtrabackup_logfile'.
Job "db_backup_tools.db_backup_start (trigger: cron[day_of_week='0,1,2,3,4,5,6', minute='*/1'], next run at: 2019-07-19 07:58:00 UTC)" raised an exception
Traceback (most recent call last):
  File "/app_shell/backup-platform/lib/python3.6/site-packages/apscheduler/executors/base.py", line 125, in run_job
    retval = job.func(*job.args, **job.kwargs)
  File "/app_shell/backup-platform/webadmins/sched_task/sched_db_backup_tasks.py", line 43, in db_backup_start
    result = x.xtrabackup_full_backup(backup_to_local_path)
  File "/app_shell/backup-platform/webadmins/lib/db_backup_tools.py", line 65, in xtrabackup_full_backup
    raise DB_BACKUP_ERROR(u"主机%s数据库备份失败! err:%s" % (self.sshObj.host, output["stderr"].decode(encoding="utf-8").strip()))
db_backup_tools.DB_BACKUP_ERROR: 主机172.16.70.221数据库备份失败! err:190628 17:05:33 innobackupex: Starting the backup operation

IMPORTANT: Please check that the backup run completes successfully.
           At the end of a successful backup run innobackupex
           prints "completed OK!".

Can't locate Digest/MD5.pm in @INC (@INC contains: /usr/local/lib64/perl5 /usr/local/share/perl5 /usr/lib64/perl5/vendor_perl /usr/share/perl5/vendor_perl /usr/lib64/perl5 /usr/share/perl5 .) at - line 693.
BEGIN failed--compilation aborted at - line 693.
190628 17:05:33 Connecting to MySQL server host: 172.16.70.221, user: root, password: set, port: 3306, socket: not set
Using server version 5.7.26
/usr/local/percona-xtrabackup/bin/innobackupex version 2.4.9 based on MySQL server 5.7.13 Linux (x86_64) (revision id: a467167cdd4)
xtrabackup: uses posix_fadvise().
xtrabackup: cd to /var/lib/mysql/
xtrabackup: open files limit requested 0, set to 1024
xtrabackup: using the following InnoDB configuration:
xtrabackup:   innodb_data_home_dir = .
xtrabackup:   innodb_data_file_path = ibdata1:12M:autoextend
xtrabackup:   innodb_log_group_home_dir = ./
xtrabackup:   innodb_log_files_in_group = 2
xtrabackup:   innodb_log_file_size = 50331648
InnoDB: Number of pools: 1
innobackupex: Can't create/write to file '/mnt/nfs/588525330779870/172.16.70.221/20190719075700/xtrabackup_logfile' (Errcode: 17 - File exists)
xtrabackup: error: failed to open the target stream for 'xtrabackup_logfile'.
Job "db_backup_tools.db_backup_start (trigger: cron[day_of_week='0,1,2,3,4,5,6', minute='*/3'], next run at: 2019-07-19 08:03:00 UTC)" raised an exception
Traceback (most recent call last):
  File "/app_shell/backup-platform/lib/python3.6/site-packages/apscheduler/executors/base.py", line 125, in run_job
    retval = job.func(*job.args, **job.kwargs)
  File "/app_shell/backup-platform/webadmins/sched_task/sched_db_backup_tasks.py", line 43, in db_backup_start
    result = x.xtrabackup_full_backup(backup_to_local_path)
  File "/app_shell/backup-platform/webadmins/lib/db_backup_tools.py", line 65, in xtrabackup_full_backup
    raise DB_BACKUP_ERROR(u"主机%s数据库备份失败! err:%s" % (self.sshObj.host, output["stderr"].decode(encoding="utf-8").strip()))
db_backup_tools.DB_BACKUP_ERROR: 主机172.16.70.221数据库备份失败! err:190628 17:08:33 innobackupex: Starting the backup operation

IMPORTANT: Please check that the backup run completes successfully.
           At the end of a successful backup run innobackupex
           prints "completed OK!".

Can't locate Digest/MD5.pm in @INC (@INC contains: /usr/local/lib64/perl5 /usr/local/share/perl5 /usr/lib64/perl5/vendor_perl /usr/share/perl5/vendor_perl /usr/lib64/perl5 /usr/share/perl5 .) at - line 693.
BEGIN failed--compilation aborted at - line 693.
190628 17:08:33 Connecting to MySQL server host: 172.16.70.221, user: root, password: set, port: 3306, socket: not set
Using server version 5.7.26
/usr/local/percona-xtrabackup/bin/innobackupex version 2.4.9 based on MySQL server 5.7.13 Linux (x86_64) (revision id: a467167cdd4)
xtrabackup: uses posix_fadvise().
xtrabackup: cd to /var/lib/mysql/
xtrabackup: open files limit requested 0, set to 1024
xtrabackup: using the following InnoDB configuration:
xtrabackup:   innodb_data_home_dir = .
xtrabackup:   innodb_data_file_path = ibdata1:12M:autoextend
xtrabackup:   innodb_log_group_home_dir = ./
xtrabackup:   innodb_log_files_in_group = 2
xtrabackup:   innodb_log_file_size = 50331648
InnoDB: Number of pools: 1
innobackupex: Can't create/write to file '/mnt/nfs/588525330779870/172.16.70.221/20190719080000/xtrabackup_logfile' (Errcode: 17 - File exists)
xtrabackup: error: failed to open the target stream for 'xtrabackup_logfile'.
Job "db_backup_tools.db_backup_start (trigger: cron[day_of_week='0,1,2,3,4,5,6', minute='*/1'], next run at: 2019-07-19 08:04:00 UTC)" raised an exception
Traceback (most recent call last):
  File "/app_shell/backup-platform/lib/python3.6/site-packages/apscheduler/executors/base.py", line 125, in run_job
    retval = job.func(*job.args, **job.kwargs)
  File "/app_shell/backup-platform/webadmins/sched_task/sched_db_backup_tasks.py", line 43, in db_backup_start
    result = x.xtrabackup_full_backup(backup_to_local_path)
  File "/app_shell/backup-platform/webadmins/lib/db_backup_tools.py", line 65, in xtrabackup_full_backup
    raise DB_BACKUP_ERROR(u"主机%s数据库备份失败! err:%s" % (self.sshObj.host, output["stderr"].decode(encoding="utf-8").strip()))
db_backup_tools.DB_BACKUP_ERROR: 主机172.16.70.221数据库备份失败! err:190628 17:11:33 innobackupex: Starting the backup operation

IMPORTANT: Please check that the backup run completes successfully.
           At the end of a successful backup run innobackupex
           prints "completed OK!".

Can't locate Digest/MD5.pm in @INC (@INC contains: /usr/local/lib64/perl5 /usr/local/share/perl5 /usr/lib64/perl5/vendor_perl /usr/share/perl5/vendor_perl /usr/lib64/perl5 /usr/share/perl5 .) at - line 693.
BEGIN failed--compilation aborted at - line 693.
190628 17:11:33 Connecting to MySQL server host: 172.16.70.221, user: root, password: set, port: 3306, socket: not set
Using server version 5.7.26
/usr/local/percona-xtrabackup/bin/innobackupex version 2.4.9 based on MySQL server 5.7.13 Linux (x86_64) (revision id: a467167cdd4)
xtrabackup: uses posix_fadvise().
xtrabackup: cd to /var/lib/mysql/
xtrabackup: open files limit requested 0, set to 1024
xtrabackup: using the following InnoDB configuration:
xtrabackup:   innodb_data_home_dir = .
xtrabackup:   innodb_data_file_path = ibdata1:12M:autoextend
xtrabackup:   innodb_log_group_home_dir = ./
xtrabackup:   innodb_log_files_in_group = 2
xtrabackup:   innodb_log_file_size = 50331648
InnoDB: Number of pools: 1
innobackupex: Can't create/write to file '/mnt/nfs/588525330779870/172.16.70.221/20190719080300/xtrabackup_logfile' (Errcode: 17 - File exists)
xtrabackup: error: failed to open the target stream for 'xtrabackup_logfile'.
Job "db_backup_tools.db_backup_start (trigger: cron[day_of_week='0,1,2,3,4,5,6', minute='*/1'], next run at: 2019-07-19 08:07:00 UTC)" raised an exception
Traceback (most recent call last):
  File "/app_shell/backup-platform/lib/python3.6/site-packages/apscheduler/executors/base.py", line 125, in run_job
    retval = job.func(*job.args, **job.kwargs)
  File "/app_shell/backup-platform/webadmins/sched_task/sched_db_backup_tasks.py", line 43, in db_backup_start
    result = x.xtrabackup_full_backup(backup_to_local_path)
  File "/app_shell/backup-platform/webadmins/lib/db_backup_tools.py", line 65, in xtrabackup_full_backup
    raise DB_BACKUP_ERROR(u"主机%s数据库备份失败! err:%s" % (self.sshObj.host, output["stderr"].decode(encoding="utf-8").strip()))
db_backup_tools.DB_BACKUP_ERROR: 主机172.16.70.221数据库备份失败! err:190628 17:14:33 innobackupex: Starting the backup operation

IMPORTANT: Please check that the backup run completes successfully.
           At the end of a successful backup run innobackupex
           prints "completed OK!".

Can't locate Digest/MD5.pm in @INC (@INC contains: /usr/local/lib64/perl5 /usr/local/share/perl5 /usr/lib64/perl5/vendor_perl /usr/share/perl5/vendor_perl /usr/lib64/perl5 /usr/share/perl5 .) at - line 693.
BEGIN failed--compilation aborted at - line 693.
190628 17:14:33 Connecting to MySQL server host: 172.16.70.221, user: root, password: set, port: 3306, socket: not set
Using server version 5.7.26
/usr/local/percona-xtrabackup/bin/innobackupex version 2.4.9 based on MySQL server 5.7.13 Linux (x86_64) (revision id: a467167cdd4)
xtrabackup: uses posix_fadvise().
xtrabackup: cd to /var/lib/mysql/
xtrabackup: open files limit requested 0, set to 1024
xtrabackup: using the following InnoDB configuration:
xtrabackup:   innodb_data_home_dir = .
xtrabackup:   innodb_data_file_path = ibdata1:12M:autoextend
xtrabackup:   innodb_log_group_home_dir = ./
xtrabackup:   innodb_log_files_in_group = 2
xtrabackup:   innodb_log_file_size = 50331648
InnoDB: Number of pools: 1
innobackupex: Can't create/write to file '/mnt/nfs/588525330779870/172.16.70.221/20190719080600/xtrabackup_logfile' (Errcode: 17 - File exists)
xtrabackup: error: failed to open the target stream for 'xtrabackup_logfile'.
Job "abstract_schedule.autoAddJob (trigger: interval[0:00:05], next run at: 2019-07-19 08:08:02 UTC)" raised an exception
Traceback (most recent call last):
  File "/app_shell/backup-platform/lib/python3.6/site-packages/apscheduler/executors/base.py", line 125, in run_job
    retval = job.func(*job.args, **job.kwargs)
  File "/app_shell/backup-platform/webadmins/scheduler.py", line 68, in autoAddJob
    current_jobs = self.getBackupPolicy()
  File "/app_shell/backup-platform/webadmins/scheduler.py", line 122, in getBackupPolicy
    func = sched_task.sched_fs_backup_tasks.fs_backup_tools(source_addr)
TypeError: __init__() missing 1 required positional argument: 'source_addr'
Job "abstract_schedule.autoAddJob (trigger: interval[0:00:05], next run at: 2019-07-19 08:08:07 UTC)" raised an exception
Traceback (most recent call last):
  File "/app_shell/backup-platform/lib/python3.6/site-packages/apscheduler/executors/base.py", line 125, in run_job
    retval = job.func(*job.args, **job.kwargs)
  File "/app_shell/backup-platform/webadmins/scheduler.py", line 68, in autoAddJob
    current_jobs = self.getBackupPolicy()
  File "/app_shell/backup-platform/webadmins/scheduler.py", line 122, in getBackupPolicy
    func = sched_task.sched_fs_backup_tasks.fs_backup_tools(source_addr)
TypeError: __init__() missing 1 required positional argument: 'source_addr'
Job "abstract_schedule.autoAddJob (trigger: interval[0:00:05], next run at: 2019-07-19 08:08:12 UTC)" raised an exception
Traceback (most recent call last):
  File "/app_shell/backup-platform/lib/python3.6/site-packages/apscheduler/executors/base.py", line 125, in run_job
    retval = job.func(*job.args, **job.kwargs)
  File "/app_shell/backup-platform/webadmins/scheduler.py", line 68, in autoAddJob
    current_jobs = self.getBackupPolicy()
  File "/app_shell/backup-platform/webadmins/scheduler.py", line 122, in getBackupPolicy
    func = sched_task.sched_fs_backup_tasks.fs_backup_tools(source_addr)
TypeError: __init__() missing 1 required positional argument: 'source_addr'
Job "abstract_schedule.autoAddJob (trigger: interval[0:00:05], next run at: 2019-07-19 08:08:17 UTC)" raised an exception
Traceback (most recent call last):
  File "/app_shell/backup-platform/lib/python3.6/site-packages/apscheduler/executors/base.py", line 125, in run_job
    retval = job.func(*job.args, **job.kwargs)
  File "/app_shell/backup-platform/webadmins/scheduler.py", line 68, in autoAddJob
    current_jobs = self.getBackupPolicy()
  File "/app_shell/backup-platform/webadmins/scheduler.py", line 122, in getBackupPolicy
    func = sched_task.sched_fs_backup_tasks.fs_backup_tools(source_addr)
TypeError: __init__() missing 1 required positional argument: 'source_addr'
Job "abstract_schedule.autoAddJob (trigger: interval[0:00:05], next run at: 2019-07-19 08:08:22 UTC)" raised an exception
Traceback (most recent call last):
  File "/app_shell/backup-platform/lib/python3.6/site-packages/apscheduler/executors/base.py", line 125, in run_job
    retval = job.func(*job.args, **job.kwargs)
  File "/app_shell/backup-platform/webadmins/scheduler.py", line 68, in autoAddJob
    current_jobs = self.getBackupPolicy()
  File "/app_shell/backup-platform/webadmins/scheduler.py", line 122, in getBackupPolicy
    func = sched_task.sched_fs_backup_tasks.fs_backup_tools(source_addr)
TypeError: __init__() missing 1 required positional argument: 'source_addr'
Job "abstract_schedule.autoAddJob (trigger: interval[0:00:05], next run at: 2019-07-19 08:08:27 UTC)" raised an exception
Traceback (most recent call last):
  File "/app_shell/backup-platform/lib/python3.6/site-packages/apscheduler/executors/base.py", line 125, in run_job
    retval = job.func(*job.args, **job.kwargs)
  File "/app_shell/backup-platform/webadmins/scheduler.py", line 68, in autoAddJob
    current_jobs = self.getBackupPolicy()
  File "/app_shell/backup-platform/webadmins/scheduler.py", line 122, in getBackupPolicy
    func = sched_task.sched_fs_backup_tasks.fs_backup_tools(source_addr)
TypeError: __init__() missing 1 required positional argument: 'source_addr'
Job "abstract_schedule.autoAddJob (trigger: interval[0:00:05], next run at: 2019-07-19 08:08:32 UTC)" raised an exception
Traceback (most recent call last):
  File "/app_shell/backup-platform/lib/python3.6/site-packages/apscheduler/executors/base.py", line 125, in run_job
    retval = job.func(*job.args, **job.kwargs)
  File "/app_shell/backup-platform/webadmins/scheduler.py", line 68, in autoAddJob
    current_jobs = self.getBackupPolicy()
  File "/app_shell/backup-platform/webadmins/scheduler.py", line 122, in getBackupPolicy
    func = sched_task.sched_fs_backup_tasks.fs_backup_tools(source_addr)
TypeError: __init__() missing 1 required positional argument: 'source_addr'
Job "abstract_schedule.autoAddJob (trigger: interval[0:00:05], next run at: 2019-07-19 08:08:37 UTC)" raised an exception
Traceback (most recent call last):
  File "/app_shell/backup-platform/lib/python3.6/site-packages/apscheduler/executors/base.py", line 125, in run_job
    retval = job.func(*job.args, **job.kwargs)
  File "/app_shell/backup-platform/webadmins/scheduler.py", line 68, in autoAddJob
    current_jobs = self.getBackupPolicy()
  File "/app_shell/backup-platform/webadmins/scheduler.py", line 122, in getBackupPolicy
    func = sched_task.sched_fs_backup_tasks.fs_backup_tools(source_addr)
TypeError: __init__() missing 1 required positional argument: 'source_addr'
Job "abstract_schedule.autoAddJob (trigger: interval[0:00:05], next run at: 2019-07-19 08:08:42 UTC)" raised an exception
Traceback (most recent call last):
  File "/app_shell/backup-platform/lib/python3.6/site-packages/apscheduler/executors/base.py", line 125, in run_job
    retval = job.func(*job.args, **job.kwargs)
  File "/app_shell/backup-platform/webadmins/scheduler.py", line 68, in autoAddJob
    current_jobs = self.getBackupPolicy()
  File "/app_shell/backup-platform/webadmins/scheduler.py", line 122, in getBackupPolicy
    func = sched_task.sched_fs_backup_tasks.fs_backup_tools(source_addr)
TypeError: __init__() missing 1 required positional argument: 'source_addr'
Job "abstract_schedule.autoAddJob (trigger: interval[0:00:05], next run at: 2019-07-19 08:08:47 UTC)" raised an exception
Traceback (most recent call last):
  File "/app_shell/backup-platform/lib/python3.6/site-packages/apscheduler/executors/base.py", line 125, in run_job
    retval = job.func(*job.args, **job.kwargs)
  File "/app_shell/backup-platform/webadmins/scheduler.py", line 68, in autoAddJob
    current_jobs = self.getBackupPolicy()
  File "/app_shell/backup-platform/webadmins/scheduler.py", line 122, in getBackupPolicy
    func = sched_task.sched_fs_backup_tasks.fs_backup_tools(source_addr)
TypeError: __init__() missing 1 required positional argument: 'source_addr'
Job "db_backup_tools.db_backup_start (trigger: cron[day_of_week='0,1,2,3,4,5,6', minute='*/3'], next run at: 2019-07-19 08:15:00 UTC)" raised an exception
Traceback (most recent call last):
  File "/app_shell/backup-platform/lib/python3.6/site-packages/apscheduler/executors/base.py", line 125, in run_job
    retval = job.func(*job.args, **job.kwargs)
  File "/app_shell/backup-platform/webadmins/sched_task/sched_db_backup_tasks.py", line 43, in db_backup_start
    result = x.xtrabackup_full_backup(backup_to_local_path)
  File "/app_shell/backup-platform/webadmins/lib/db_backup_tools.py", line 65, in xtrabackup_full_backup
    raise DB_BACKUP_ERROR(u"主机%s数据库备份失败! err:%s" % (self.sshObj.host, output["stderr"].decode(encoding="utf-8").strip()))
db_backup_tools.DB_BACKUP_ERROR: 主机172.16.70.221数据库备份失败! err:190628 17:20:33 innobackupex: Starting the backup operation

IMPORTANT: Please check that the backup run completes successfully.
           At the end of a successful backup run innobackupex
           prints "completed OK!".

Can't locate Digest/MD5.pm in @INC (@INC contains: /usr/local/lib64/perl5 /usr/local/share/perl5 /usr/lib64/perl5/vendor_perl /usr/share/perl5/vendor_perl /usr/lib64/perl5 /usr/share/perl5 .) at - line 693.
BEGIN failed--compilation aborted at - line 693.
190628 17:20:33 Connecting to MySQL server host: 172.16.70.221, user: root, password: set, port: 3306, socket: not set
Using server version 5.7.26
/usr/local/percona-xtrabackup/bin/innobackupex version 2.4.9 based on MySQL server 5.7.13 Linux (x86_64) (revision id: a467167cdd4)
xtrabackup: uses posix_fadvise().
xtrabackup: cd to /var/lib/mysql/
xtrabackup: open files limit requested 0, set to 1024
xtrabackup: using the following InnoDB configuration:
xtrabackup:   innodb_data_home_dir = .
xtrabackup:   innodb_data_file_path = ibdata1:12M:autoextend
xtrabackup:   innodb_log_group_home_dir = ./
xtrabackup:   innodb_log_files_in_group = 2
xtrabackup:   innodb_log_file_size = 50331648
InnoDB: Number of pools: 1
innobackupex: Can't create/write to file '/mnt/nfs/588525330779870/172.16.70.221/20190719081200/xtrabackup_logfile' (Errcode: 17 - File exists)
xtrabackup: error: failed to open the target stream for 'xtrabackup_logfile'.
Job "abstract_schedule.autoAddJob (trigger: interval[0:00:05], next run at: 2019-07-19 08:12:38 UTC)" raised an exception
Traceback (most recent call last):
  File "/app_shell/backup-platform/lib/python3.6/site-packages/apscheduler/executors/base.py", line 125, in run_job
    retval = job.func(*job.args, **job.kwargs)
  File "/app_shell/backup-platform/webadmins/scheduler.py", line 82, in autoAddJob
    self.delCronJob(job_id=j)
  File "/app_shell/backup-platform/webadmins/scheduler.py", line 48, in delCronJob
    if not jid["job_id"]:
KeyError: 'job_id'
Job "abstract_schedule.autoAddJob (trigger: interval[0:00:05], next run at: 2019-07-19 08:12:43 UTC)" raised an exception
Traceback (most recent call last):
  File "/app_shell/backup-platform/lib/python3.6/site-packages/apscheduler/executors/base.py", line 125, in run_job
    retval = job.func(*job.args, **job.kwargs)
  File "/app_shell/backup-platform/webadmins/scheduler.py", line 82, in autoAddJob
    self.delCronJob(job_id=j)
  File "/app_shell/backup-platform/webadmins/scheduler.py", line 48, in delCronJob
    if not jid["job_id"]:
KeyError: 'job_id'
Job "abstract_schedule.autoAddJob (trigger: interval[0:00:05], next run at: 2019-07-19 08:12:48 UTC)" raised an exception
Traceback (most recent call last):
  File "/app_shell/backup-platform/lib/python3.6/site-packages/apscheduler/executors/base.py", line 125, in run_job
    retval = job.func(*job.args, **job.kwargs)
  File "/app_shell/backup-platform/webadmins/scheduler.py", line 82, in autoAddJob
    self.delCronJob(job_id=j)
  File "/app_shell/backup-platform/webadmins/scheduler.py", line 48, in delCronJob
    if not jid["job_id"]:
KeyError: 'job_id'
Job "abstract_schedule.autoAddJob (trigger: interval[0:00:05], next run at: 2019-07-19 08:12:53 UTC)" raised an exception
Traceback (most recent call last):
  File "/app_shell/backup-platform/lib/python3.6/site-packages/apscheduler/executors/base.py", line 125, in run_job
    retval = job.func(*job.args, **job.kwargs)
  File "/app_shell/backup-platform/webadmins/scheduler.py", line 82, in autoAddJob
    self.delCronJob(job_id=j)
  File "/app_shell/backup-platform/webadmins/scheduler.py", line 48, in delCronJob
    if not jid["job_id"]:
KeyError: 'job_id'
Job "abstract_schedule.autoAddJob (trigger: interval[0:00:05], next run at: 2019-07-19 08:12:58 UTC)" raised an exception
Traceback (most recent call last):
  File "/app_shell/backup-platform/lib/python3.6/site-packages/apscheduler/executors/base.py", line 125, in run_job
    retval = job.func(*job.args, **job.kwargs)
  File "/app_shell/backup-platform/webadmins/scheduler.py", line 82, in autoAddJob
    self.delCronJob(job_id=j)
  File "/app_shell/backup-platform/webadmins/scheduler.py", line 48, in delCronJob
    if not jid["job_id"]:
KeyError: 'job_id'
Job "abstract_schedule.autoAddJob (trigger: interval[0:00:05], next run at: 2019-07-19 08:13:03 UTC)" raised an exception
Traceback (most recent call last):
  File "/app_shell/backup-platform/lib/python3.6/site-packages/apscheduler/executors/base.py", line 125, in run_job
    retval = job.func(*job.args, **job.kwargs)
  File "/app_shell/backup-platform/webadmins/scheduler.py", line 82, in autoAddJob
    self.delCronJob(job_id=j)
  File "/app_shell/backup-platform/webadmins/scheduler.py", line 48, in delCronJob
    if not jid["job_id"]:
KeyError: 'job_id'
Job "abstract_schedule.autoAddJob (trigger: interval[0:00:05], next run at: 2019-07-19 08:13:08 UTC)" raised an exception
Traceback (most recent call last):
  File "/app_shell/backup-platform/lib/python3.6/site-packages/apscheduler/executors/base.py", line 125, in run_job
    retval = job.func(*job.args, **job.kwargs)
  File "/app_shell/backup-platform/webadmins/scheduler.py", line 82, in autoAddJob
    self.delCronJob(job_id=j)
  File "/app_shell/backup-platform/webadmins/scheduler.py", line 48, in delCronJob
    if not jid["job_id"]:
KeyError: 'job_id'
Job "abstract_schedule.autoAddJob (trigger: interval[0:00:05], next run at: 2019-07-19 08:13:13 UTC)" raised an exception
Traceback (most recent call last):
  File "/app_shell/backup-platform/lib/python3.6/site-packages/apscheduler/executors/base.py", line 125, in run_job
    retval = job.func(*job.args, **job.kwargs)
  File "/app_shell/backup-platform/webadmins/scheduler.py", line 82, in autoAddJob
    self.delCronJob(job_id=j)
  File "/app_shell/backup-platform/webadmins/scheduler.py", line 48, in delCronJob
    if not jid["job_id"]:
KeyError: 'job_id'
Job "abstract_schedule.autoAddJob (trigger: interval[0:00:05], next run at: 2019-07-19 08:13:18 UTC)" raised an exception
Traceback (most recent call last):
  File "/app_shell/backup-platform/lib/python3.6/site-packages/apscheduler/executors/base.py", line 125, in run_job
    retval = job.func(*job.args, **job.kwargs)
  File "/app_shell/backup-platform/webadmins/scheduler.py", line 82, in autoAddJob
    self.delCronJob(job_id=j)
  File "/app_shell/backup-platform/webadmins/scheduler.py", line 48, in delCronJob
    if not jid["job_id"]:
KeyError: 'job_id'
Job "abstract_schedule.autoAddJob (trigger: interval[0:00:05], next run at: 2019-07-19 08:13:23 UTC)" raised an exception
Traceback (most recent call last):
  File "/app_shell/backup-platform/lib/python3.6/site-packages/apscheduler/executors/base.py", line 125, in run_job
    retval = job.func(*job.args, **job.kwargs)
  File "/app_shell/backup-platform/webadmins/scheduler.py", line 82, in autoAddJob
    self.delCronJob(job_id=j)
  File "/app_shell/backup-platform/webadmins/scheduler.py", line 48, in delCronJob
    if not jid["job_id"]:
KeyError: 'job_id'
Job "abstract_schedule.autoAddJob (trigger: interval[0:00:05], next run at: 2019-07-19 08:13:28 UTC)" raised an exception
Traceback (most recent call last):
  File "/app_shell/backup-platform/lib/python3.6/site-packages/apscheduler/executors/base.py", line 125, in run_job
    retval = job.func(*job.args, **job.kwargs)
  File "/app_shell/backup-platform/webadmins/scheduler.py", line 82, in autoAddJob
    self.delCronJob(job_id=j)
  File "/app_shell/backup-platform/webadmins/scheduler.py", line 48, in delCronJob
    if not jid["job_id"]:
KeyError: 'job_id'
Job "abstract_schedule.autoAddJob (trigger: interval[0:00:05], next run at: 2019-07-19 08:13:33 UTC)" raised an exception
Traceback (most recent call last):
  File "/app_shell/backup-platform/lib/python3.6/site-packages/apscheduler/executors/base.py", line 125, in run_job
    retval = job.func(*job.args, **job.kwargs)
  File "/app_shell/backup-platform/webadmins/scheduler.py", line 82, in autoAddJob
    self.delCronJob(job_id=j)
  File "/app_shell/backup-platform/webadmins/scheduler.py", line 48, in delCronJob
    if not jid["job_id"]:
KeyError: 'job_id'
Job "abstract_schedule.autoAddJob (trigger: interval[0:00:05], next run at: 2019-07-19 08:13:38 UTC)" raised an exception
Traceback (most recent call last):
  File "/app_shell/backup-platform/lib/python3.6/site-packages/apscheduler/executors/base.py", line 125, in run_job
    retval = job.func(*job.args, **job.kwargs)
  File "/app_shell/backup-platform/webadmins/scheduler.py", line 82, in autoAddJob
    self.delCronJob(job_id=j)
  File "/app_shell/backup-platform/webadmins/scheduler.py", line 48, in delCronJob
    if not jid["job_id"]:
KeyError: 'job_id'
Job "abstract_schedule.autoAddJob (trigger: interval[0:00:05], next run at: 2019-07-19 08:13:43 UTC)" raised an exception
Traceback (most recent call last):
  File "/app_shell/backup-platform/lib/python3.6/site-packages/apscheduler/executors/base.py", line 125, in run_job
    retval = job.func(*job.args, **job.kwargs)
  File "/app_shell/backup-platform/webadmins/scheduler.py", line 82, in autoAddJob
    self.delCronJob(job_id=j)
  File "/app_shell/backup-platform/webadmins/scheduler.py", line 48, in delCronJob
    if not jid["job_id"]:
KeyError: 'job_id'
Job "abstract_schedule.autoAddJob (trigger: interval[0:00:05], next run at: 2019-07-19 08:13:48 UTC)" raised an exception
Traceback (most recent call last):
  File "/app_shell/backup-platform/lib/python3.6/site-packages/apscheduler/executors/base.py", line 125, in run_job
    retval = job.func(*job.args, **job.kwargs)
  File "/app_shell/backup-platform/webadmins/scheduler.py", line 82, in autoAddJob
    self.delCronJob(job_id=j)
  File "/app_shell/backup-platform/webadmins/scheduler.py", line 48, in delCronJob
    if not jid["job_id"]:
KeyError: 'job_id'
Job "abstract_schedule.autoAddJob (trigger: interval[0:00:05], next run at: 2019-07-19 08:13:53 UTC)" raised an exception
Traceback (most recent call last):
  File "/app_shell/backup-platform/lib/python3.6/site-packages/apscheduler/executors/base.py", line 125, in run_job
    retval = job.func(*job.args, **job.kwargs)
  File "/app_shell/backup-platform/webadmins/scheduler.py", line 82, in autoAddJob
    self.delCronJob(job_id=j)
  File "/app_shell/backup-platform/webadmins/scheduler.py", line 48, in delCronJob
    if not jid["job_id"]:
KeyError: 'job_id'
Job "abstract_schedule.autoAddJob (trigger: interval[0:00:05], next run at: 2019-07-19 08:13:58 UTC)" raised an exception
Traceback (most recent call last):
  File "/app_shell/backup-platform/lib/python3.6/site-packages/apscheduler/executors/base.py", line 125, in run_job
    retval = job.func(*job.args, **job.kwargs)
  File "/app_shell/backup-platform/webadmins/scheduler.py", line 82, in autoAddJob
    self.delCronJob(job_id=j)
  File "/app_shell/backup-platform/webadmins/scheduler.py", line 48, in delCronJob
    if not jid["job_id"]:
KeyError: 'job_id'
Job "abstract_schedule.autoAddJob (trigger: interval[0:00:05], next run at: 2019-07-19 08:14:03 UTC)" raised an exception
Traceback (most recent call last):
  File "/app_shell/backup-platform/lib/python3.6/site-packages/apscheduler/executors/base.py", line 125, in run_job
    retval = job.func(*job.args, **job.kwargs)
  File "/app_shell/backup-platform/webadmins/scheduler.py", line 82, in autoAddJob
    self.delCronJob(job_id=j)
  File "/app_shell/backup-platform/webadmins/scheduler.py", line 48, in delCronJob
    if not jid["job_id"]:
KeyError: 'job_id'
Job "abstract_schedule.autoAddJob (trigger: interval[0:00:05], next run at: 2019-07-19 08:14:08 UTC)" raised an exception
Traceback (most recent call last):
  File "/app_shell/backup-platform/lib/python3.6/site-packages/apscheduler/executors/base.py", line 125, in run_job
    retval = job.func(*job.args, **job.kwargs)
  File "/app_shell/backup-platform/webadmins/scheduler.py", line 82, in autoAddJob
    self.delCronJob(job_id=j)
  File "/app_shell/backup-platform/webadmins/scheduler.py", line 48, in delCronJob
    if not jid["job_id"]:
KeyError: 'job_id'
Job "abstract_schedule.autoAddJob (trigger: interval[0:00:05], next run at: 2019-07-19 08:14:13 UTC)" raised an exception
Traceback (most recent call last):
  File "/app_shell/backup-platform/lib/python3.6/site-packages/apscheduler/executors/base.py", line 125, in run_job
    retval = job.func(*job.args, **job.kwargs)
  File "/app_shell/backup-platform/webadmins/scheduler.py", line 82, in autoAddJob
    self.delCronJob(job_id=j)
  File "/app_shell/backup-platform/webadmins/scheduler.py", line 48, in delCronJob
    if not jid["job_id"]:
KeyError: 'job_id'
Job "abstract_schedule.autoAddJob (trigger: interval[0:00:05], next run at: 2019-07-19 08:14:18 UTC)" raised an exception
Traceback (most recent call last):
  File "/app_shell/backup-platform/lib/python3.6/site-packages/apscheduler/executors/base.py", line 125, in run_job
    retval = job.func(*job.args, **job.kwargs)
  File "/app_shell/backup-platform/webadmins/scheduler.py", line 82, in autoAddJob
    self.delCronJob(job_id=j)
  File "/app_shell/backup-platform/webadmins/scheduler.py", line 48, in delCronJob
    if not jid["job_id"]:
KeyError: 'job_id'
Job "abstract_schedule.autoAddJob (trigger: interval[0:00:05], next run at: 2019-07-19 08:14:23 UTC)" raised an exception
Traceback (most recent call last):
  File "/app_shell/backup-platform/lib/python3.6/site-packages/apscheduler/executors/base.py", line 125, in run_job
    retval = job.func(*job.args, **job.kwargs)
  File "/app_shell/backup-platform/webadmins/scheduler.py", line 82, in autoAddJob
    self.delCronJob(job_id=j)
  File "/app_shell/backup-platform/webadmins/scheduler.py", line 48, in delCronJob
    if not jid["job_id"]:
KeyError: 'job_id'
Job "abstract_schedule.autoAddJob (trigger: interval[0:00:05], next run at: 2019-07-19 08:14:28 UTC)" raised an exception
Traceback (most recent call last):
  File "/app_shell/backup-platform/lib/python3.6/site-packages/apscheduler/executors/base.py", line 125, in run_job
    retval = job.func(*job.args, **job.kwargs)
  File "/app_shell/backup-platform/webadmins/scheduler.py", line 82, in autoAddJob
    self.delCronJob(job_id=j)
  File "/app_shell/backup-platform/webadmins/scheduler.py", line 48, in delCronJob
    if not jid["job_id"]:
KeyError: 'job_id'
Job "abstract_schedule.autoAddJob (trigger: interval[0:00:05], next run at: 2019-07-19 08:14:33 UTC)" raised an exception
Traceback (most recent call last):
  File "/app_shell/backup-platform/lib/python3.6/site-packages/apscheduler/executors/base.py", line 125, in run_job
    retval = job.func(*job.args, **job.kwargs)
  File "/app_shell/backup-platform/webadmins/scheduler.py", line 82, in autoAddJob
    self.delCronJob(job_id=j)
  File "/app_shell/backup-platform/webadmins/scheduler.py", line 48, in delCronJob
    if not jid["job_id"]:
KeyError: 'job_id'
Job "abstract_schedule.autoAddJob (trigger: interval[0:00:05], next run at: 2019-07-19 08:14:38 UTC)" raised an exception
Traceback (most recent call last):
  File "/app_shell/backup-platform/lib/python3.6/site-packages/apscheduler/executors/base.py", line 125, in run_job
    retval = job.func(*job.args, **job.kwargs)
  File "/app_shell/backup-platform/webadmins/scheduler.py", line 82, in autoAddJob
    self.delCronJob(job_id=j)
  File "/app_shell/backup-platform/webadmins/scheduler.py", line 48, in delCronJob
    if not jid["job_id"]:
KeyError: 'job_id'
Job "abstract_schedule.autoAddJob (trigger: interval[0:00:05], next run at: 2019-07-19 08:14:43 UTC)" raised an exception
Traceback (most recent call last):
  File "/app_shell/backup-platform/lib/python3.6/site-packages/apscheduler/executors/base.py", line 125, in run_job
    retval = job.func(*job.args, **job.kwargs)
  File "/app_shell/backup-platform/webadmins/scheduler.py", line 82, in autoAddJob
    self.delCronJob(job_id=j)
  File "/app_shell/backup-platform/webadmins/scheduler.py", line 48, in delCronJob
    if not jid["job_id"]:
KeyError: 'job_id'
Job "abstract_schedule.autoAddJob (trigger: interval[0:00:05], next run at: 2019-07-19 08:14:48 UTC)" raised an exception
Traceback (most recent call last):
  File "/app_shell/backup-platform/lib/python3.6/site-packages/apscheduler/executors/base.py", line 125, in run_job
    retval = job.func(*job.args, **job.kwargs)
  File "/app_shell/backup-platform/webadmins/scheduler.py", line 82, in autoAddJob
    self.delCronJob(job_id=j)
  File "/app_shell/backup-platform/webadmins/scheduler.py", line 48, in delCronJob
    if not jid["job_id"]:
KeyError: 'job_id'
Job "abstract_schedule.autoAddJob (trigger: interval[0:00:05], next run at: 2019-07-19 08:14:53 UTC)" raised an exception
Traceback (most recent call last):
  File "/app_shell/backup-platform/lib/python3.6/site-packages/apscheduler/executors/base.py", line 125, in run_job
    retval = job.func(*job.args, **job.kwargs)
  File "/app_shell/backup-platform/webadmins/scheduler.py", line 82, in autoAddJob
    self.delCronJob(job_id=j)
  File "/app_shell/backup-platform/webadmins/scheduler.py", line 48, in delCronJob
    if not jid["job_id"]:
KeyError: 'job_id'
Job "abstract_schedule.autoAddJob (trigger: interval[0:00:05], next run at: 2019-07-19 08:14:58 UTC)" raised an exception
Traceback (most recent call last):
  File "/app_shell/backup-platform/lib/python3.6/site-packages/apscheduler/executors/base.py", line 125, in run_job
    retval = job.func(*job.args, **job.kwargs)
  File "/app_shell/backup-platform/webadmins/scheduler.py", line 82, in autoAddJob
    self.delCronJob(job_id=j)
  File "/app_shell/backup-platform/webadmins/scheduler.py", line 48, in delCronJob
    if not jid["job_id"]:
KeyError: 'job_id'
Job "abstract_schedule.autoAddJob (trigger: interval[0:00:05], next run at: 2019-07-19 08:15:03 UTC)" raised an exception
Traceback (most recent call last):
  File "/app_shell/backup-platform/lib/python3.6/site-packages/apscheduler/executors/base.py", line 125, in run_job
    retval = job.func(*job.args, **job.kwargs)
  File "/app_shell/backup-platform/webadmins/scheduler.py", line 82, in autoAddJob
    self.delCronJob(job_id=j)
  File "/app_shell/backup-platform/webadmins/scheduler.py", line 48, in delCronJob
    if not jid["job_id"]:
KeyError: 'job_id'
Job "db_backup_tools.db_backup_start (trigger: cron[day_of_week='0,1,2,3,4,5,6', minute='*/3'], next run at: 2019-07-19 08:18:00 UTC)" raised an exception
Traceback (most recent call last):
  File "/app_shell/backup-platform/lib/python3.6/site-packages/apscheduler/executors/base.py", line 125, in run_job
    retval = job.func(*job.args, **job.kwargs)
  File "/app_shell/backup-platform/webadmins/sched_task/sched_db_backup_tasks.py", line 43, in db_backup_start
    result = x.xtrabackup_full_backup(backup_to_local_path)
  File "/app_shell/backup-platform/webadmins/lib/db_backup_tools.py", line 65, in xtrabackup_full_backup
    raise DB_BACKUP_ERROR(u"主机%s数据库备份失败! err:%s" % (self.sshObj.host, output["stderr"].decode(encoding="utf-8").strip()))
db_backup_tools.DB_BACKUP_ERROR: 主机172.16.70.221数据库备份失败! err:190628 17:23:33 innobackupex: Starting the backup operation

IMPORTANT: Please check that the backup run completes successfully.
           At the end of a successful backup run innobackupex
           prints "completed OK!".

Can't locate Digest/MD5.pm in @INC (@INC contains: /usr/local/lib64/perl5 /usr/local/share/perl5 /usr/lib64/perl5/vendor_perl /usr/share/perl5/vendor_perl /usr/lib64/perl5 /usr/share/perl5 .) at - line 693.
BEGIN failed--compilation aborted at - line 693.
190628 17:23:33 Connecting to MySQL server host: 172.16.70.221, user: root, password: set, port: 3306, socket: not set
Using server version 5.7.26
/usr/local/percona-xtrabackup/bin/innobackupex version 2.4.9 based on MySQL server 5.7.13 Linux (x86_64) (revision id: a467167cdd4)
xtrabackup: uses posix_fadvise().
xtrabackup: cd to /var/lib/mysql/
xtrabackup: open files limit requested 0, set to 1024
xtrabackup: using the following InnoDB configuration:
xtrabackup:   innodb_data_home_dir = .
xtrabackup:   innodb_data_file_path = ibdata1:12M:autoextend
xtrabackup:   innodb_log_group_home_dir = ./
xtrabackup:   innodb_log_files_in_group = 2
xtrabackup:   innodb_log_file_size = 50331648
InnoDB: Number of pools: 1
innobackupex: Can't create/write to file '/mnt/nfs/588525330779870/172.16.70.221/20190719081500/xtrabackup_logfile' (Errcode: 17 - File exists)
xtrabackup: error: failed to open the target stream for 'xtrabackup_logfile'.
Job "abstract_schedule.autoAddJob (trigger: interval[0:00:05], next run at: 2019-07-19 08:15:08 UTC)" raised an exception
Traceback (most recent call last):
  File "/app_shell/backup-platform/lib/python3.6/site-packages/apscheduler/executors/base.py", line 125, in run_job
    retval = job.func(*job.args, **job.kwargs)
  File "/app_shell/backup-platform/webadmins/scheduler.py", line 82, in autoAddJob
    self.delCronJob(job_id=j)
  File "/app_shell/backup-platform/webadmins/scheduler.py", line 48, in delCronJob
    if not jid["job_id"]:
KeyError: 'job_id'
Job "abstract_schedule.autoAddJob (trigger: interval[0:00:05], next run at: 2019-07-19 08:15:13 UTC)" raised an exception
Traceback (most recent call last):
  File "/app_shell/backup-platform/lib/python3.6/site-packages/apscheduler/executors/base.py", line 125, in run_job
    retval = job.func(*job.args, **job.kwargs)
  File "/app_shell/backup-platform/webadmins/scheduler.py", line 82, in autoAddJob
    self.delCronJob(job_id=j)
  File "/app_shell/backup-platform/webadmins/scheduler.py", line 48, in delCronJob
    if not jid["job_id"]:
KeyError: 'job_id'
Job "abstract_schedule.autoAddJob (trigger: interval[0:00:05], next run at: 2019-07-19 08:15:18 UTC)" raised an exception
Traceback (most recent call last):
  File "/app_shell/backup-platform/lib/python3.6/site-packages/apscheduler/executors/base.py", line 125, in run_job
    retval = job.func(*job.args, **job.kwargs)
  File "/app_shell/backup-platform/webadmins/scheduler.py", line 82, in autoAddJob
    self.delCronJob(job_id=j)
  File "/app_shell/backup-platform/webadmins/scheduler.py", line 48, in delCronJob
    if not jid["job_id"]:
KeyError: 'job_id'
Job "abstract_schedule.autoAddJob (trigger: interval[0:00:05], next run at: 2019-07-19 08:15:23 UTC)" raised an exception
Traceback (most recent call last):
  File "/app_shell/backup-platform/lib/python3.6/site-packages/apscheduler/executors/base.py", line 125, in run_job
    retval = job.func(*job.args, **job.kwargs)
  File "/app_shell/backup-platform/webadmins/scheduler.py", line 82, in autoAddJob
    self.delCronJob(job_id=j)
  File "/app_shell/backup-platform/webadmins/scheduler.py", line 48, in delCronJob
    if not jid["job_id"]:
KeyError: 'job_id'
Job "abstract_schedule.autoAddJob (trigger: interval[0:00:05], next run at: 2019-07-19 08:15:28 UTC)" raised an exception
Traceback (most recent call last):
  File "/app_shell/backup-platform/lib/python3.6/site-packages/apscheduler/executors/base.py", line 125, in run_job
    retval = job.func(*job.args, **job.kwargs)
  File "/app_shell/backup-platform/webadmins/scheduler.py", line 82, in autoAddJob
    self.delCronJob(job_id=j)
  File "/app_shell/backup-platform/webadmins/scheduler.py", line 48, in delCronJob
    if not jid["job_id"]:
KeyError: 'job_id'
Job "db_backup_tools.db_backup_start (trigger: cron[day_of_week='0,1,2,3,4,5,6', minute='*/3'], next run at: 2019-07-19 08:33:00 UTC)" raised an exception
Traceback (most recent call last):
  File "/app_shell/backup-platform/lib/python3.6/site-packages/apscheduler/executors/base.py", line 125, in run_job
    retval = job.func(*job.args, **job.kwargs)
  File "/app_shell/backup-platform/webadmins/sched_task/sched_db_backup_tasks.py", line 43, in db_backup_start
    result = x.xtrabackup_full_backup(backup_to_local_path)
  File "/app_shell/backup-platform/webadmins/lib/db_backup_tools.py", line 65, in xtrabackup_full_backup
    raise DB_BACKUP_ERROR(u"主机%s数据库备份失败! err:%s" % (self.sshObj.host, output["stderr"].decode(encoding="utf-8").strip()))
db_backup_tools.DB_BACKUP_ERROR: 主机172.16.70.221数据库备份失败! err:190628 17:38:33 innobackupex: Starting the backup operation

IMPORTANT: Please check that the backup run completes successfully.
           At the end of a successful backup run innobackupex
           prints "completed OK!".

Can't locate Digest/MD5.pm in @INC (@INC contains: /usr/local/lib64/perl5 /usr/local/share/perl5 /usr/lib64/perl5/vendor_perl /usr/share/perl5/vendor_perl /usr/lib64/perl5 /usr/share/perl5 .) at - line 693.
BEGIN failed--compilation aborted at - line 693.
190628 17:38:33 Connecting to MySQL server host: 172.16.70.221, user: root, password: set, port: 3306, socket: not set
Using server version 5.7.26
/usr/local/percona-xtrabackup/bin/innobackupex version 2.4.9 based on MySQL server 5.7.13 Linux (x86_64) (revision id: a467167cdd4)
xtrabackup: uses posix_fadvise().
xtrabackup: cd to /var/lib/mysql/
xtrabackup: open files limit requested 0, set to 1024
xtrabackup: using the following InnoDB configuration:
xtrabackup:   innodb_data_home_dir = .
xtrabackup:   innodb_data_file_path = ibdata1:12M:autoextend
xtrabackup:   innodb_log_group_home_dir = ./
xtrabackup:   innodb_log_files_in_group = 2
xtrabackup:   innodb_log_file_size = 50331648
InnoDB: Number of pools: 1
innobackupex: Can't create/write to file '/mnt/nfs/588525330779870/172.16.70.221/20190719083000/xtrabackup_logfile' (Errcode: 17 - File exists)
xtrabackup: error: failed to open the target stream for 'xtrabackup_logfile'.
Job "db_backup_tools.db_backup_start (trigger: cron[day_of_week='0,1,2,3,4,5,6', minute='*/3'], next run at: 2019-07-19 08:36:00 UTC)" raised an exception
Traceback (most recent call last):
  File "/app_shell/backup-platform/lib/python3.6/site-packages/apscheduler/executors/base.py", line 125, in run_job
    retval = job.func(*job.args, **job.kwargs)
  File "/app_shell/backup-platform/webadmins/sched_task/sched_db_backup_tasks.py", line 43, in db_backup_start
    result = x.xtrabackup_full_backup(backup_to_local_path)
  File "/app_shell/backup-platform/webadmins/lib/db_backup_tools.py", line 65, in xtrabackup_full_backup
    raise DB_BACKUP_ERROR(u"主机%s数据库备份失败! err:%s" % (self.sshObj.host, output["stderr"].decode(encoding="utf-8").strip()))
db_backup_tools.DB_BACKUP_ERROR: 主机172.16.70.221数据库备份失败! err:190628 17:41:33 innobackupex: Starting the backup operation

IMPORTANT: Please check that the backup run completes successfully.
           At the end of a successful backup run innobackupex
           prints "completed OK!".

Can't locate Digest/MD5.pm in @INC (@INC contains: /usr/local/lib64/perl5 /usr/local/share/perl5 /usr/lib64/perl5/vendor_perl /usr/share/perl5/vendor_perl /usr/lib64/perl5 /usr/share/perl5 .) at - line 693.
BEGIN failed--compilation aborted at - line 693.
190628 17:41:33 Connecting to MySQL server host: 172.16.70.221, user: root, password: set, port: 3306, socket: not set
Using server version 5.7.26
/usr/local/percona-xtrabackup/bin/innobackupex version 2.4.9 based on MySQL server 5.7.13 Linux (x86_64) (revision id: a467167cdd4)
xtrabackup: uses posix_fadvise().
xtrabackup: cd to /var/lib/mysql/
xtrabackup: open files limit requested 0, set to 1024
xtrabackup: using the following InnoDB configuration:
xtrabackup:   innodb_data_home_dir = .
xtrabackup:   innodb_data_file_path = ibdata1:12M:autoextend
xtrabackup:   innodb_log_group_home_dir = ./
xtrabackup:   innodb_log_files_in_group = 2
xtrabackup:   innodb_log_file_size = 50331648
InnoDB: Number of pools: 1
innobackupex: Can't create/write to file '/mnt/nfs/588525330779870/172.16.70.221/20190719083300/xtrabackup_logfile' (Errcode: 17 - File exists)
xtrabackup: error: failed to open the target stream for 'xtrabackup_logfile'.
Job "db_backup_tools.db_backup_start (trigger: cron[day_of_week='0,1,2,3,4,5,6', minute='*/1'], next run at: 2019-07-19 08:37:00 UTC)" raised an exception
Traceback (most recent call last):
  File "/app_shell/backup-platform/lib/python3.6/site-packages/apscheduler/executors/base.py", line 125, in run_job
    retval = job.func(*job.args, **job.kwargs)
  File "/app_shell/backup-platform/webadmins/sched_task/sched_db_backup_tasks.py", line 43, in db_backup_start
    result = x.xtrabackup_full_backup(backup_to_local_path)
  File "/app_shell/backup-platform/webadmins/lib/db_backup_tools.py", line 65, in xtrabackup_full_backup
    raise DB_BACKUP_ERROR(u"主机%s数据库备份失败! err:%s" % (self.sshObj.host, output["stderr"].decode(encoding="utf-8").strip()))
db_backup_tools.DB_BACKUP_ERROR: 主机172.16.70.221数据库备份失败! err:190628 17:44:33 innobackupex: Starting the backup operation

IMPORTANT: Please check that the backup run completes successfully.
           At the end of a successful backup run innobackupex
           prints "completed OK!".

Can't locate Digest/MD5.pm in @INC (@INC contains: /usr/local/lib64/perl5 /usr/local/share/perl5 /usr/lib64/perl5/vendor_perl /usr/share/perl5/vendor_perl /usr/lib64/perl5 /usr/share/perl5 .) at - line 693.
BEGIN failed--compilation aborted at - line 693.
190628 17:44:33 Connecting to MySQL server host: 172.16.70.221, user: root, password: set, port: 3306, socket: not set
Using server version 5.7.26
/usr/local/percona-xtrabackup/bin/innobackupex version 2.4.9 based on MySQL server 5.7.13 Linux (x86_64) (revision id: a467167cdd4)
xtrabackup: uses posix_fadvise().
xtrabackup: cd to /var/lib/mysql/
xtrabackup: open files limit requested 0, set to 1024
xtrabackup: using the following InnoDB configuration:
xtrabackup:   innodb_data_home_dir = .
xtrabackup:   innodb_data_file_path = ibdata1:12M:autoextend
xtrabackup:   innodb_log_group_home_dir = ./
xtrabackup:   innodb_log_files_in_group = 2
xtrabackup:   innodb_log_file_size = 50331648
InnoDB: Number of pools: 1
innobackupex: Can't create/write to file '/mnt/nfs/588525330779870/172.16.70.221/20190719083600/xtrabackup_logfile' (Errcode: 17 - File exists)
xtrabackup: error: failed to open the target stream for 'xtrabackup_logfile'.
Job "db_backup_tools.db_backup_start (trigger: cron[day_of_week='0,1,2,3,4,5,6', minute='*/1'], next run at: 2019-07-19 09:27:00 UTC)" raised an exception
Traceback (most recent call last):
  File "/app_shell/backup-platform/lib/python3.6/site-packages/apscheduler/executors/base.py", line 125, in run_job
    retval = job.func(*job.args, **job.kwargs)
  File "/app_shell/backup-platform/webadmins/sched_task/sched_db_backup_tasks.py", line 65, in db_backup_start
    self.before_db_backup_status_add(backup_to_local_path)
  File "/app_shell/backup-platform/webadmins/sched_task/sched_db_backup_tasks.py", line 46, in before_db_backup_status_add
    data = {"stat_time": stat_time, "task_id": task_id, "source_addr": source_addr, "svc_type": "db",
NameError: name 'source_addr' is not defined
Job "db_backup_tools.db_backup_start (trigger: cron[day_of_week='0,1,2,3,4,5,6', minute='*/1'], next run at: 2019-07-19 09:28:00 UTC)" raised an exception
Traceback (most recent call last):
  File "/app_shell/backup-platform/lib/python3.6/site-packages/apscheduler/executors/base.py", line 125, in run_job
    retval = job.func(*job.args, **job.kwargs)
  File "/app_shell/backup-platform/webadmins/sched_task/sched_db_backup_tasks.py", line 65, in db_backup_start
    self.before_db_backup_status_add(backup_to_local_path)
  File "/app_shell/backup-platform/webadmins/sched_task/sched_db_backup_tasks.py", line 46, in before_db_backup_status_add
    data = {"stat_time": stat_time, "task_id": task_id, "source_addr": source_addr, "svc_type": "db",
NameError: name 'source_addr' is not defined
Job "fs_backup_tools.fs_backup_start (trigger: cron[day_of_week='0,1,2,3,4,5,6', minute='*/1'], next run at: 2019-07-19 09:52:00 UTC)" raised an exception
Traceback (most recent call last):
  File "/app_shell/backup-platform/lib/python3.6/site-packages/apscheduler/executors/base.py", line 125, in run_job
    retval = job.func(*job.args, **job.kwargs)
  File "/app_shell/backup-platform/webadmins/sched_task/sched_fs_backup_tasks.py", line 69, in fs_backup_start
    data = {"task_status": 1, "message": pymysql.escape_string(result)}
NameError: name 'pymysql' is not defined
Job "fs_backup_tools.fs_backup_start (trigger: cron[day_of_week='0,1,2,3,4,5,6', minute='*/1'], next run at: 2019-07-19 09:53:00 UTC)" raised an exception
Traceback (most recent call last):
  File "/app_shell/backup-platform/lib/python3.6/site-packages/apscheduler/executors/base.py", line 125, in run_job
    retval = job.func(*job.args, **job.kwargs)
  File "/app_shell/backup-platform/webadmins/sched_task/sched_fs_backup_tasks.py", line 69, in fs_backup_start
    data = {"task_status": 1, "message": pymysql.escape_string(result)}
NameError: name 'pymysql' is not defined
Job "abstract_schedule.autoAddJob (trigger: interval[0:00:05], next run at: 2019-07-20 06:32:18 UTC)" raised an exception
Traceback (most recent call last):
  File "/app_shell/backup-platform/lib/python3.6/site-packages/apscheduler/executors/base.py", line 125, in run_job
    retval = job.func(*job.args, **job.kwargs)
  File "/app_shell/backup-platform/webadmins/scheduler.py", line 68, in autoAddJob
    current_jobs = self.getBackupPolicy()
  File "/app_shell/backup-platform/webadmins/scheduler.py", line 125, in getBackupPolicy
    result[t_id].update(day_of_week)
KeyError: '1000000001'
Job "abstract_schedule.autoAddJob (trigger: interval[0:00:05], next run at: 2019-07-20 06:32:23 UTC)" raised an exception
Traceback (most recent call last):
  File "/app_shell/backup-platform/lib/python3.6/site-packages/apscheduler/executors/base.py", line 125, in run_job
    retval = job.func(*job.args, **job.kwargs)
  File "/app_shell/backup-platform/webadmins/scheduler.py", line 68, in autoAddJob
    current_jobs = self.getBackupPolicy()
  File "/app_shell/backup-platform/webadmins/scheduler.py", line 125, in getBackupPolicy
    result[t_id].update(day_of_week)
KeyError: '1000000001'
Job "abstract_schedule.autoAddJob (trigger: interval[0:00:05], next run at: 2019-07-20 06:32:28 UTC)" raised an exception
Traceback (most recent call last):
  File "/app_shell/backup-platform/lib/python3.6/site-packages/apscheduler/executors/base.py", line 125, in run_job
    retval = job.func(*job.args, **job.kwargs)
  File "/app_shell/backup-platform/webadmins/scheduler.py", line 68, in autoAddJob
    current_jobs = self.getBackupPolicy()
  File "/app_shell/backup-platform/webadmins/scheduler.py", line 125, in getBackupPolicy
    result[t_id].update(day_of_week)
KeyError: '1000000001'
Job "abstract_schedule.autoAddJob (trigger: interval[0:00:05], next run at: 2019-07-20 06:32:33 UTC)" raised an exception
Traceback (most recent call last):
  File "/app_shell/backup-platform/lib/python3.6/site-packages/apscheduler/executors/base.py", line 125, in run_job
    retval = job.func(*job.args, **job.kwargs)
  File "/app_shell/backup-platform/webadmins/scheduler.py", line 68, in autoAddJob
    current_jobs = self.getBackupPolicy()
  File "/app_shell/backup-platform/webadmins/scheduler.py", line 125, in getBackupPolicy
    result[t_id].update(day_of_week)
KeyError: '1000000001'
Job "abstract_schedule.autoAddJob (trigger: interval[0:00:05], next run at: 2019-07-20 06:32:38 UTC)" raised an exception
Traceback (most recent call last):
  File "/app_shell/backup-platform/lib/python3.6/site-packages/apscheduler/executors/base.py", line 125, in run_job
    retval = job.func(*job.args, **job.kwargs)
  File "/app_shell/backup-platform/webadmins/scheduler.py", line 68, in autoAddJob
    current_jobs = self.getBackupPolicy()
  File "/app_shell/backup-platform/webadmins/scheduler.py", line 125, in getBackupPolicy
    result[t_id].update(day_of_week)
KeyError: '1000000001'
Job "abstract_schedule.autoAddJob (trigger: interval[0:00:05], next run at: 2019-07-20 06:32:43 UTC)" raised an exception
Traceback (most recent call last):
  File "/app_shell/backup-platform/lib/python3.6/site-packages/apscheduler/executors/base.py", line 125, in run_job
    retval = job.func(*job.args, **job.kwargs)
  File "/app_shell/backup-platform/webadmins/scheduler.py", line 68, in autoAddJob
    current_jobs = self.getBackupPolicy()
  File "/app_shell/backup-platform/webadmins/scheduler.py", line 125, in getBackupPolicy
    result[t_id].update(day_of_week)
KeyError: '1000000001'
Job "abstract_schedule.autoAddJob (trigger: interval[0:00:05], next run at: 2019-07-20 06:32:48 UTC)" raised an exception
Traceback (most recent call last):
  File "/app_shell/backup-platform/lib/python3.6/site-packages/apscheduler/executors/base.py", line 125, in run_job
    retval = job.func(*job.args, **job.kwargs)
  File "/app_shell/backup-platform/webadmins/scheduler.py", line 68, in autoAddJob
    current_jobs = self.getBackupPolicy()
  File "/app_shell/backup-platform/webadmins/scheduler.py", line 125, in getBackupPolicy
    result[t_id].update(day_of_week)
KeyError: '1000000001'
Job "abstract_schedule.autoAddJob (trigger: interval[0:00:05], next run at: 2019-07-20 06:32:53 UTC)" raised an exception
Traceback (most recent call last):
  File "/app_shell/backup-platform/lib/python3.6/site-packages/apscheduler/executors/base.py", line 125, in run_job
    retval = job.func(*job.args, **job.kwargs)
  File "/app_shell/backup-platform/webadmins/scheduler.py", line 68, in autoAddJob
    current_jobs = self.getBackupPolicy()
  File "/app_shell/backup-platform/webadmins/scheduler.py", line 125, in getBackupPolicy
    result[t_id].update(day_of_week)
KeyError: '1000000001'
Job "abstract_schedule.autoAddJob (trigger: interval[0:00:05], next run at: 2019-07-20 06:32:58 UTC)" raised an exception
Traceback (most recent call last):
  File "/app_shell/backup-platform/lib/python3.6/site-packages/apscheduler/executors/base.py", line 125, in run_job
    retval = job.func(*job.args, **job.kwargs)
  File "/app_shell/backup-platform/webadmins/scheduler.py", line 68, in autoAddJob
    current_jobs = self.getBackupPolicy()
  File "/app_shell/backup-platform/webadmins/scheduler.py", line 125, in getBackupPolicy
    result[t_id].update(day_of_week)
KeyError: '1000000001'
Job "abstract_schedule.autoAddJob (trigger: interval[0:00:05], next run at: 2019-07-20 06:33:03 UTC)" raised an exception
Traceback (most recent call last):
  File "/app_shell/backup-platform/lib/python3.6/site-packages/apscheduler/executors/base.py", line 125, in run_job
    retval = job.func(*job.args, **job.kwargs)
  File "/app_shell/backup-platform/webadmins/scheduler.py", line 68, in autoAddJob
    current_jobs = self.getBackupPolicy()
  File "/app_shell/backup-platform/webadmins/scheduler.py", line 125, in getBackupPolicy
    result[t_id].update(day_of_week)
KeyError: '1000000001'
Job "abstract_schedule.autoAddJob (trigger: interval[0:00:05], next run at: 2019-07-20 06:33:08 UTC)" raised an exception
Traceback (most recent call last):
  File "/app_shell/backup-platform/lib/python3.6/site-packages/apscheduler/executors/base.py", line 125, in run_job
    retval = job.func(*job.args, **job.kwargs)
  File "/app_shell/backup-platform/webadmins/scheduler.py", line 68, in autoAddJob
    current_jobs = self.getBackupPolicy()
  File "/app_shell/backup-platform/webadmins/scheduler.py", line 125, in getBackupPolicy
    result[t_id].update(day_of_week)
KeyError: '1000000001'
Job "abstract_schedule.autoAddJob (trigger: interval[0:00:05], next run at: 2019-07-20 06:33:13 UTC)" raised an exception
Traceback (most recent call last):
  File "/app_shell/backup-platform/lib/python3.6/site-packages/apscheduler/executors/base.py", line 125, in run_job
    retval = job.func(*job.args, **job.kwargs)
  File "/app_shell/backup-platform/webadmins/scheduler.py", line 68, in autoAddJob
    current_jobs = self.getBackupPolicy()
  File "/app_shell/backup-platform/webadmins/scheduler.py", line 125, in getBackupPolicy
    result[t_id].update(day_of_week)
KeyError: '1000000001'
Job "abstract_schedule.autoAddJob (trigger: interval[0:00:05], next run at: 2019-07-20 06:33:18 UTC)" raised an exception
Traceback (most recent call last):
  File "/app_shell/backup-platform/lib/python3.6/site-packages/apscheduler/executors/base.py", line 125, in run_job
    retval = job.func(*job.args, **job.kwargs)
  File "/app_shell/backup-platform/webadmins/scheduler.py", line 68, in autoAddJob
    current_jobs = self.getBackupPolicy()
  File "/app_shell/backup-platform/webadmins/scheduler.py", line 125, in getBackupPolicy
    result[t_id].update(day_of_week)
KeyError: '1000000001'
Job "abstract_schedule.autoAddJob (trigger: interval[0:00:05], next run at: 2019-07-20 06:33:23 UTC)" raised an exception
Traceback (most recent call last):
  File "/app_shell/backup-platform/lib/python3.6/site-packages/apscheduler/executors/base.py", line 125, in run_job
    retval = job.func(*job.args, **job.kwargs)
  File "/app_shell/backup-platform/webadmins/scheduler.py", line 68, in autoAddJob
    current_jobs = self.getBackupPolicy()
  File "/app_shell/backup-platform/webadmins/scheduler.py", line 125, in getBackupPolicy
    result[t_id].update(day_of_week)
KeyError: '1000000001'
Job "abstract_schedule.autoAddJob (trigger: interval[0:00:05], next run at: 2019-07-20 06:33:28 UTC)" raised an exception
Traceback (most recent call last):
  File "/app_shell/backup-platform/lib/python3.6/site-packages/apscheduler/executors/base.py", line 125, in run_job
    retval = job.func(*job.args, **job.kwargs)
  File "/app_shell/backup-platform/webadmins/scheduler.py", line 68, in autoAddJob
    current_jobs = self.getBackupPolicy()
  File "/app_shell/backup-platform/webadmins/scheduler.py", line 125, in getBackupPolicy
    result[t_id].update(day_of_week)
KeyError: '1000000001'
Job "abstract_schedule.autoAddJob (trigger: interval[0:00:05], next run at: 2019-07-20 06:33:33 UTC)" raised an exception
Traceback (most recent call last):
  File "/app_shell/backup-platform/lib/python3.6/site-packages/apscheduler/executors/base.py", line 125, in run_job
    retval = job.func(*job.args, **job.kwargs)
  File "/app_shell/backup-platform/webadmins/scheduler.py", line 68, in autoAddJob
    current_jobs = self.getBackupPolicy()
  File "/app_shell/backup-platform/webadmins/scheduler.py", line 125, in getBackupPolicy
    result[t_id].update(day_of_week)
KeyError: '1000000001'
Job "abstract_schedule.autoAddJob (trigger: interval[0:00:05], next run at: 2019-07-20 06:33:38 UTC)" raised an exception
Traceback (most recent call last):
  File "/app_shell/backup-platform/lib/python3.6/site-packages/apscheduler/executors/base.py", line 125, in run_job
    retval = job.func(*job.args, **job.kwargs)
  File "/app_shell/backup-platform/webadmins/scheduler.py", line 68, in autoAddJob
    current_jobs = self.getBackupPolicy()
  File "/app_shell/backup-platform/webadmins/scheduler.py", line 125, in getBackupPolicy
    result[t_id].update(day_of_week)
KeyError: '1000000001'
Job "abstract_schedule.autoAddJob (trigger: interval[0:00:05], next run at: 2019-07-20 06:33:43 UTC)" raised an exception
Traceback (most recent call last):
  File "/app_shell/backup-platform/lib/python3.6/site-packages/apscheduler/executors/base.py", line 125, in run_job
    retval = job.func(*job.args, **job.kwargs)
  File "/app_shell/backup-platform/webadmins/scheduler.py", line 68, in autoAddJob
    current_jobs = self.getBackupPolicy()
  File "/app_shell/backup-platform/webadmins/scheduler.py", line 125, in getBackupPolicy
    result[t_id].update(day_of_week)
KeyError: '1000000001'
Job "abstract_schedule.autoAddJob (trigger: interval[0:00:05], next run at: 2019-07-20 06:33:48 UTC)" raised an exception
Traceback (most recent call last):
  File "/app_shell/backup-platform/lib/python3.6/site-packages/apscheduler/executors/base.py", line 125, in run_job
    retval = job.func(*job.args, **job.kwargs)
  File "/app_shell/backup-platform/webadmins/scheduler.py", line 68, in autoAddJob
    current_jobs = self.getBackupPolicy()
  File "/app_shell/backup-platform/webadmins/scheduler.py", line 125, in getBackupPolicy
    result[t_id].update(day_of_week)
KeyError: '1000000001'
Job "abstract_schedule.autoAddJob (trigger: interval[0:00:05], next run at: 2019-07-20 06:33:53 UTC)" raised an exception
Traceback (most recent call last):
  File "/app_shell/backup-platform/lib/python3.6/site-packages/apscheduler/executors/base.py", line 125, in run_job
    retval = job.func(*job.args, **job.kwargs)
  File "/app_shell/backup-platform/webadmins/scheduler.py", line 68, in autoAddJob
    current_jobs = self.getBackupPolicy()
  File "/app_shell/backup-platform/webadmins/scheduler.py", line 125, in getBackupPolicy
    result[t_id].update(day_of_week)
KeyError: '1000000001'
Job "abstract_schedule.autoAddJob (trigger: interval[0:00:05], next run at: 2019-07-20 06:33:58 UTC)" raised an exception
Traceback (most recent call last):
  File "/app_shell/backup-platform/lib/python3.6/site-packages/apscheduler/executors/base.py", line 125, in run_job
    retval = job.func(*job.args, **job.kwargs)
  File "/app_shell/backup-platform/webadmins/scheduler.py", line 68, in autoAddJob
    current_jobs = self.getBackupPolicy()
  File "/app_shell/backup-platform/webadmins/scheduler.py", line 125, in getBackupPolicy
    result[t_id].update(day_of_week)
KeyError: '1000000001'
Job "abstract_schedule.autoAddJob (trigger: interval[0:00:05], next run at: 2019-07-20 06:34:03 UTC)" raised an exception
Traceback (most recent call last):
  File "/app_shell/backup-platform/lib/python3.6/site-packages/apscheduler/executors/base.py", line 125, in run_job
    retval = job.func(*job.args, **job.kwargs)
  File "/app_shell/backup-platform/webadmins/scheduler.py", line 68, in autoAddJob
    current_jobs = self.getBackupPolicy()
  File "/app_shell/backup-platform/webadmins/scheduler.py", line 125, in getBackupPolicy
    result[t_id].update(day_of_week)
KeyError: '1000000001'
Job "abstract_schedule.autoAddJob (trigger: interval[0:00:05], next run at: 2019-07-20 06:34:08 UTC)" raised an exception
Traceback (most recent call last):
  File "/app_shell/backup-platform/lib/python3.6/site-packages/apscheduler/executors/base.py", line 125, in run_job
    retval = job.func(*job.args, **job.kwargs)
  File "/app_shell/backup-platform/webadmins/scheduler.py", line 68, in autoAddJob
    current_jobs = self.getBackupPolicy()
  File "/app_shell/backup-platform/webadmins/scheduler.py", line 125, in getBackupPolicy
    result[t_id].update(day_of_week)
KeyError: '1000000001'
Job "abstract_schedule.autoAddJob (trigger: interval[0:00:05], next run at: 2019-07-20 06:34:13 UTC)" raised an exception
Traceback (most recent call last):
  File "/app_shell/backup-platform/lib/python3.6/site-packages/apscheduler/executors/base.py", line 125, in run_job
    retval = job.func(*job.args, **job.kwargs)
  File "/app_shell/backup-platform/webadmins/scheduler.py", line 68, in autoAddJob
    current_jobs = self.getBackupPolicy()
  File "/app_shell/backup-platform/webadmins/scheduler.py", line 125, in getBackupPolicy
    result[t_id].update(day_of_week)
KeyError: '1000000001'
Job "abstract_schedule.autoAddJob (trigger: interval[0:00:05], next run at: 2019-07-20 06:34:18 UTC)" raised an exception
Traceback (most recent call last):
  File "/app_shell/backup-platform/lib/python3.6/site-packages/apscheduler/executors/base.py", line 125, in run_job
    retval = job.func(*job.args, **job.kwargs)
  File "/app_shell/backup-platform/webadmins/scheduler.py", line 68, in autoAddJob
    current_jobs = self.getBackupPolicy()
  File "/app_shell/backup-platform/webadmins/scheduler.py", line 125, in getBackupPolicy
    result[t_id].update(day_of_week)
KeyError: '1000000001'
Job "abstract_schedule.autoAddJob (trigger: interval[0:00:05], next run at: 2019-07-20 06:34:23 UTC)" raised an exception
Traceback (most recent call last):
  File "/app_shell/backup-platform/lib/python3.6/site-packages/apscheduler/executors/base.py", line 125, in run_job
    retval = job.func(*job.args, **job.kwargs)
  File "/app_shell/backup-platform/webadmins/scheduler.py", line 68, in autoAddJob
    current_jobs = self.getBackupPolicy()
  File "/app_shell/backup-platform/webadmins/scheduler.py", line 125, in getBackupPolicy
    result[t_id].update(day_of_week)
KeyError: '1000000001'
Job "abstract_schedule.autoAddJob (trigger: interval[0:00:05], next run at: 2019-07-20 06:34:28 UTC)" raised an exception
Traceback (most recent call last):
  File "/app_shell/backup-platform/lib/python3.6/site-packages/apscheduler/executors/base.py", line 125, in run_job
    retval = job.func(*job.args, **job.kwargs)
  File "/app_shell/backup-platform/webadmins/scheduler.py", line 68, in autoAddJob
    current_jobs = self.getBackupPolicy()
  File "/app_shell/backup-platform/webadmins/scheduler.py", line 125, in getBackupPolicy
    result[t_id].update(day_of_week)
KeyError: '1000000001'
Job "abstract_schedule.autoAddJob (trigger: interval[0:00:05], next run at: 2019-07-20 06:34:33 UTC)" raised an exception
Traceback (most recent call last):
  File "/app_shell/backup-platform/lib/python3.6/site-packages/apscheduler/executors/base.py", line 125, in run_job
    retval = job.func(*job.args, **job.kwargs)
  File "/app_shell/backup-platform/webadmins/scheduler.py", line 68, in autoAddJob
  File "/app_shell/backup-platform/webadmins/scheduler.py", line 125, in getBackupPolicy
KeyError: '1000000001'
Job "abstract_schedule.autoAddJob (trigger: interval[0:00:05], next run at: 2019-07-20 06:34:38 UTC)" raised an exception
Traceback (most recent call last):
  File "/app_shell/backup-platform/lib/python3.6/site-packages/apscheduler/executors/base.py", line 125, in run_job
    retval = job.func(*job.args, **job.kwargs)
  File "/app_shell/backup-platform/webadmins/scheduler.py", line 68, in autoAddJob
  File "/app_shell/backup-platform/webadmins/scheduler.py", line 125, in getBackupPolicy
KeyError: '1000000001'
Job "abstract_schedule.autoAddJob (trigger: interval[0:00:05], next run at: 2019-07-20 06:34:43 UTC)" raised an exception
Traceback (most recent call last):
  File "/app_shell/backup-platform/lib/python3.6/site-packages/apscheduler/executors/base.py", line 125, in run_job
    retval = job.func(*job.args, **job.kwargs)
  File "/app_shell/backup-platform/webadmins/scheduler.py", line 68, in autoAddJob
  File "/app_shell/backup-platform/webadmins/scheduler.py", line 125, in getBackupPolicy
KeyError: '1000000001'
Job "abstract_schedule.autoAddJob (trigger: interval[0:00:05], next run at: 2019-07-20 06:34:48 UTC)" raised an exception
Traceback (most recent call last):
  File "/app_shell/backup-platform/lib/python3.6/site-packages/apscheduler/executors/base.py", line 125, in run_job
    retval = job.func(*job.args, **job.kwargs)
  File "/app_shell/backup-platform/webadmins/scheduler.py", line 68, in autoAddJob
  File "/app_shell/backup-platform/webadmins/scheduler.py", line 125, in getBackupPolicy
KeyError: '1000000001'
Job "abstract_schedule.autoAddJob (trigger: interval[0:00:05], next run at: 2019-07-20 06:34:53 UTC)" raised an exception
Traceback (most recent call last):
  File "/app_shell/backup-platform/lib/python3.6/site-packages/apscheduler/executors/base.py", line 125, in run_job
    retval = job.func(*job.args, **job.kwargs)
  File "/app_shell/backup-platform/webadmins/scheduler.py", line 68, in autoAddJob
  File "/app_shell/backup-platform/webadmins/scheduler.py", line 125, in getBackupPolicy
KeyError: '1000000001'
Job "abstract_schedule.autoAddJob (trigger: interval[0:00:05], next run at: 2019-07-20 06:35:05 UTC)" raised an exception
Traceback (most recent call last):
  File "/app_shell/backup-platform/lib/python3.6/site-packages/apscheduler/executors/base.py", line 125, in run_job
    retval = job.func(*job.args, **job.kwargs)
  File "/app_shell/backup-platform/webadmins/scheduler.py", line 69, in autoAddJob
    current_jobs = self.getBackupPolicy()
  File "/app_shell/backup-platform/webadmins/scheduler.py", line 127, in getBackupPolicy
    func = sched_task.sched_clean_backup_duplicate(p_id, t_id)
TypeError: 'module' object is not callable
Job "abstract_schedule.autoAddJob (trigger: interval[0:00:05], next run at: 2019-07-20 06:35:10 UTC)" raised an exception
Traceback (most recent call last):
  File "/app_shell/backup-platform/lib/python3.6/site-packages/apscheduler/executors/base.py", line 125, in run_job
    retval = job.func(*job.args, **job.kwargs)
  File "/app_shell/backup-platform/webadmins/scheduler.py", line 69, in autoAddJob
    current_jobs = self.getBackupPolicy()
  File "/app_shell/backup-platform/webadmins/scheduler.py", line 127, in getBackupPolicy
    func = sched_task.sched_clean_backup_duplicate(p_id, t_id)
TypeError: 'module' object is not callable
Job "abstract_schedule.autoAddJob (trigger: interval[0:00:05], next run at: 2019-07-20 06:35:15 UTC)" raised an exception
Traceback (most recent call last):
  File "/app_shell/backup-platform/lib/python3.6/site-packages/apscheduler/executors/base.py", line 125, in run_job
    retval = job.func(*job.args, **job.kwargs)
  File "/app_shell/backup-platform/webadmins/scheduler.py", line 69, in autoAddJob
    current_jobs = self.getBackupPolicy()
  File "/app_shell/backup-platform/webadmins/scheduler.py", line 127, in getBackupPolicy
    func = sched_task.sched_clean_backup_duplicate(p_id, t_id)
TypeError: 'module' object is not callable
Job "abstract_schedule.autoAddJob (trigger: interval[0:00:05], next run at: 2019-07-20 06:35:20 UTC)" raised an exception
Traceback (most recent call last):
  File "/app_shell/backup-platform/lib/python3.6/site-packages/apscheduler/executors/base.py", line 125, in run_job
    retval = job.func(*job.args, **job.kwargs)
  File "/app_shell/backup-platform/webadmins/scheduler.py", line 69, in autoAddJob
    current_jobs = self.getBackupPolicy()
  File "/app_shell/backup-platform/webadmins/scheduler.py", line 127, in getBackupPolicy
    func = sched_task.sched_clean_backup_duplicate(p_id, t_id)
TypeError: 'module' object is not callable
Job "abstract_schedule.autoAddJob (trigger: interval[0:00:05], next run at: 2019-07-20 06:35:25 UTC)" raised an exception
Traceback (most recent call last):
  File "/app_shell/backup-platform/lib/python3.6/site-packages/apscheduler/executors/base.py", line 125, in run_job
    retval = job.func(*job.args, **job.kwargs)
  File "/app_shell/backup-platform/webadmins/scheduler.py", line 69, in autoAddJob
    current_jobs = self.getBackupPolicy()
  File "/app_shell/backup-platform/webadmins/scheduler.py", line 127, in getBackupPolicy
    func = sched_task.sched_clean_backup_duplicate(p_id, t_id)
TypeError: 'module' object is not callable
Job "abstract_schedule.autoAddJob (trigger: interval[0:00:05], next run at: 2019-07-20 06:35:30 UTC)" raised an exception
Traceback (most recent call last):
  File "/app_shell/backup-platform/lib/python3.6/site-packages/apscheduler/executors/base.py", line 125, in run_job
    retval = job.func(*job.args, **job.kwargs)
  File "/app_shell/backup-platform/webadmins/scheduler.py", line 69, in autoAddJob
    current_jobs = self.getBackupPolicy()
  File "/app_shell/backup-platform/webadmins/scheduler.py", line 127, in getBackupPolicy
    func = sched_task.sched_clean_backup_duplicate(p_id, t_id)
TypeError: 'module' object is not callable
Job "abstract_schedule.autoAddJob (trigger: interval[0:00:05], next run at: 2019-07-20 06:35:35 UTC)" raised an exception
Traceback (most recent call last):
  File "/app_shell/backup-platform/lib/python3.6/site-packages/apscheduler/executors/base.py", line 125, in run_job
    retval = job.func(*job.args, **job.kwargs)
  File "/app_shell/backup-platform/webadmins/scheduler.py", line 69, in autoAddJob
    current_jobs = self.getBackupPolicy()
  File "/app_shell/backup-platform/webadmins/scheduler.py", line 127, in getBackupPolicy
    func = sched_task.sched_clean_backup_duplicate(p_id, t_id)
TypeError: 'module' object is not callable
Job "abstract_schedule.autoAddJob (trigger: interval[0:00:05], next run at: 2019-07-20 06:35:40 UTC)" raised an exception
Traceback (most recent call last):
  File "/app_shell/backup-platform/lib/python3.6/site-packages/apscheduler/executors/base.py", line 125, in run_job
    retval = job.func(*job.args, **job.kwargs)
  File "/app_shell/backup-platform/webadmins/scheduler.py", line 69, in autoAddJob
    current_jobs = self.getBackupPolicy()
  File "/app_shell/backup-platform/webadmins/scheduler.py", line 127, in getBackupPolicy
    func = sched_task.sched_clean_backup_duplicate(p_id, t_id)
TypeError: 'module' object is not callable
Job "abstract_schedule.autoAddJob (trigger: interval[0:00:05], next run at: 2019-07-20 06:35:45 UTC)" raised an exception
Traceback (most recent call last):
  File "/app_shell/backup-platform/lib/python3.6/site-packages/apscheduler/executors/base.py", line 125, in run_job
    retval = job.func(*job.args, **job.kwargs)
  File "/app_shell/backup-platform/webadmins/scheduler.py", line 69, in autoAddJob
    current_jobs = self.getBackupPolicy()
  File "/app_shell/backup-platform/webadmins/scheduler.py", line 127, in getBackupPolicy
    func = sched_task.sched_clean_backup_duplicate(p_id, t_id)
TypeError: 'module' object is not callable
Job "abstract_schedule.autoAddJob (trigger: interval[0:00:05], next run at: 2019-07-20 06:35:50 UTC)" raised an exception
Traceback (most recent call last):
  File "/app_shell/backup-platform/lib/python3.6/site-packages/apscheduler/executors/base.py", line 125, in run_job
    retval = job.func(*job.args, **job.kwargs)
  File "/app_shell/backup-platform/webadmins/scheduler.py", line 69, in autoAddJob
    current_jobs = self.getBackupPolicy()
  File "/app_shell/backup-platform/webadmins/scheduler.py", line 127, in getBackupPolicy
    func = sched_task.sched_clean_backup_duplicate(p_id, t_id)
TypeError: 'module' object is not callable
Job "abstract_schedule.autoAddJob (trigger: interval[0:00:05], next run at: 2019-07-20 06:35:55 UTC)" raised an exception
Traceback (most recent call last):
  File "/app_shell/backup-platform/lib/python3.6/site-packages/apscheduler/executors/base.py", line 125, in run_job
    retval = job.func(*job.args, **job.kwargs)
  File "/app_shell/backup-platform/webadmins/scheduler.py", line 69, in autoAddJob
    current_jobs = self.getBackupPolicy()
  File "/app_shell/backup-platform/webadmins/scheduler.py", line 127, in getBackupPolicy
    func = sched_task.sched_clean_backup_duplicate(p_id, t_id)
TypeError: 'module' object is not callable
Job "abstract_schedule.autoAddJob (trigger: interval[0:00:05], next run at: 2019-07-20 06:36:00 UTC)" raised an exception
Traceback (most recent call last):
  File "/app_shell/backup-platform/lib/python3.6/site-packages/apscheduler/executors/base.py", line 125, in run_job
    retval = job.func(*job.args, **job.kwargs)
  File "/app_shell/backup-platform/webadmins/scheduler.py", line 69, in autoAddJob
    current_jobs = self.getBackupPolicy()
  File "/app_shell/backup-platform/webadmins/scheduler.py", line 127, in getBackupPolicy
    func = sched_task.sched_clean_backup_duplicate(p_id, t_id)
TypeError: 'module' object is not callable
Job "abstract_schedule.autoAddJob (trigger: interval[0:00:05], next run at: 2019-07-20 06:36:05 UTC)" raised an exception
Traceback (most recent call last):
  File "/app_shell/backup-platform/lib/python3.6/site-packages/apscheduler/executors/base.py", line 125, in run_job
    retval = job.func(*job.args, **job.kwargs)
  File "/app_shell/backup-platform/webadmins/scheduler.py", line 69, in autoAddJob
    current_jobs = self.getBackupPolicy()
  File "/app_shell/backup-platform/webadmins/scheduler.py", line 127, in getBackupPolicy
    func = sched_task.sched_clean_backup_duplicate(p_id, t_id)
TypeError: 'module' object is not callable
Job "abstract_schedule.autoAddJob (trigger: interval[0:00:05], next run at: 2019-07-20 06:36:10 UTC)" raised an exception
Traceback (most recent call last):
  File "/app_shell/backup-platform/lib/python3.6/site-packages/apscheduler/executors/base.py", line 125, in run_job
    retval = job.func(*job.args, **job.kwargs)
  File "/app_shell/backup-platform/webadmins/scheduler.py", line 69, in autoAddJob
    current_jobs = self.getBackupPolicy()
  File "/app_shell/backup-platform/webadmins/scheduler.py", line 127, in getBackupPolicy
    func = sched_task.sched_clean_backup_duplicate(p_id, t_id)
TypeError: 'module' object is not callable
Job "abstract_schedule.autoAddJob (trigger: interval[0:00:05], next run at: 2019-07-20 06:36:15 UTC)" raised an exception
Traceback (most recent call last):
  File "/app_shell/backup-platform/lib/python3.6/site-packages/apscheduler/executors/base.py", line 125, in run_job
    retval = job.func(*job.args, **job.kwargs)
  File "/app_shell/backup-platform/webadmins/scheduler.py", line 69, in autoAddJob
    current_jobs = self.getBackupPolicy()
  File "/app_shell/backup-platform/webadmins/scheduler.py", line 127, in getBackupPolicy
    func = sched_task.sched_clean_backup_duplicate(p_id, t_id)
TypeError: 'module' object is not callable
Job "abstract_schedule.autoAddJob (trigger: interval[0:00:05], next run at: 2019-07-20 06:36:20 UTC)" raised an exception
Traceback (most recent call last):
  File "/app_shell/backup-platform/lib/python3.6/site-packages/apscheduler/executors/base.py", line 125, in run_job
    retval = job.func(*job.args, **job.kwargs)
  File "/app_shell/backup-platform/webadmins/scheduler.py", line 69, in autoAddJob
    current_jobs = self.getBackupPolicy()
  File "/app_shell/backup-platform/webadmins/scheduler.py", line 127, in getBackupPolicy
    func = sched_task.sched_clean_backup_duplicate(p_id, t_id)
TypeError: 'module' object is not callable
Job "abstract_schedule.autoAddJob (trigger: interval[0:00:05], next run at: 2019-07-20 06:36:25 UTC)" raised an exception
Traceback (most recent call last):
  File "/app_shell/backup-platform/lib/python3.6/site-packages/apscheduler/executors/base.py", line 125, in run_job
    retval = job.func(*job.args, **job.kwargs)
  File "/app_shell/backup-platform/webadmins/scheduler.py", line 69, in autoAddJob
    current_jobs = self.getBackupPolicy()
  File "/app_shell/backup-platform/webadmins/scheduler.py", line 127, in getBackupPolicy
    func = sched_task.sched_clean_backup_duplicate(p_id, t_id)
TypeError: 'module' object is not callable
Job "abstract_schedule.autoAddJob (trigger: interval[0:00:05], next run at: 2019-07-20 06:36:30 UTC)" raised an exception
Traceback (most recent call last):
  File "/app_shell/backup-platform/lib/python3.6/site-packages/apscheduler/executors/base.py", line 125, in run_job
    retval = job.func(*job.args, **job.kwargs)
  File "/app_shell/backup-platform/webadmins/scheduler.py", line 69, in autoAddJob
    current_jobs = self.getBackupPolicy()
  File "/app_shell/backup-platform/webadmins/scheduler.py", line 127, in getBackupPolicy
    func = sched_task.sched_clean_backup_duplicate(p_id, t_id)
TypeError: 'module' object is not callable
Job "abstract_schedule.autoAddJob (trigger: interval[0:00:05], next run at: 2019-07-20 06:36:35 UTC)" raised an exception
Traceback (most recent call last):
  File "/app_shell/backup-platform/lib/python3.6/site-packages/apscheduler/executors/base.py", line 125, in run_job
    retval = job.func(*job.args, **job.kwargs)
  File "/app_shell/backup-platform/webadmins/scheduler.py", line 69, in autoAddJob
    current_jobs = self.getBackupPolicy()
  File "/app_shell/backup-platform/webadmins/scheduler.py", line 127, in getBackupPolicy
    func = sched_task.sched_clean_backup_duplicate(p_id, t_id)
TypeError: 'module' object is not callable
Job "abstract_schedule.autoAddJob (trigger: interval[0:00:05], next run at: 2019-07-20 06:36:40 UTC)" raised an exception
Traceback (most recent call last):
  File "/app_shell/backup-platform/lib/python3.6/site-packages/apscheduler/executors/base.py", line 125, in run_job
    retval = job.func(*job.args, **job.kwargs)
  File "/app_shell/backup-platform/webadmins/scheduler.py", line 69, in autoAddJob
    current_jobs = self.getBackupPolicy()
  File "/app_shell/backup-platform/webadmins/scheduler.py", line 127, in getBackupPolicy
    func = sched_task.sched_clean_backup_duplicate(p_id, t_id)
TypeError: 'module' object is not callable
Job "abstract_schedule.autoAddJob (trigger: interval[0:00:05], next run at: 2019-07-20 06:36:45 UTC)" raised an exception
Traceback (most recent call last):
  File "/app_shell/backup-platform/lib/python3.6/site-packages/apscheduler/executors/base.py", line 125, in run_job
    retval = job.func(*job.args, **job.kwargs)
  File "/app_shell/backup-platform/webadmins/scheduler.py", line 69, in autoAddJob
    current_jobs = self.getBackupPolicy()
  File "/app_shell/backup-platform/webadmins/scheduler.py", line 127, in getBackupPolicy
    func = sched_task.sched_clean_backup_duplicate(p_id, t_id)
TypeError: 'module' object is not callable
Job "abstract_schedule.autoAddJob (trigger: interval[0:00:05], next run at: 2019-07-20 06:36:50 UTC)" raised an exception
Traceback (most recent call last):
  File "/app_shell/backup-platform/lib/python3.6/site-packages/apscheduler/executors/base.py", line 125, in run_job
    retval = job.func(*job.args, **job.kwargs)
  File "/app_shell/backup-platform/webadmins/scheduler.py", line 69, in autoAddJob
    current_jobs = self.getBackupPolicy()
  File "/app_shell/backup-platform/webadmins/scheduler.py", line 127, in getBackupPolicy
    func = sched_task.sched_clean_backup_duplicate(p_id, t_id)
TypeError: 'module' object is not callable
Job "abstract_schedule.autoAddJob (trigger: interval[0:00:05], next run at: 2019-07-20 06:36:55 UTC)" raised an exception
Traceback (most recent call last):
  File "/app_shell/backup-platform/lib/python3.6/site-packages/apscheduler/executors/base.py", line 125, in run_job
    retval = job.func(*job.args, **job.kwargs)
  File "/app_shell/backup-platform/webadmins/scheduler.py", line 69, in autoAddJob
    current_jobs = self.getBackupPolicy()
  File "/app_shell/backup-platform/webadmins/scheduler.py", line 127, in getBackupPolicy
    func = sched_task.sched_clean_backup_duplicate(p_id, t_id)
TypeError: 'module' object is not callable
Job "abstract_schedule.autoAddJob (trigger: interval[0:00:05], next run at: 2019-07-20 06:37:00 UTC)" raised an exception
Traceback (most recent call last):
  File "/app_shell/backup-platform/lib/python3.6/site-packages/apscheduler/executors/base.py", line 125, in run_job
    retval = job.func(*job.args, **job.kwargs)
  File "/app_shell/backup-platform/webadmins/scheduler.py", line 69, in autoAddJob
    current_jobs = self.getBackupPolicy()
  File "/app_shell/backup-platform/webadmins/scheduler.py", line 127, in getBackupPolicy
    func = sched_task.sched_clean_backup_duplicate(p_id, t_id)
TypeError: 'module' object is not callable
Job "abstract_schedule.autoAddJob (trigger: interval[0:00:05], next run at: 2019-07-20 06:37:05 UTC)" raised an exception
Traceback (most recent call last):
  File "/app_shell/backup-platform/lib/python3.6/site-packages/apscheduler/executors/base.py", line 125, in run_job
    retval = job.func(*job.args, **job.kwargs)
  File "/app_shell/backup-platform/webadmins/scheduler.py", line 69, in autoAddJob
    current_jobs = self.getBackupPolicy()
  File "/app_shell/backup-platform/webadmins/scheduler.py", line 127, in getBackupPolicy
    func = sched_task.sched_clean_backup_duplicate(p_id, t_id)
TypeError: 'module' object is not callable
Job "abstract_schedule.autoAddJob (trigger: interval[0:00:05], next run at: 2019-07-20 06:37:10 UTC)" raised an exception
Traceback (most recent call last):
  File "/app_shell/backup-platform/lib/python3.6/site-packages/apscheduler/executors/base.py", line 125, in run_job
    retval = job.func(*job.args, **job.kwargs)
  File "/app_shell/backup-platform/webadmins/scheduler.py", line 69, in autoAddJob
    current_jobs = self.getBackupPolicy()
  File "/app_shell/backup-platform/webadmins/scheduler.py", line 127, in getBackupPolicy
    func = sched_task.sched_clean_backup_duplicate(p_id, t_id)
TypeError: 'module' object is not callable
Job "abstract_schedule.autoAddJob (trigger: interval[0:00:05], next run at: 2019-07-20 06:37:15 UTC)" raised an exception
Traceback (most recent call last):
  File "/app_shell/backup-platform/lib/python3.6/site-packages/apscheduler/executors/base.py", line 125, in run_job
    retval = job.func(*job.args, **job.kwargs)
  File "/app_shell/backup-platform/webadmins/scheduler.py", line 69, in autoAddJob
    current_jobs = self.getBackupPolicy()
  File "/app_shell/backup-platform/webadmins/scheduler.py", line 127, in getBackupPolicy
    func = sched_task.sched_clean_backup_duplicate(p_id, t_id)
TypeError: 'module' object is not callable
Job "abstract_schedule.autoAddJob (trigger: interval[0:00:05], next run at: 2019-07-20 06:37:20 UTC)" raised an exception
Traceback (most recent call last):
  File "/app_shell/backup-platform/lib/python3.6/site-packages/apscheduler/executors/base.py", line 125, in run_job
    retval = job.func(*job.args, **job.kwargs)
  File "/app_shell/backup-platform/webadmins/scheduler.py", line 69, in autoAddJob
    current_jobs = self.getBackupPolicy()
  File "/app_shell/backup-platform/webadmins/scheduler.py", line 127, in getBackupPolicy
    func = sched_task.sched_clean_backup_duplicate(p_id, t_id)
TypeError: 'module' object is not callable
Job "abstract_schedule.autoAddJob (trigger: interval[0:00:05], next run at: 2019-07-20 06:37:25 UTC)" raised an exception
Traceback (most recent call last):
  File "/app_shell/backup-platform/lib/python3.6/site-packages/apscheduler/executors/base.py", line 125, in run_job
    retval = job.func(*job.args, **job.kwargs)
  File "/app_shell/backup-platform/webadmins/scheduler.py", line 69, in autoAddJob
    current_jobs = self.getBackupPolicy()
  File "/app_shell/backup-platform/webadmins/scheduler.py", line 127, in getBackupPolicy
    func = sched_task.sched_clean_backup_duplicate(p_id, t_id)
TypeError: 'module' object is not callable
Job "abstract_schedule.autoAddJob (trigger: interval[0:00:05], next run at: 2019-07-20 06:37:30 UTC)" raised an exception
Traceback (most recent call last):
  File "/app_shell/backup-platform/lib/python3.6/site-packages/apscheduler/executors/base.py", line 125, in run_job
    retval = job.func(*job.args, **job.kwargs)
  File "/app_shell/backup-platform/webadmins/scheduler.py", line 69, in autoAddJob
    current_jobs = self.getBackupPolicy()
  File "/app_shell/backup-platform/webadmins/scheduler.py", line 127, in getBackupPolicy
    func = sched_task.sched_clean_backup_duplicate(p_id, t_id)
TypeError: 'module' object is not callable
Job "abstract_schedule.autoAddJob (trigger: interval[0:00:05], next run at: 2019-07-20 06:37:35 UTC)" raised an exception
Traceback (most recent call last):
  File "/app_shell/backup-platform/lib/python3.6/site-packages/apscheduler/executors/base.py", line 125, in run_job
    retval = job.func(*job.args, **job.kwargs)
  File "/app_shell/backup-platform/webadmins/scheduler.py", line 69, in autoAddJob
    current_jobs = self.getBackupPolicy()
  File "/app_shell/backup-platform/webadmins/scheduler.py", line 127, in getBackupPolicy
    func = sched_task.sched_clean_backup_duplicate(p_id, t_id)
TypeError: 'module' object is not callable
Job "abstract_schedule.autoAddJob (trigger: interval[0:00:05], next run at: 2019-07-20 06:37:40 UTC)" raised an exception
Traceback (most recent call last):
  File "/app_shell/backup-platform/lib/python3.6/site-packages/apscheduler/executors/base.py", line 125, in run_job
    retval = job.func(*job.args, **job.kwargs)
  File "/app_shell/backup-platform/webadmins/scheduler.py", line 69, in autoAddJob
    current_jobs = self.getBackupPolicy()
  File "/app_shell/backup-platform/webadmins/scheduler.py", line 127, in getBackupPolicy
    func = sched_task.sched_clean_backup_duplicate(p_id, t_id)
TypeError: 'module' object is not callable
Job "abstract_schedule.autoAddJob (trigger: interval[0:00:05], next run at: 2019-07-20 06:37:45 UTC)" raised an exception
Traceback (most recent call last):
  File "/app_shell/backup-platform/lib/python3.6/site-packages/apscheduler/executors/base.py", line 125, in run_job
    retval = job.func(*job.args, **job.kwargs)
  File "/app_shell/backup-platform/webadmins/scheduler.py", line 69, in autoAddJob
    current_jobs = self.getBackupPolicy()
  File "/app_shell/backup-platform/webadmins/scheduler.py", line 127, in getBackupPolicy
    func = sched_task.sched_clean_backup_duplicate(p_id, t_id)
TypeError: 'module' object is not callable
Job "abstract_schedule.autoAddJob (trigger: interval[0:00:05], next run at: 2019-07-20 06:37:50 UTC)" raised an exception
Traceback (most recent call last):
  File "/app_shell/backup-platform/lib/python3.6/site-packages/apscheduler/executors/base.py", line 125, in run_job
    retval = job.func(*job.args, **job.kwargs)
  File "/app_shell/backup-platform/webadmins/scheduler.py", line 69, in autoAddJob
    current_jobs = self.getBackupPolicy()
  File "/app_shell/backup-platform/webadmins/scheduler.py", line 127, in getBackupPolicy
    func = sched_task.sched_clean_backup_duplicate(p_id, t_id)
TypeError: 'module' object is not callable
Job "abstract_schedule.autoAddJob (trigger: interval[0:00:05], next run at: 2019-07-20 06:37:55 UTC)" raised an exception
Traceback (most recent call last):
  File "/app_shell/backup-platform/lib/python3.6/site-packages/apscheduler/executors/base.py", line 125, in run_job
    retval = job.func(*job.args, **job.kwargs)
  File "/app_shell/backup-platform/webadmins/scheduler.py", line 69, in autoAddJob
    current_jobs = self.getBackupPolicy()
  File "/app_shell/backup-platform/webadmins/scheduler.py", line 127, in getBackupPolicy
    func = sched_task.sched_clean_backup_duplicate(p_id, t_id)
TypeError: 'module' object is not callable
Job "abstract_schedule.autoAddJob (trigger: interval[0:00:05], next run at: 2019-07-20 06:38:00 UTC)" raised an exception
Traceback (most recent call last):
  File "/app_shell/backup-platform/lib/python3.6/site-packages/apscheduler/executors/base.py", line 125, in run_job
    retval = job.func(*job.args, **job.kwargs)
  File "/app_shell/backup-platform/webadmins/scheduler.py", line 69, in autoAddJob
    current_jobs = self.getBackupPolicy()
  File "/app_shell/backup-platform/webadmins/scheduler.py", line 127, in getBackupPolicy
    func = sched_task.sched_clean_backup_duplicate(p_id, t_id)
TypeError: 'module' object is not callable
Job "abstract_schedule.autoAddJob (trigger: interval[0:00:05], next run at: 2019-07-20 06:38:05 UTC)" raised an exception
Traceback (most recent call last):
  File "/app_shell/backup-platform/lib/python3.6/site-packages/apscheduler/executors/base.py", line 125, in run_job
    retval = job.func(*job.args, **job.kwargs)
  File "/app_shell/backup-platform/webadmins/scheduler.py", line 69, in autoAddJob
    current_jobs = self.getBackupPolicy()
  File "/app_shell/backup-platform/webadmins/scheduler.py", line 127, in getBackupPolicy
    func = sched_task.sched_clean_backup_duplicate(p_id, t_id)
TypeError: 'module' object is not callable
Job "abstract_schedule.autoAddJob (trigger: interval[0:00:05], next run at: 2019-07-20 06:38:10 UTC)" raised an exception
Traceback (most recent call last):
  File "/app_shell/backup-platform/lib/python3.6/site-packages/apscheduler/executors/base.py", line 125, in run_job
    retval = job.func(*job.args, **job.kwargs)
  File "/app_shell/backup-platform/webadmins/scheduler.py", line 69, in autoAddJob
    current_jobs = self.getBackupPolicy()
  File "/app_shell/backup-platform/webadmins/scheduler.py", line 127, in getBackupPolicy
    func = sched_task.sched_clean_backup_duplicate(p_id, t_id)
TypeError: 'module' object is not callable
Job "abstract_schedule.autoAddJob (trigger: interval[0:00:05], next run at: 2019-07-20 06:38:15 UTC)" raised an exception
Traceback (most recent call last):
  File "/app_shell/backup-platform/lib/python3.6/site-packages/apscheduler/executors/base.py", line 125, in run_job
    retval = job.func(*job.args, **job.kwargs)
  File "/app_shell/backup-platform/webadmins/scheduler.py", line 69, in autoAddJob
    current_jobs = self.getBackupPolicy()
  File "/app_shell/backup-platform/webadmins/scheduler.py", line 127, in getBackupPolicy
    func = sched_task.sched_clean_backup_duplicate(p_id, t_id)
TypeError: 'module' object is not callable
Job "abstract_schedule.autoAddJob (trigger: interval[0:00:05], next run at: 2019-07-20 06:38:20 UTC)" raised an exception
Traceback (most recent call last):
  File "/app_shell/backup-platform/lib/python3.6/site-packages/apscheduler/executors/base.py", line 125, in run_job
    retval = job.func(*job.args, **job.kwargs)
  File "/app_shell/backup-platform/webadmins/scheduler.py", line 69, in autoAddJob
    current_jobs = self.getBackupPolicy()
  File "/app_shell/backup-platform/webadmins/scheduler.py", line 127, in getBackupPolicy
    if t_id == "1000000001": ##副本自动清理任务脚本
TypeError: 'module' object is not callable
Job "abstract_schedule.autoAddJob (trigger: interval[0:00:05], next run at: 2019-07-20 06:38:25 UTC)" raised an exception
Traceback (most recent call last):
  File "/app_shell/backup-platform/lib/python3.6/site-packages/apscheduler/executors/base.py", line 125, in run_job
    retval = job.func(*job.args, **job.kwargs)
  File "/app_shell/backup-platform/webadmins/scheduler.py", line 69, in autoAddJob
    current_jobs = self.getBackupPolicy()
  File "/app_shell/backup-platform/webadmins/scheduler.py", line 127, in getBackupPolicy
    if t_id == "1000000001": ##副本自动清理任务脚本
TypeError: 'module' object is not callable
Job "abstract_schedule.autoAddJob (trigger: interval[0:00:05], next run at: 2019-07-20 06:38:30 UTC)" raised an exception
Traceback (most recent call last):
  File "/app_shell/backup-platform/lib/python3.6/site-packages/apscheduler/executors/base.py", line 125, in run_job
    retval = job.func(*job.args, **job.kwargs)
  File "/app_shell/backup-platform/webadmins/scheduler.py", line 69, in autoAddJob
    current_jobs = self.getBackupPolicy()
  File "/app_shell/backup-platform/webadmins/scheduler.py", line 127, in getBackupPolicy
    if t_id == "1000000001": ##副本自动清理任务脚本
TypeError: 'module' object is not callable
Job "abstract_schedule.autoAddJob (trigger: interval[0:00:05], next run at: 2019-07-20 06:58:39 UTC)" raised an exception
Traceback (most recent call last):
  File "/app_shell/backup-platform/lib/python3.6/site-packages/apscheduler/executors/base.py", line 125, in run_job
    retval = job.func(*job.args, **job.kwargs)
  File "/app_shell/backup-platform/webadmins/scheduler.py", line 69, in autoAddJob
    current_jobs = self.getBackupPolicy()
  File "/app_shell/backup-platform/webadmins/scheduler.py", line 130, in getBackupPolicy
    result[t_id].update(day_of_week)
KeyError: '1000000002'
Job "abstract_schedule.autoAddJob (trigger: interval[0:00:05], next run at: 2019-07-20 06:58:44 UTC)" raised an exception
Traceback (most recent call last):
  File "/app_shell/backup-platform/lib/python3.6/site-packages/apscheduler/executors/base.py", line 125, in run_job
    retval = job.func(*job.args, **job.kwargs)
  File "/app_shell/backup-platform/webadmins/scheduler.py", line 69, in autoAddJob
    current_jobs = self.getBackupPolicy()
  File "/app_shell/backup-platform/webadmins/scheduler.py", line 130, in getBackupPolicy
    result[t_id].update(day_of_week)
KeyError: '1000000002'
Job "abstract_schedule.autoAddJob (trigger: interval[0:00:05], next run at: 2019-07-20 06:59:09 UTC)" raised an exception
Traceback (most recent call last):
  File "/app_shell/backup-platform/lib/python3.6/site-packages/apscheduler/executors/base.py", line 125, in run_job
    retval = job.func(*job.args, **job.kwargs)
  File "/app_shell/backup-platform/webadmins/scheduler.py", line 69, in autoAddJob
    current_jobs = self.getBackupPolicy()
  File "/app_shell/backup-platform/webadmins/scheduler.py", line 130, in getBackupPolicy
    result[t_id].update(day_of_week)
KeyError: '1000000002'
Job "abstract_schedule.autoAddJob (trigger: interval[0:00:05], next run at: 2019-07-20 06:59:14 UTC)" raised an exception
Traceback (most recent call last):
  File "/app_shell/backup-platform/lib/python3.6/site-packages/apscheduler/executors/base.py", line 125, in run_job
    retval = job.func(*job.args, **job.kwargs)
  File "/app_shell/backup-platform/webadmins/scheduler.py", line 69, in autoAddJob
    current_jobs = self.getBackupPolicy()
  File "/app_shell/backup-platform/webadmins/scheduler.py", line 130, in getBackupPolicy
    result[t_id].update(day_of_week)
KeyError: '1000000002'
Job "abstract_schedule.autoAddJob (trigger: interval[0:00:05], next run at: 2019-07-20 06:59:19 UTC)" raised an exception
Traceback (most recent call last):
  File "/app_shell/backup-platform/lib/python3.6/site-packages/apscheduler/executors/base.py", line 125, in run_job
    retval = job.func(*job.args, **job.kwargs)
  File "/app_shell/backup-platform/webadmins/scheduler.py", line 69, in autoAddJob
    current_jobs = self.getBackupPolicy()
  File "/app_shell/backup-platform/webadmins/scheduler.py", line 130, in getBackupPolicy
    result[t_id].update(day_of_week)
KeyError: '1000000002'
Run time of job "db_backup_tools.db_backup_start (trigger: cron[day_of_week='0,1,2,3,4,5,6', minute='*/1'], next run at: 2019-07-20 13:42:00 UTC)" was missed by 0:00:24.909326
Run time of job "fs_backup_tools.fs_backup_start (trigger: cron[day_of_week='0,1,2,3,4,5,6', minute='*/1'], next run at: 2019-07-20 13:42:00 UTC)" was missed by 0:00:24.911425
Run time of job "duplicate_claen_tools.duplicate_clean_start (trigger: cron[day_of_week='0,1,2,3,4,5,6', minute='*/6'], next run at: 2019-07-20 13:42:00 UTC)" was missed by 0:05:24.911560
